Workbook

Sheet box
A1: 宝箱ID | B1: 宝箱名称 | C1: 宝箱类型 | D1: 开箱方式 | E1: 宝箱内容
A2: id | B2: name | C2: boxType | D2: openType | E2: award

Sheet boxpoint
A1: 宝箱点ID | B1: 所属地图 | C1: 坐标 | D1: 层级调整 | E1: 表现形式 | F1: 对话 | G1: 选项 | H1: 宝箱奖励 | I1: 生效模式
A2: id | B2: mapId | C2: pos | D2: sortingOrder | E2: showStyle | F2: dialog | G2: lipsStr | H2: awards | I2: activateMode
A3: 90 | B3: 10001 | C3: 17,22 | D3: 4 | E3: 21 | F3: 一方小巧精致的盒子，不知内容何物。 | G3: 打开,离开 | H3: item,800002,1;1002+142; | I3: 0
A4: 91 | B4: 10001 | C4: 15,28 | D4: 4 | E4: 4 | F4: 有些破损的木柜，可隐隐窥见其中藏有物品。 | G4: 搜寻,离开 | H4: item,500001,1;item,901102,1; | I4: 0
A5: 92 | B5: 10001 | C5: 17,24 | D5: 4 | E5: 15 | F5: 此处堆积着一大捆干草。 | G5: 搜寻,离开 | H5: item,103001,1;item,901101,2; | I5: 0
A6: 3 | B6: 10002 | C6: 30,22 | D6: 4 | E6: 2 | F6: 一大堆乱石杂积，似乎压藏着什么。 | G6: 搜寻,离开 | H6: item,102002,2; | I6: 0
A7: 4 | B7: 10002 | C7: 38,14 | D7: 4 | E7: 24 | F7: 地上似乎有何物什，被半埋于土中。 | G7: 拾取,离开 | H7: item,600001,1; | I7: 0
A8: 5 | B8: 10002 | C8: 30,3 | D8: 4 | E8: 30 | F8: 无主的箱子，不知何人丢弃。 | G8: 打开,离开 | H8: item,95101019,1;item,901001,2; | I8: 0
A9: 6 | B9: 10002 | C9: 4,22 | D9: 4 | E9: 25 | F9: 一个遗弃的布兜，观之似乎是游方郎中常用式样。 | G9: 拾取,离开 | H9: item,800001,1;item,95201168,1; | I9: 0
A10: 8 | B10: 10002 | C10: 8,2 | D10: 4 | E10: 21 | F10: 一方小巧精致的盒子，不知内容何物。 | G10: 打开,离开 | H10: item,901001,3; | I10: 0
A11: 13 | B11: 13000 | C11: 18,24 | D11: 4 | E11: 23 | F11: 一个包袱，不知是何人遗失在此。 | G11: 拾取,离开 | H11: item,907027,2;item,902015,1; | I11: 0
A12: 15 | B12: 13000 | C12: 5,15 | D12: 4 | E12: 2 | F12: 一堆凌乱无章的乱石。 | G12: 搜寻,离开 | H12: item,101004,1; | I12: 0
A13: 16 | B13: 13010 | C13: 10,3 | D13: 4 | E13: 22 | F13: 无主的箱子，不知何人遗弃于墙角。 | G13: 打开,离开 | H13: 1002+802;item,98090101,1; | I13: 0
A14: 17 | B14: 13030 | C14: 9,1 | D14: 4 | E14: 23 | F14: 一个包袱，或许是寨中贼人劫掠而来。 | G14: 拾取,离开 | H14: item,901002,3; | I14: 0
... A106: 114 | B106: 17020 | C106: 3,0 | D106: 4 | E106: 34 | F106: 墨家存放于秘窟之中的宝箱，想来价值不菲。 | G106: 打开,离开 | H106: item,95301120,1 | I106: 2

Sheet boxpoint2
A1: 宝箱点ID | B1: 所属地图 | C1: 坐标 | D1: 层级调整 | E1: 表现形式 | F1: 对话 | G1: 选项 | H1: 宝箱奖励
A2: id | B2: mapId | C2: pos | D2: sortingOrder | E2: showStyle | F2: dialog | G2: lipsStr | H2: awards
A3: 90 | B3: 10001 | C3: 17,22 | D3: 4 | E3: 21 | F3: A small, delicate box, contents unknown. | G3: Open,Leave | H3: item,800002,1;1002+142;
A4: 91 | B4: 10001 | C4: 15,28 | D4: 4 | E4: 4 | F4: A somewhat damaged wooden cabinet, faintly revealing stored items within. | G4: Search,Leave | H4: item,500001,1;item,901102,1;
A5: 92 | B5: 10001 | C5: 17,24 | D5: 4 | E5: 15 | F5: A large bundle of dry grass piled here. | G5: Search,Leave | H5: item,103001,1;item,901101,2;
A6: 3 | B6: 10002 | C6: 30,22 | D6: 4 | E6: 2 | F6: A pile of disorderly rocks, seemingly concealing something beneath. | G6: Search,Leave | H6: item,102002,2;
A7: 4 | B7: 10002 | C7: 38,14 | D7: 4 | E7: 24 | F7: Something appears half-buried in the earth. | G7: Pick,Leave | H7: item,600001,1;
A8: 5 | B8: 10002 | C8: 30,3 | D8: 4 | E8: 30 | F8: An ownerless chest, discarded by unknown hands. | G8: Open,Leave | H8: item,95101019,1;item,901001,2;
A9: 6 | B9: 10002 | C9: 4,22 | D9: 4 | E9: 25 | F9: An abandoned cloth bag, resembling the style often used by itinerant physicians. | G9: Pick,Leave | H9: item,800001,1;item,95201168,1;
A10: 8 | B10: 10002 | C10: 8,2 | D10: 4 | E10: 21 | F10: A small, delicate box, contents unknown. | G10: Open,Leave | H10: item,901001,3;
A11: 13 | B11: 13000 | C11: 18,24 | D11: 4 | E11: 23 | F11: A wrapped bundle, lost here by unknown person. | G11: Pick,Leave | H11: item,907027,2;item,902015,1;
A12: 15 | B12: 13000 | C12: 5,15 | D12: 4 | E12: 2 | F12: A pile of haphazardly stacked rocks. | G12: Search,Leave | H12: item,101004,1;
A13: 16 | B13: 13010 | C13: 10,3 | D13: 4 | E13: 22 | F13: An ownerless chest, abandoned by unknown hands in the corner. | G13: Open,Leave | H13: 1002+802;item,98090101,1;
A14: 17 | B14: 13030 | C14: 9,1 | D14: 4 | E14: 23 | F14: A wrapped bundle, perhaps plundered by bandits from the stronghold. | G14: Pick,Leave | H14: item,901002,3;
... A105: 113 | B105: 23070 | C105: 1,4 | D105: 4 | E105: 34 | F105: A treasure chest hidden by a Taiping Taoist, likely holds profound secrets. | G105: Open,Leave | H105: item,95201189,1;item,95410140,1;

Sheet Sheet2
A1: 宝箱奖励 | E1: 所属地图
A2: awards | E2: mapId
A3: 200001 | B3: =VLOOKUP(A3,[1]装备!$A:$B,2,0) -> 粗布衣 | E3: 10001 | F3: =VLOOKUP(E3,[1]装备!$A:$B,2,0) -> #N/A
A4: 500001 | B4: =VLOOKUP(A4,[1]装备!$A:$B,2,0) -> 蒲草缠腰 | C4: 901102 | D4: =VLOOKUP(C4,[1]装备!$A:$B,2,0) -> 续命散 | E4: 10001 | F4: =VLOOKUP(E4,[1]装备!$A:$B,2,0) -> #N/A
A5: 103001 | B5: =VLOOKUP(A5,[1]装备!$A:$B,2,0) -> 旧柴刀 | C5: 901101 | D5: =VLOOKUP(C5,[1]装备!$A:$B,2,0) -> 金创散 | E5: 10001 | F5: =VLOOKUP(E5,[1]装备!$A:$B,2,0) -> #N/A
B6: =VLOOKUP(A6,[1]装备!$A:$B,2,0) -> #N/A | E6: 10002 | F6: =VLOOKUP(E6,[1]装备!$A:$B,2,0) -> #N/A
B7: =VLOOKUP(A7,[1]装备!$A:$B,2,0) -> #N/A | E7: 10002 | F7: =VLOOKUP(E7,[1]装备!$A:$B,2,0) -> #N/A
A8: 902002 | B8: =VLOOKUP(A8,[1]装备!$A:$B,2,0) -> 馒头 | E8: 10002 | F8: =VLOOKUP(E8,[1]装备!$A:$B,2,0) -> #N/A
A9: 901101 | B9: =VLOOKUP(A9,[1]装备!$A:$B,2,0) -> 金创散 | E9: 10002 | F9: =VLOOKUP(E9,[1]装备!$A:$B,2,0) -> #N/A
A10: 600001 | B10: =VLOOKUP(A10,[1]装备!$A:$B,2,0) -> 旧木环 | E10: 10002 | F10: =VLOOKUP(E10,[1]装备!$A:$B,2,0) -> #N/A
A11: 800001 | B11: =VLOOKUP(A11,[1]装备!$A:$B,2,0) -> 亮铜坠 | E11: 10002 | F11: =VLOOKUP(E11,[1]装备!$A:$B,2,0) -> #N/A
A12: 700001 | B12: =VLOOKUP(A12,[1]装备!$A:$B,2,0) -> 兽骨链 | E12: 10002 | F12: =VLOOKUP(E12,[1]装备!$A:$B,2,0) -> #N/A
A13: 902007 | B13: =VLOOKUP(A13,[1]装备!$A:$B,2,0) -> 高粱红陈酿 | E13: 10002 | F13: =VLOOKUP(E13,[1]装备!$A:$B,2,0) -> #N/A
A14: 300001 | B14: =VLOOKUP(A14,[1]装备!$A:$B,2,0) -> 破布护腕 | E14: 10002 | F14: =VLOOKUP(E14,[1]装备!$A:$B,2,0) -> #N/A
A15: 400001 | B15: =VLOOKUP(A15,[1]装备!$A:$B,2,0) -> 蒲草绑腿 | E15: 10002 | F15: =VLOOKUP(E15,[1]装备!$A:$B,2,0) -> #N/A
A16: 106002 | B16: =VLOOKUP(A16,[1]装备!$A:$B,2,0) -> 薄柳镖 | E16: 13000 | F16: =VLOOKUP(E16,[1]装备!$A:$B,2,0) -> #N/A
A17: 901102 | B17: =VLOOKUP(A17,[1]装备!$A:$B,2,0) -> 续命散 | E17: 13000 | F17: =VLOOKUP(E17,[1]装备!$A:$B,2,0) -> #N/A
A18: 907027 | B18: =VLOOKUP(A18,[1]装备!$A:$B,2,0) -> 粗粮 | C18: 902015 | D18: =VLOOKUP(C18,[1]装备!$A:$B,2,0) -> 桂花糕 | E18: 13000 | F18: =VLOOKUP(E18,[1]装备!$A:$B,2,0) -> #N/A
A19: 113002 | B19: =VLOOKUP(A19,[1]装备!$A:$B,2,0) -> 青藤鞭 | C19: 907014 | D19: =VLOOKUP(C19,[1]装备!$A:$B,2,0) -> 野蘑菇 | E19: 13000 | F19: =VLOOKUP(E19,[1]装备!$A:$B,2,0) -> #N/A
A20: 95410135 | B20: =VLOOKUP(A20,[1]装备!$A:$B,2,0) -> 人世·撼岳卷 | E20: 13000 | F20: =VLOOKUP(E20,[1]装备!$A:$B,2,0) -> #N/A
B21: =VLOOKUP(A21,[1]装备!$A:$B,2,0) -> #N/A | E21: 13010 | F21: =VLOOKUP(E21,[1]装备!$A:$B,2,0) -> #N/A
A22: 901002 | B22: =VLOOKUP(A22,[1]装备!$A:$B,2,0) -> 八宝花丸 | E22: 13030 | F22: =VLOOKUP(E22,[1]装备!$A:$B,2,0) -> #N/A
B23: =VLOOKUP(A23,[1]装备!$A:$B,2,0) -> #N/A | E23: 13030 | F23: =VLOOKUP(E23,[1]装备!$A:$B,2,0) -> #N/A
A24: 104002 | B24: =VLOOKUP(A24,[1]装备!$A:$B,2,0) -> 白蜡杆 | E24: 13030 | F24: =VLOOKUP(E24,[1]装备!$A:$B,2,0) -> #N/A
A25: 95410123 | B25: =VLOOKUP(A25,[1]装备!$A:$B,2,0) -> 地覆·垒峦卷 | E25: 13040 | F25: =VLOOKUP(E25,[1]装备!$A:$B,2,0) -> #N/A
A26: 901500 | B26: =VLOOKUP(A26,[1]装备!$A:$B,2,0) -> 五力士丹 | E26: 13040 | F26: =VLOOKUP(E26,[1]装备!$A:$B,2,0) -> #N/A
A27: 904021 | B27: =VLOOKUP(A27,[1]装备!$A:$B,2,0) -> 墨家连环铳图解·1 | E27: 13050 | F27: =VLOOKUP(E27,[1]装备!$A:$B,2,0) -> #N/A
A28: 908095 | B28: =VLOOKUP(A28,[1]装备!$A:$B,2,0) -> 蜡烛 | E28: 13050 | F28: =VLOOKUP(E28,[1]装备!$A:$B,2,0) -> #N/A
B29: =VLOOKUP(A29,[1]装备!$A:$B,2,0) -> #N/A | E29: 13050 | F29: =VLOOKUP(E29,[1]装备!$A:$B,2,0) -> #N/A
A30: 300003 | B30: =VLOOKUP(A30,[1]装备!$A:$B,2,0) -> 竹片护腕 | E30: 14000 | F30: =VLOOKUP(E30,[1]装备!$A:$B,2,0) -> #N/A
A31: 104003 | B31: =VLOOKUP(A31,[1]装备!$A:$B,2,0) -> 磐龙杖 | E31: 14000 | F31: =VLOOKUP(E31,[1]装备!$A:$B,2,0) -> #N/A
A32: 95410119 | B32: =VLOOKUP(A32,[1]装备!$A:$B,2,0) -> 天衍·晦朔卷 | E32: 14000 | F32: =VLOOKUP(E32,[1]装备!$A:$B,2,0) -> #N/A
A33: 907023 | B33: =VLOOKUP(A33,[1]装备!$A:$B,2,0) -> 天麻草 | C33: 901002 | D33: =VLOOKUP(C33,[1]装备!$A:$B,2,0) -> 八宝花丸 | E33: 14000 | F33: =VLOOKUP(E33,[1]装备!$A:$B,2,0) -> #N/A
A34: 901507 | B34: =VLOOKUP(A34,[1]装备!$A:$B,2,0) -> 秋冰方 | E34: 14000 | F34: =VLOOKUP(E34,[1]装备!$A:$B,2,0) -> #N/A
A35: 909100 | B35: =VLOOKUP(A35,[1]装备!$A:$B,2,0) -> 黄天秘要·2 | E35: 14010 | F35: =VLOOKUP(E35,[1]装备!$A:$B,2,0) -> #N/A
A36: 95410119 | B36: =VLOOKUP(A36,[1]装备!$A:$B,2,0) -> 天衍·晦朔卷 | E36: 14010 | F36: =VLOOKUP(E36,[1]装备!$A:$B,2,0) -> #N/A
A37: 901501 | B37: =VLOOKUP(A37,[1]装备!$A:$B,2,0) -> 九阳丹 | E37: 14010 | F37: =VLOOKUP(E37,[1]装备!$A:$B,2,0) -> #N/A
A38: 909099 | B38: =VLOOKUP(A38,[1]装备!$A:$B,2,0) -> 黄天秘要·1 | E38: 14020 | F38: =VLOOKUP(E38,[1]装备!$A:$B,2,0) -> #N/A
A39: 200003 | B39: =VLOOKUP(A39,[1]装备!$A:$B,2,0) -> 棉布长衫 | C39: 500002 | D39: =VLOOKUP(C39,[1]装备!$A:$B,2,0) -> 麻布缠腰 | E39: 14020 | F39: =VLOOKUP(E39,[1]装备!$A:$B,2,0) -> #N/A
A40: 600005 | B40: =VLOOKUP(A40,[1]装备!$A:$B,2,0) -> 精铁扳指 | E40: 14020 | F40: =VLOOKUP(E40,[1]装备!$A:$B,2,0) -> #N/A
...

Sheet 宝箱表现形式
A1: ID | B1: 宝箱名 | C1: 限制方式 | D1: icon | E1: icon_UI
A2: 1 | B2: 枯树洞 | C2: 室外 | D2: 880001 | E2: 880001
A3: 2 | B3: 乱石堆 | C3: 室外 | D3: 880002 | E3: 880002
A4: 3 | B4: 墙缝 | C4: 室内 | D4: 880003 | E4: 880003
A5: 4 | B5: 破木柜 | C5: 室内 | D5: 880004 | E5: 880004
A6: 5 | B6: 橱柜 | C6: 室内 | D6: 880005 | E6: 880005
A7: 6 | B7: 书架 | C7: 室内 | D7: 880006 | E7: 880006
A8: 7 | B8: 土坑 | C8: 室外 | D8: 880007 | E8: 880007
A9: 8 | B9: 破布袋 | C9: 通用 | D9: 880008 | E9: 880008
A10: 9 | B10: 旧木桶 | C10: 通用 | D10: 880009 | E10: 880009
A11: 10 | B11: 水井 | C11: 室外 | D11: 880010 | E11: 880010
A12: 11 | B12: 破水缸 | C12: 通用 | D12: 880011 | E12: 880011
A13: 12 | B13: 墙壁暗格 | C13: 室内 | D13: 880012 | E13: 880012
... A40: 39 | B40: 竹篓 | C40: 通用 | D40: 880039 | E40: 880039

Sheet Sheet1
