Workbook

Sheet PassiveSkillData
A1: id | B1: 技能总称 | D1: 技能名 | E1: buffId列表 | F1: 效果id列表 | G1: 冷却时间
A2: id | B2: 技能总称 | C2: 备注 | D2: name | F2: effectIdListStr | G2: CD | I2: 1 | K2: 2 | M2: 3 | O2: 4 | P2: 5 | R2: 6
A3: =VLOOKUP(D3,Sheet3!$C:$AP,40,0) -> 2010101 | B3: 天涯月明章 | C3: 朔独还 | D3: 朔独还 | F3: =I3&K3&M3 -> 201010100;201010101; | G3: 0 | H3: =B3&C3&$I$2 -> 天涯月明章朔独还1 | I3: =IF(IFERROR(INDEX(EffectData!$G:$G,MATCH(H3,EffectData!$C:$C,0)),"")&";"=";","",IFERROR(INDEX(EffectData!$G:$G,MATCH(H3,EffectData!$C:$C,0)),"")&";") -> 201010100; | J3: =B3&C3&$K$2 -> 天涯月明章朔独还2 | K3: =IF(IFERROR(INDEX(EffectData!$G:$G,MATCH(J3,EffectData!$C:$C,0)),"")&";"=";","",IFERROR(INDEX(EffectData!$G:$G,MATCH(J3,EffectData!$C:$C,0)),"")&";") -> 201010101; | L3: =B3&C3&$M$2 -> 天涯月明章朔独还3 | N3: =B3&C3&$O$2 -> 天涯月明章朔独还4 | O3: =IFERROR(INDEX(EffectData!$G:$G,MATCH(O2,EffectData!$C:$C,0)),"")
A4: =VLOOKUP(D4,Sheet3!$C:$AP,40,0) -> 2010102 | B4: 天涯月明章 | C4: 执无言 | D4: 执无言 | F4: =I4&K4&M4 -> 201010200; | G4: 0 | H4: =B4&C4&$I$2 -> 天涯月明章执无言1 | I4: =IF(IFERROR(INDEX(EffectData!$G:$G,MATCH(H4,EffectData!$C:$C,0)),"")&";"=";","",IFERROR(INDEX(EffectData!$G:$G,MATCH(H4,EffectData!$C:$C,0)),"")&";") -> 201010200; | J4: =B4&C4&$K$2 -> 天涯月明章执无言2 | L4: =B4&C4&$M$2 -> 天涯月明章执无言3 | N4: =B4&C4&$O$2 -> 天涯月明章执无言4
A5: =VLOOKUP(D5,Sheet3!$C:$AP,40,0) -> 2010103 | B5: 天涯月明章 | C5: 涯无书 | D5: 涯无书 | F5: =I5&K5&M5 -> 201010300; | G5: 0 | H5: =B5&C5&$I$2 -> 天涯月明章涯无书1 | I5: =IF(IFERROR(INDEX(EffectData!$G:$G,MATCH(H5,EffectData!$C:$C,0)),"")&";"=";","",IFERROR(INDEX(EffectData!$G:$G,MATCH(H5,EffectData!$C:$C,0)),"")&";") -> 201010300; | J5: =B5&C5&$K$2 -> 天涯月明章涯无书2 | L5: =B5&C5&$M$2 -> 天涯月明章涯无书3 | N5: =B5&C5&$O$2 -> 天涯月明章涯无书4
A6: =VLOOKUP(D6,Sheet3!$C:$AP,40,0) -> 2010104 | B6: 天涯月明章 | C6: 晓月残星 | D6: 晓月残星 | F6: =I6&K6&M6&O6 -> 201010401;201010402;201010403; | G6: 0 | H6: =B6&C6&$I$2 -> 天涯月明章晓月残星1 | J6: =B6&C6&$K$2 -> 天涯月明章晓月残星2 | K6: =IF(IFERROR(INDEX(EffectData!$G:$G,MATCH(J6,EffectData!$C:$C,0)),"")&";"=";","",IFERROR(INDEX(EffectData!$G:$G,MATCH(J6,EffectData!$C:$C,0)),"")&";") -> 201010401; | L6: =B6&C6&$M$2 -> 天涯月明章晓月残星3 | M6: =IF(IFERROR(INDEX(EffectData!$G:$G,MATCH(L6,EffectData!$C:$C,0)),"")&";"=";","",IFERROR(INDEX(EffectData!$G:$G,MATCH(L6,EffectData!$C:$C,0)),"")&";") -> 201010402; | N6: =B6&C6&$O$2 -> 天涯月明章晓月残星4 | O6: =IF(IFERROR(INDEX(EffectData!$G:$G,MATCH(N6,EffectData!$C:$C,0)),"")&";"=";","",IFERROR(INDEX(EffectData!$G:$G,MATCH(N6,EffectData!$C:$C,0)),"")&";") -> 201010403;
A7: =VLOOKUP(D7,Sheet3!$C:$AP,40,0) -> 2010105 | B7: 天涯月明章 | C7: 人踟躇 | D7: 人踟躇 | F7: =I7&K7&M7&O7 -> 201010500; | G7: 0 | H7: =B7&C7&$I$2 -> 天涯月明章人踟躇1 | I7: =IF(IFERROR(INDEX(EffectData!$G:$G,MATCH(H7,EffectData!$C:$C,0)),"")&";"=";","",IFERROR(INDEX(EffectData!$G:$G,MATCH(H7,EffectData!$C:$C,0)),"")&";") -> 201010500; | J7: =B7&C7&$K$2 -> 天涯月明章人踟躇2 | K7: =IF(IFERROR(INDEX(EffectData!$G:$G,MATCH(J7,EffectData!$C:$C,0)),"")&";"=";","",IFERROR(INDEX(EffectData!$G:$G,MATCH(J7,EffectData!$C:$C,0)),"")&";") | L7: =B7&C7&$M$2 -> 天涯月明章人踟躇3 | M7: =IF(IFERROR(INDEX(EffectData!$G:$G,MATCH(L7,EffectData!$C:$C,0)),"")&";"=";","",IFERROR(INDEX(EffectData!$G:$G,MATCH(L7,EffectData!$C:$C,0)),"")&";") | N7: =B7&C7&$O$2 -> 天涯月明章人踟躇4 | O7: =IF(IFERROR(INDEX(EffectData!$G:$G,MATCH(N7,EffectData!$C:$C,0)),"")&";"=";","",IFERROR(INDEX(EffectData!$G:$G,MATCH(N7,EffectData!$C:$C,0)),"")&";")
A8: =VLOOKUP(D8,Sheet3!$C:$AP,40,0) -> 2010106 | B8: 天涯月明章 | C8: 携吴钩 | D8: 携吴钩 | F8: =I8&K8&M8 -> 201010600;201010601;201010602; | G8: 0 | H8: =B8&C8&$I$2 -> 天涯月明章携吴钩1 | I8: =IF(IFERROR(INDEX(EffectData!$G:$G,MATCH(H8,EffectData!$C:$C,0)),"")&";"=";","",IFERROR(INDEX(EffectData!$G:$G,MATCH(H8,EffectData!$C:$C,0)),"")&";") -> 201010600; | J8: =B8&C8&$K$2 -> 天涯月明章携吴钩2 | K8: =IF(IFERROR(INDEX(EffectData!$G:$G,MATCH(J8,EffectData!$C:$C,0)),"")&";"=";","",IFERROR(INDEX(EffectData!$G:$G,MATCH(J8,EffectData!$C:$C,0)),"")&";") -> 201010601; | L8: =B8&C8&$M$2 -> 天涯月明章携吴钩3 | M8: =IF(IFERROR(INDEX(EffectData!$G:$G,MATCH(L8,EffectData!$C:$C,0)),"")&";"=";","",IFERROR(INDEX(EffectData!$G:$G,MATCH(L8,EffectData!$C:$C,0)),"")&";") -> 201010602; | N8: =B8&C8&$O$2 -> 天涯月明章携吴钩4 | O8: =IFERROR(INDEX(EffectData!$G:$G,MATCH(O4,EffectData!$C:$C,0)),"")
A9: =VLOOKUP(D9,Sheet3!$C:$AP,40,0) -> 2010107 | B9: 天涯月明章 | C9: 折桂枝 | D9: 折桂枝 | F9: =I9&K9&M9&O9 -> 201010701;201010702;201010703; | G9: 0 | H9: =B9&C9&$I$2 -> 天涯月明章折桂枝1 | J9: =B9&C9&$K$2 -> 天涯月明章折桂枝2 | K9: =IF(IFERROR(INDEX(EffectData!$G:$G,MATCH(J9,EffectData!$C:$C,0)),"")&";"=";","",IFERROR(INDEX(EffectData!$G:$G,MATCH(J9,EffectData!$C:$C,0)),"")&";") -> 201010701; | L9: =B9&C9&$M$2 -> 天涯月明章折桂枝3 | M9: =IF(IFERROR(INDEX(EffectData!$G:$G,MATCH(L9,EffectData!$C:$C,0)),"")&";"=";","",IFERROR(INDEX(EffectData!$G:$G,MATCH(L9,EffectData!$C:$C,0)),"")&";") -> 201010702; | N9: =B9&C9&$O$2 -> 天涯月明章折桂枝4 | O9: =IF(IFERROR(INDEX(EffectData!$G:$G,MATCH(N9,EffectData!$C:$C,0)),"")&";"=";","",IFERROR(INDEX(EffectData!$G:$G,MATCH(N9,EffectData!$C:$C,0)),"")&";") -> 201010703;
A10: =VLOOKUP(D10,Sheet3!$C:$AP,40,0) -> 2010109 | B10: 天涯月明章 | C10: 共此时 | D10: 共此时 | F10: =I10&K10&M10&O10 -> 201010900; | G10: 0 | H10: =B10&C10&$I$2 -> 天涯月明章共此时1 | I10: =IF(IFERROR(INDEX(EffectData!$G:$G,MATCH(H10,EffectData!$C:$C,0)),"")&";"=";","",IFERROR(INDEX(EffectData!$G:$G,MATCH(H10,EffectData!$C:$C,0)),"")&";") -> 201010900; | J10: =B10&C10&$K$2 -> 天涯月明章共此时2 | L10: =B10&C10&$M$2 -> 天涯月明章共此时3 | M10: =IF(IFERROR(INDEX(EffectData!$G:$G,MATCH(L10,EffectData!$C:$C,0)),"")&";"=";","",IFERROR(INDEX(EffectData!$G:$G,MATCH(L10,EffectData!$C:$C,0)),"")&";") | N10: =B10&C10&$O$2 -> 天涯月明章共此时4 | O10: =IF(IFERROR(INDEX(EffectData!$G:$G,MATCH(N10,EffectData!$C:$C,0)),"")&";"=";","",IFERROR(INDEX(EffectData!$G:$G,MATCH(N10,EffectData!$C:$C,0)),"")&";") | P10: =B10&C10&$P$2 -> 天涯月明章共此时5 | Q10: =IFERROR(INDEX(EffectData!$G:$G,MATCH(P10,EffectData!$C:$C,0)),"")&";" -> ;
A11: =VLOOKUP(D11,Sheet3!$C:$AP,40,0) -> 2010201 | B11: 嗤魔祭血真经 | C11: 嗤魔万化 | D11: 嗤魔万化 | F11: =I11&K11&M11 -> 201020100;201020101; | H11: =B11&C11&$I$2 -> 嗤魔祭血真经嗤魔万化1 | I11: =IF(IFERROR(INDEX(EffectData!$G:$G,MATCH(H11,EffectData!$C:$C,0)),"")&";"=";","",IFERROR(INDEX(EffectData!$G:$G,MATCH(H11,EffectData!$C:$C,0)),"")&";") -> 201020100; | J11: =B11&C11&$K$2 -> 嗤魔祭血真经嗤魔万化2 | K11: =IF(IFERROR(INDEX(EffectData!$G:$G,MATCH(J11,EffectData!$C:$C,0)),"")&";"=";","",IFERROR(INDEX(EffectData!$G:$G,MATCH(J11,EffectData!$C:$C,0)),"")&";") -> 201020101;
A12: =VLOOKUP(D12,Sheet3!$C:$AP,40,0) -> 2010202 | B12: 嗤魔祭血真经 | C12: 鬼哭阴嚎 | D12: 鬼哭阴嚎 | F12: =I12&K12&M12 -> 201020200; | H12: =B12&C12&$I$2 -> 嗤魔祭血真经鬼哭阴嚎1 | I12: =IF(IFERROR(INDEX(EffectData!$G:$G,MATCH(H12,EffectData!$C:$C,0)),"")&";"=";","",IFERROR(INDEX(EffectData!$G:$G,MATCH(H12,EffectData!$C:$C,0)),"")&";") -> 201020200; | J12: =B12&C12&$K$2 -> 嗤魔祭血真经鬼哭阴嚎2 | K12: =IF(IFERROR(INDEX(EffectData!$G:$G,MATCH(J12,EffectData!$C:$C,0)),"")&";"=";","",IFERROR(INDEX(EffectData!$G:$G,MATCH(J12,EffectData!$C:$C,0)),"")&";")
A13: =VLOOKUP(D13,Sheet3!$C:$AP,40,0) -> 2010203 | B13: 嗤魔祭血真经 | C13: 附疽黄泉 | D13: 附疽黄泉 | F13: =I13&K13&M13 -> 201020300;201020301; | H13: =B13&C13&$I$2 -> 嗤魔祭血真经附疽黄泉1 | I13: =IF(IFERROR(INDEX(EffectData!$G:$G,MATCH(H13,EffectData!$C:$C,0)),"")&";"=";","",IFERROR(INDEX(EffectData!$G:$G,MATCH(H13,EffectData!$C:$C,0)),"")&";") -> 201020300; | J13: =B13&C13&$K$2 -> 嗤魔祭血真经附疽黄泉2 | K13: =IF(IFERROR(INDEX(EffectData!$G:$G,MATCH(J13,EffectData!$C:$C,0)),"")&";"=";","",IFERROR(INDEX(EffectData!$G:$G,MATCH(J13,EffectData!$C:$C,0)),"")&";") -> 201020301;
A14: =VLOOKUP(D14,Sheet3!$C:$AP,40,0) -> 2010204 | B14: 嗤魔祭血真经 | C14: 幽魂出窍 | D14: 幽魂出窍 | F14: =I14&K14&M14 -> 201020400;201020401; | H14: =B14&C14&$I$2 -> 嗤魔祭血真经幽魂出窍1 | I14: =IF(IFERROR(INDEX(EffectData!$G:$G,MATCH(H14,EffectData!$C:$C,0)),"")&";"=";","",IFERROR(INDEX(EffectData!$G:$G,MATCH(H14,EffectData!$C:$C,0)),"")&";") -> 201020400; | J14: =B14&C14&$K$2 -> 嗤魔祭血真经幽魂出窍2 | K14: =IF(IFERROR(INDEX(EffectData!$G:$G,MATCH(J14,EffectData!$C:$C,0)),"")&";"=";","",IFERROR(INDEX(EffectData!$G:$G,MATCH(J14,EffectData!$C:$C,0)),"")&";") -> 201020401;
A15: =VLOOKUP(D15,Sheet3!$C:$AP,40,0) -> 2010205 | B15: 嗤魔祭血真经 | C15: 残恶两生咒 | D15: 残恶两生咒 | F15: =I15&K15&M15 -> 201020500; | H15: =B15&C15&$I$2 -> 嗤魔祭血真经残恶两生咒1 | I15: =IF(IFERROR(INDEX(EffectData!$G:$G,MATCH(H15,EffectData!$C:$C,0)),"")&";"=";","",IFERROR(INDEX(EffectData!$G:$G,MATCH(H15,EffectData!$C:$C,0)),"")&";") -> 201020500; | J15: =B15&C15&$K$2 -> 嗤魔祭血真经残恶两生咒2 | K15: =IF(IFERROR(INDEX(EffectData!$G:$G,MATCH(J15,EffectData!$C:$C,0)),"")&";"=";","",IFERROR(INDEX(EffectData!$G:$G,MATCH(J15,EffectData!$C:$C,0)),"")&";")
A16: =VLOOKUP(D16,Sheet3!$C:$AP,40,0) -> 2010206 | B16: 嗤魔祭血真经 | C16: 恶鬼争食 | D16: 恶鬼争食 | F16: =I16&K16&M16 -> 201020600; | H16: =B16&C16&$I$2 -> 嗤魔祭血真经恶鬼争食1 | I16: =IF(IFERROR(INDEX(EffectData!$G:$G,MATCH(H16,EffectData!$C:$C,0)),"")&";"=";","",IFERROR(INDEX(EffectData!$G:$G,MATCH(H16,EffectData!$C:$C,0)),"")&";") -> 201020600; | J16: =B16&C16&$K$2 -> 嗤魔祭血真经恶鬼争食2 | K16: =IF(IFERROR(INDEX(EffectData!$G:$G,MATCH(J16,EffectData!$C:$C,0)),"")&";"=";","",IFERROR(INDEX(EffectData!$G:$G,MATCH(J16,EffectData!$C:$C,0)),"")&";")
A17: =VLOOKUP(D17,Sheet3!$C:$AP,40,0) -> 2010207 | B17: 嗤魔祭血真经 | C17: 瘟啼无间 | D17: 瘟啼无间 | F17: =I17&K17&M17 -> 201020700;201020701; | H17: =B17&C17&$I$2 -> 嗤魔祭血真经瘟啼无间1 | I17: =IF(IFERROR(INDEX(EffectData!$G:$G,MATCH(H17,EffectData!$C:$C,0)),"")&";"=";","",IFERROR(INDEX(EffectData!$G:$G,MATCH(H17,EffectData!$C:$C,0)),"")&";") -> 201020700; | J17: =B17&C17&$K$2 -> 嗤魔祭血真经瘟啼无间2 | K17: =IF(IFERROR(INDEX(EffectData!$G:$G,MATCH(J17,EffectData!$C:$C,0)),"")&";"=";","",IFERROR(INDEX(EffectData!$G:$G,MATCH(J17,EffectData!$C:$C,0)),"")&";") -> 201020701;
A18: =VLOOKUP(D18,Sheet3!$C:$AP,40,0) -> 2010209 | B18: 嗤魔祭血真经 | C18: 残躯转 | D18: 残躯转 | F18: =I18&K18&M18&O18 -> 201020900; | G18: 0 | H18: =B18&C18&$I$2 -> 嗤魔祭血真经残躯转1 | I18: =IF(IFERROR(INDEX(EffectData!$G:$G,MATCH(H18,EffectData!$C:$C,0)),"")&";"=";","",IFERROR(INDEX(EffectData!$G:$G,MATCH(H18,EffectData!$C:$C,0)),"")&";") -> 201020900; | J18: =B18&C18&$K$2 -> 嗤魔祭血真经残躯转2 | L18: =B18&C18&$M$2 -> 嗤魔祭血真经残躯转3 | M18: =IF(IFERROR(INDEX(EffectData!$G:$G,MATCH(L18,EffectData!$C:$C,0)),"")&";"=";","",IFERROR(INDEX(EffectData!$G:$G,MATCH(L18,EffectData!$C:$C,0)),"")&";") | N18: =B18&C18&$O$2 -> 嗤魔祭血真经残躯转4 | O18: =IF(IFERROR(INDEX(EffectData!$G:$G,MATCH(N18,EffectData!$C:$C,0)),"")&";"=";","",IFERROR(INDEX(EffectData!$G:$G,MATCH(N18,EffectData!$C:$C,0)),"")&";") | P18: =B18&C18&$P$2 -> 嗤魔祭血真经残躯转5 | Q18: =IFERROR(INDEX(EffectData!$G:$G,MATCH(P18,EffectData!$C:$C,0)),"")&";" -> ;
A19: =VLOOKUP(D19,Sheet3!$C:$AP,40,0) -> 2010301 | B19: 连珏天璧法 | C19: 璧碎珠沉 | D19: 璧碎珠沉 | F19: =I19&K19&M19 -> 201030100;201030101; | G19: 0 | H19: =B19&C19&$I$2 -> 连珏天璧法璧碎珠沉1 | I19: =IF(IFERROR(INDEX(EffectData!$G:$G,MATCH(H19,EffectData!$C:$C,0)),"")&";"=";","",IFERROR(INDEX(EffectData!$G:$G,MATCH(H19,EffectData!$C:$C,0)),"")&";") -> 201030100; | J19: =B19&C19&$K$2 -> 连珏天璧法璧碎珠沉2 | K19: =IF(IFERROR(INDEX(EffectData!$G:$G,MATCH(J19,EffectData!$C:$C,0)),"")&";"=";","",IFERROR(INDEX(EffectData!$G:$G,MATCH(J19,EffectData!$C:$C,0)),"")&";") -> 201030101; | L19: =B19&C19&$M$2 -> 连珏天璧法璧碎珠沉3 | N19: =B19&C19&$O$2 -> 连珏天璧法璧碎珠沉4 | O19: =IFERROR(INDEX(EffectData!$G:$G,MATCH(O9,EffectData!$C:$C,0)),"")
A20: =VLOOKUP(D20,Sheet3!$C:$AP,40,0) -> 2010302 | B20: 连珏天璧法 | C20: 圭角无痕 | D20: 圭角无痕 | F20: =I20&K20&M20 -> 201030200; | G20: 0 | H20: =B20&C20&$I$2 -> 连珏天璧法圭角无痕1 | I20: =IF(IFERROR(INDEX(EffectData!$G:$G,MATCH(H20,EffectData!$C:$C,0)),"")&";"=";","",IFERROR(INDEX(EffectData!$G:$G,MATCH(H20,EffectData!$C:$C,0)),"")&";") -> 201030200; | J20: =B20&C20&$K$2 -> 连珏天璧法圭角无痕2 | L20: =B20&C20&$M$2 -> 连珏天璧法圭角无痕3
A21: =VLOOKUP(D21,Sheet3!$C:$AP,40,0) -> 2010303 | B21: 连珏天璧法 | C21: 璞玉浑金 | D21: 璞玉浑金 | F21: =I21&K21&M21 -> 201030300; | G21: 0 | H21: =B21&C21&$I$2 -> 连珏天璧法璞玉浑金1 | I21: =IF(IFERROR(INDEX(EffectData!$G:$G,MATCH(H21,EffectData!$C:$C,0)),"")&";"=";","",IFERROR(INDEX(EffectData!$G:$G,MATCH(H21,EffectData!$C:$C,0)),"")&";") -> 201030300; | J21: =B21&C21&$K$2 -> 连珏天璧法璞玉浑金2 | L21: =B21&C21&$M$2 -> 连珏天璧法璞玉浑金3
A22: =VLOOKUP(D22,Sheet3!$C:$AP,40,0) -> 2010304 | B22: 连珏天璧法 | C22: 乱琼碎玉 | D22: 乱琼碎玉 | F22: =I22&K22&M22 -> 201030400;201030401; | G22: 0 | H22: =B22&C22&$I$2 -> 连珏天璧法乱琼碎玉1 | I22: =IF(IFERROR(INDEX(EffectData!$G:$G,MATCH(H22,EffectData!$C:$C,0)),"")&";"=";","",IFERROR(INDEX(EffectData!$G:$G,MATCH(H22,EffectData!$C:$C,0)),"")&";") -> 201030400; | J22: =B22&C22&$K$2 -> 连珏天璧法乱琼碎玉2 | K22: =IF(IFERROR(INDEX(EffectData!$G:$G,MATCH(J22,EffectData!$C:$C,0)),"")&";"=";","",IFERROR(INDEX(EffectData!$G:$G,MATCH(J22,EffectData!$C:$C,0)),"")&";") -> 201030401; | L22: =B22&C22&$M$2 -> 连珏天璧法乱琼碎玉3 | N22: =B22&C22&$O$2 -> 连珏天璧法乱琼碎玉4 | O22: =IFERROR(INDEX(EffectData!$G:$G,MATCH(O19,EffectData!$C:$C,0)),"")
A23: =VLOOKUP(D23,Sheet3!$C:$AP,40,0) -> 2010305 | B23: 连珏天璧法 | C23: 白璧无瑕 | D23: 白璧无瑕 | F23: =I23&K23&M23 -> 201030500; | G23: 0 | H23: =B23&C23&$I$2 -> 连珏天璧法白璧无瑕1 | I23: =IF(IFERROR(INDEX(EffectData!$G:$G,MATCH(H23,EffectData!$C:$C,0)),"")&";"=";","",IFERROR(INDEX(EffectData!$G:$G,MATCH(H23,EffectData!$C:$C,0)),"")&";") -> 201030500; | J23: =B23&C23&$K$2 -> 连珏天璧法白璧无瑕2
A24: =VLOOKUP(D24,Sheet3!$C:$AP,40,0) -> 2010306 | B24: 连珏天璧法 | C24: 金枝菩树 | D24: 金枝菩树 | F24: =I24&K24&M24 -> 201030600; | G24: 0 | H24: =B24&C24&$I$2 -> 连珏天璧法金枝菩树1 | I24: =IF(IFERROR(INDEX(EffectData!$G:$G,MATCH(H24,EffectData!$C:$C,0)),"")&";"=";","",IFERROR(INDEX(EffectData!$G:$G,MATCH(H24,EffectData!$C:$C,0)),"")&";") -> 201030600; | J24: =B24&C24&$K$2 -> 连珏天璧法金枝菩树2 | L24: =B24&C24&$M$2 -> 连珏天璧法金枝菩树3 | N24: =B24&C24&$O$2 -> 连珏天璧法金枝菩树4 | O24: =IFERROR(INDEX(EffectData!$G:$G,MATCH(O21,EffectData!$C:$C,0)),"")
A25: =VLOOKUP(D25,Sheet3!$C:$AP,40,0) -> 2010307 | B25: 连珏天璧法 | C25: 珠联璧合 | D25: 珠联璧合 | F25: =I25&K25&M25 -> 201030700;201030701; | G25: 0 | H25: =B25&C25&$I$2 -> 连珏天璧法珠联璧合1 | I25: =IF(IFERROR(INDEX(EffectData!$G:$G,MATCH(H25,EffectData!$C:$C,0)),"")&";"=";","",IFERROR(INDEX(EffectData!$G:$G,MATCH(H25,EffectData!$C:$C,0)),"")&";") -> 201030700; | J25: =B25&C25&$K$2 -> 连珏天璧法珠联璧合2 | K25: =IF(IFERROR(INDEX(EffectData!$G:$G,MATCH(J25,EffectData!$C:$C,0)),"")&";"=";","",IFERROR(INDEX(EffectData!$G:$G,MATCH(J25,EffectData!$C:$C,0)),"")&";") -> 201030701; | L25: =B25&C25&$M$2 -> 连珏天璧法珠联璧合3 | N25: =B25&C25&$O$2 -> 连珏天璧法珠联璧合4 | O25: =IFERROR(INDEX(EffectData!$G:$G,MATCH(O22,EffectData!$C:$C,0)),"")
A26: =VLOOKUP(D26,Sheet3!$C:$AP,40,0) -> 2010308 | B26: 连珏天璧法 | C26: 完璧不破 | D26: 完璧不破 | F26: =I26&K26&M26 -> 201030800; | G26: 0 | H26: =B26&C26&$I$2 -> 连珏天璧法完璧不破1 | I26: =IF(IFERROR(INDEX(EffectData!$G:$G,MATCH(H26,EffectData!$C:$C,0)),"")&";"=";","",IFERROR(INDEX(EffectData!$G:$G,MATCH(H26,EffectData!$C:$C,0)),"")&";") -> 201030800; | J26: =B26&C26&$K$2 -> 连珏天璧法完璧不破2
A27: =VLOOKUP(D27,Sheet3!$C:$AP,40,0) -> 2010309 | B27: 连珏天璧法 | C27: 不破壁 | D27: 不破壁 | F27: =I27&K27&M27&O27 -> 201030900; | G27: 0 | H27: =B27&C27&$I$2 -> 连珏天璧法不破壁1 | I27: =IF(IFERROR(INDEX(EffectData!$G:$G,MATCH(H27,EffectData!$C:$C,0)),"")&";"=";","",IFERROR(INDEX(EffectData!$G:$G,MATCH(H27,EffectData!$C:$C,0)),"")&";") -> 201030900; | J27: =B27&C27&$K$2 -> 连珏天璧法不破壁2 | L27: =B27&C27&$M$2 -> 连珏天璧法不破壁3 | M27: =IF(IFERROR(INDEX(EffectData!$G:$G,MATCH(L27,EffectData!$C:$C,0)),"")&";"=";","",IFERROR(INDEX(EffectData!$G:$G,MATCH(L27,EffectData!$C:$C,0)),"")&";") | N27: =B27&C27&$O$2 -> 连珏天璧法不破壁4 | O27: =IF(IFERROR(INDEX(EffectData!$G:$G,MATCH(N27,EffectData!$C:$C,0)),"")&";"=";","",IFERROR(INDEX(EffectData!$G:$G,MATCH(N27,EffectData!$C:$C,0)),"")&";") | P27: =B27&C27&$P$2 -> 连珏天璧法不破壁5 | Q27: =IFERROR(INDEX(EffectData!$G:$G,MATCH(P27,EffectData!$C:$C,0)),"")&";" -> ;
A28: =VLOOKUP(D28,Sheet3!$C:$AP,40,0) -> 2010401 | B28: 玄黎蛊瘴 | C28: 赤蛛织心 | D28: 赤蛛织心 | F28: =I28&K28&M28&O28 -> 201040100;201040101; | G28: 0 | H28: =B28&C28&$I$2 -> 玄黎蛊瘴赤蛛织心1 | I28: =IF(IFERROR(INDEX(EffectData!$G:$G,MATCH(H28,EffectData!$C:$C,0)),"")&";"=";","",IFERROR(INDEX(EffectData!$G:$G,MATCH(H28,EffectData!$C:$C,0)),"")&";") -> 201040100; | J28: =B28&C28&$K$2 -> 玄黎蛊瘴赤蛛织心2 | K28: =IF(IFERROR(INDEX(EffectData!$G:$G,MATCH(J28,EffectData!$C:$C,0)),"")&";"=";","",IFERROR(INDEX(EffectData!$G:$G,MATCH(J28,EffectData!$C:$C,0)),"")&";") -> 201040101; | L28: =B28&C28&$M$2 -> 玄黎蛊瘴赤蛛织心3 | M28: =IF(IFERROR(INDEX(EffectData!$G:$G,MATCH(L28,EffectData!$C:$C,0)),"")&";"=";","",IFERROR(INDEX(EffectData!$G:$G,MATCH(L28,EffectData!$C:$C,0)),"")&";") | N28: =B28&C28&$O$2 -> 玄黎蛊瘴赤蛛织心4 | O28: =IF(IFERROR(INDEX(EffectData!$G:$G,MATCH(N28,EffectData!$C:$C,0)),"")&";"=";","",IFERROR(INDEX(EffectData!$G:$G,MATCH(N28,EffectData!$C:$C,0)),"")&";")
A29: =VLOOKUP(D29,Sheet3!$C:$AP,40,0) -> 2010402 | B29: 玄黎蛊瘴 | C29: 天龙披山 | D29: 天龙披山 | F29: =I29&K29&M29 -> 201040200; | G29: 0 | H29: =B29&C29&$I$2 -> 玄黎蛊瘴天龙披山1 | I29: =IF(IFERROR(INDEX(EffectData!$G:$G,MATCH(H29,EffectData!$C:$C,0)),"")&";"=";","",IFERROR(INDEX(EffectData!$G:$G,MATCH(H29,EffectData!$C:$C,0)),"")&";") -> 201040200; | J29: =B29&C29&$K$2 -> 玄黎蛊瘴天龙披山2 | L29: =B29&C29&$M$2 -> 玄黎蛊瘴天龙披山3
A30: =VLOOKUP(D30,Sheet3!$C:$AP,40,0) -> 2010403 | B30: 玄黎蛊瘴 | C30: 撩蝎剔骨 | D30: 撩蝎剔骨 | F30: =I30&K30&M30 -> 201040300; | G30: 0 | H30: =B30&C30&$I$2 -> 玄黎蛊瘴撩蝎剔骨1 | I30: =IF(IFERROR(INDEX(EffectData!$G:$G,MATCH(H30,EffectData!$C:$C,0)),"")&";"=";","",IFERROR(INDEX(EffectData!$G:$G,MATCH(H30,EffectData!$C:$C,0)),"")&";") -> 201040300; | J30: =B30&C30&$K$2 -> 玄黎蛊瘴撩蝎剔骨2 | L30: =B30&C30&$M$2 -> 玄黎蛊瘴撩蝎剔骨3
A31: =VLOOKUP(D31,Sheet3!$C:$AP,40,0) -> 2010404 | B31: 玄黎蛊瘴 | C31: 仙蛛缠月 | D31: 仙蛛缠月 | F31: =I31&K31&M31 -> 201040400;201040402; | G31: 0 | H31: =B31&C31&$I$2 -> 玄黎蛊瘴仙蛛缠月1 | I31: =IF(IFERROR(INDEX(EffectData!$G:$G,MATCH(H31,EffectData!$C:$C,0)),"")&";"=";","",IFERROR(INDEX(EffectData!$G:$G,MATCH(H31,EffectData!$C:$C,0)),"")&";") -> 201040400; | J31: =B31&C31&$K$2 -> 玄黎蛊瘴仙蛛缠月2 | L31: =B31&C31&$M$2 -> 玄黎蛊瘴仙蛛缠月3 | M31: =IF(IFERROR(INDEX(EffectData!$G:$G,MATCH(L31,EffectData!$C:$C,0)),"")&";"=";","",IFERROR(INDEX(EffectData!$G:$G,MATCH(L31,EffectData!$C:$C,0)),"")&";") -> 201040402;
A32: =VLOOKUP(D32,Sheet3!$C:$AP,40,0) -> 2010405 | B32: 玄黎蛊瘴 | C32: 灵蛇淬骨 | D32: 灵蛇淬骨 | F32: =I32&K32&M32 -> 201040500;201040501; | G32: 0 | H32: =B32&C32&$I$2 -> 玄黎蛊瘴灵蛇淬骨1 | I32: =IF(IFERROR(INDEX(EffectData!$G:$G,MATCH(H32,EffectData!$C:$C,0)),"")&";"=";","",IFERROR(INDEX(EffectData!$G:$G,MATCH(H32,EffectData!$C:$C,0)),"")&";") -> 201040500; | J32: =B32&C32&$K$2 -> 玄黎蛊瘴灵蛇淬骨2 | K32: =IF(IFERROR(INDEX(EffectData!$G:$G,MATCH(J32,EffectData!$C:$C,0)),"")&";"=";","",IFERROR(INDEX(EffectData!$G:$G,MATCH(J32,EffectData!$C:$C,0)),"")&";") -> 201040501; | L32: =B32&C32&$M$2 -> 玄黎蛊瘴灵蛇淬骨3
A33: =VLOOKUP(D33,Sheet3!$C:$AP,40,0) -> 2010407 | B33: 玄黎蛊瘴 | C33: 金蟾宝衣 | D33: 金蟾宝衣 | F33: =I33&K33&M33 -> 201040700; | G33: 0 | H33: =B33&C33&$I$2 -> 玄黎蛊瘴金蟾宝衣1 | I33: =IF(IFERROR(INDEX(EffectData!$G:$G,MATCH(H33,EffectData!$C:$C,0)),"")&";"=";","",IFERROR(INDEX(EffectData!$G:$G,MATCH(H33,EffectData!$C:$C,0)),"")&";") -> 201040700; | J33: =B33&C33&$K$2 -> 玄黎蛊瘴金蟾宝衣2 | L33: =B33&C33&$M$2 -> 玄黎蛊瘴金蟾宝衣3 | M33: =IF(IFERROR(INDEX(EffectData!$G:$G,MATCH(L33,EffectData!$C:$C,0)),"")&";"=";","",IFERROR(INDEX(EffectData!$G:$G,MATCH(L33,EffectData!$C:$C,0)),"")&";")
A34: =VLOOKUP(D34,Sheet3!$C:$AP,40,0) -> 2010408 | B34: 玄黎蛊瘴 | C34: 玄黎蛊体 | D34: 玄黎蛊体 | F34: =I34&K34&M34 -> 201040800; | G34: 0 | H34: =B34&C34&$I$2 -> 玄黎蛊瘴玄黎蛊体1 | I34: =IF(IFERROR(INDEX(EffectData!$G:$G,MATCH(H34,EffectData!$C:$C,0)),"")&";"=";","",IFERROR(INDEX(EffectData!$G:$G,MATCH(H34,EffectData!$C:$C,0)),"")&";") -> 201040800; | J34: =B34&C34&$K$2 -> 玄黎蛊瘴玄黎蛊体2 | L34: =B34&C34&$M$2 -> 玄黎蛊瘴玄黎蛊体3 | M34: =IF(IFERROR(INDEX(EffectData!$G:$G,MATCH(L34,EffectData!$C:$C,0)),"")&";"=";","",IFERROR(INDEX(EffectData!$G:$G,MATCH(L34,EffectData!$C:$C,0)),"")&";")
A35: =VLOOKUP(D35,Sheet3!$C:$AP,40,0) -> 2010409 | B35: 玄黎蛊瘴 | C35: 蚩尤身 | D35: 蚩尤身 | F35: =I35&K35&M35 -> 201040900; | G35: 0 | H35: =B35&C35&$I$2 -> 玄黎蛊瘴蚩尤身1 | I35: =IF(IFERROR(INDEX(EffectData!$G:$G,MATCH(H35,EffectData!$C:$C,0)),"")&";"=";","",IFERROR(INDEX(EffectData!$G:$G,MATCH(H35,EffectData!$C:$C,0)),"")&";") -> 201040900; | J35: =B35&C35&$K$2 -> 玄黎蛊瘴蚩尤身2 | L35: =B35&C35&$M$2 -> 玄黎蛊瘴蚩尤身3 | M35: =IF(IFERROR(INDEX(EffectData!$G:$G,MATCH(L35,EffectData!$C:$C,0)),"")&";"=";","",IFERROR(INDEX(EffectData!$G:$G,MATCH(L35,EffectData!$C:$C,0)),"")&";")
A36: =VLOOKUP(D36,Sheet3!$C:$AP,40,0) -> 2010501 | B36: 三昧阿修罗道 | C36: 罗睺忿身相 | D36: 罗睺忿身相 | F36: =I36&K36&M36&O36 -> 201050100; | G36: 0 | H36: =B36&C36&$I$2 -> 三昧阿修罗道罗睺忿身相1 | I36: =IF(IFERROR(INDEX(EffectData!$G:$G,MATCH(H36,EffectData!$C:$C,0)),"")&";"=";","",IFERROR(INDEX(EffectData!$G:$G,MATCH(H36,EffectData!$C:$C,0)),"")&";") -> 201050100; | J36: =B36&C36&$K$2 -> 三昧阿修罗道罗睺忿身相2 | K36: =IF(IFERROR(INDEX(EffectData!$G:$G,MATCH(J36,EffectData!$C:$C,0)),"")&";"=";","",IFERROR(INDEX(EffectData!$G:$G,MATCH(J36,EffectData!$C:$C,0)),"")&";") | L36: =B36&C36&$M$2 -> 三昧阿修罗道罗睺忿身相3 | N36: =B36&C36&$O$2 -> 三昧阿修罗道罗睺忿身相4 | O36: =IFERROR(INDEX(EffectData!$G:$G,MATCH(O32,EffectData!$C:$C,0)),"")
A37: =VLOOKUP(D37,Sheet3!$C:$AP,40,0) -> 2010502 | B37: 三昧阿修罗道 | C37: 广纳障孽 | D37: 广纳障孽 | F37: =I37&K37&M37&O37 -> 201050200;201050201; | G37: 0 | H37: =B37&C37&$I$2 -> 三昧阿修罗道广纳障孽1 | I37: =IF(IFERROR(INDEX(EffectData!$G:$G,MATCH(H37,EffectData!$C:$C,0)),"")&";"=";","",IFERROR(INDEX(EffectData!$G:$G,MATCH(H37,EffectData!$C:$C,0)),"")&";") -> 201050200; | J37: =B37&C37&$K$2 -> 三昧阿修罗道广纳障孽2 | K37: =IF(IFERROR(INDEX(EffectData!$G:$G,MATCH(J37,EffectData!$C:$C,0)),"")&";"=";","",IFERROR(INDEX(EffectData!$G:$G,MATCH(J37,EffectData!$C:$C,0)),"")&";") -> 201050201; | L37: =B37&C37&$M$2 -> 三昧阿修罗道广纳障孽3 | N37: =B37&C37&$O$2 -> 三昧阿修罗道广纳障孽4 | O37: =IFERROR(INDEX(EffectData!$G:$G,MATCH(O32,EffectData!$C:$C,0)),"")
A38: =VLOOKUP(D38,Sheet3!$C:$AP,40,0) -> 2010503 | B38: 三昧阿修罗道 | C38: 刹鬼缚身 | D38: 刹鬼缚身 | F38: =I38&K38&M38&O38 -> 201050300; | G38: 0 | H38: =B38&C38&$I$2 -> 三昧阿修罗道刹鬼缚身1 | I38: =IF(IFERROR(INDEX(EffectData!$G:$G,MATCH(H38,EffectData!$C:$C,0)),"")&";"=";","",IFERROR(INDEX(EffectData!$G:$G,MATCH(H38,EffectData!$C:$C,0)),"")&";") -> 201050300; | J38: =B38&C38&$K$2 -> 三昧阿修罗道刹鬼缚身2 | L38: =B38&C38&$M$2 -> 三昧阿修罗道刹鬼缚身3 | N38: =B38&C38&$O$2 -> 三昧阿修罗道刹鬼缚身4 | O38: =IFERROR(INDEX(EffectData!$G:$G,MATCH(O32,EffectData!$C:$C,0)),"")
A39: =VLOOKUP(D39,Sheet3!$C:$AP,40,0) -> 2010504 | B39: 三昧阿修罗道 | C39: 黑绳众狱 | D39: 黑绳众狱 | F39: =I39&K39&M39&O39 -> 201050400; | G39: 0 | H39: =B39&C39&$I$2 -> 三昧阿修罗道黑绳众狱1 | I39: =IF(IFERROR(INDEX(EffectData!$G:$G,MATCH(H39,EffectData!$C:$C,0)),"")&";"=";","",IFERROR(INDEX(EffectData!$G:$G,MATCH(H39,EffectData!$C:$C,0)),"")&";") -> 201050400; | J39: =B39&C39&$K$2 -> 三昧阿修罗道黑绳众狱2 | L39: =B39&C39&$M$2 -> 三昧阿修罗道黑绳众狱3 | N39: =B39&C39&$O$2 -> 三昧阿修罗道黑绳众狱4 | O39: =IFERROR(INDEX(EffectData!$G:$G,MATCH(O33,EffectData!$C:$C,0)),"")
A40: =VLOOKUP(D40,Sheet3!$C:$AP,40,0) -> 2010505 | B40: 三昧阿修罗道 | C40: 明王身 | D40: 明王身 | F40: =I40&K40&M40&O40 -> 201050500;201050501; | G40: 0 | H40: =B40&C40&$I$2 -> 三昧阿修罗道明王身1 | I40: =IF(IFERROR(INDEX(EffectData!$G:$G,MATCH(H40,EffectData!$C:$C,0)),"")&";"=";","",IFERROR(INDEX(EffectData!$G:$G,MATCH(H40,EffectData!$C:$C,0)),"")&";") -> 201050500; | J40: =B40&C40&$K$2 -> 三昧阿修罗道明王身2 | K40: =IF(IFERROR(INDEX(EffectData!$G:$G,MATCH(J40,EffectData!$C:$C,0)),"")&";"=";","",IFERROR(INDEX(EffectData!$G:$G,MATCH(J40,EffectData!$C:$C,0)),"")&";") -> 201050501; | L40: =B40&C40&$M$2 -> 三昧阿修罗道明王身3 | N40: =B40&C40&$O$2 -> 三昧阿修罗道明王身4 | O40: =IFERROR(INDEX(EffectData!$G:$G,MATCH(O36,EffectData!$C:$C,0)),"")
...

Sheet EffectData
H1: 事件类型 | I1: 条件类型 | J1: 条件参数 | K1: 额外条件 | L1: 动作目标类型 | M1: 动作类型 | N1: 动作参数 | O1: 冷却时间 | P1: 最大触发次数
E2: 备注 | G2: id | H2: eventTypeInt | I2: conditionTypeInt | J2: conditionParamListStr | K2: exConditionListStr | L2: actionTargetTypeInt | M2: actionTypeInt | N2: actionParamListStr | O2: cd | P2: maxCount
A3: 1 | B3: 2 | C3: =D3&E3&A3 -> 天涯月明章朔独还1 | D3: 天涯月明章 | E3: 朔独还 | F3: 增攻 | G3: =VLOOKUP(E3,Sheet3!$C:$AP,40,0)*100+IF(A3=1,0,0)+IF(A3=2,1,0)+IF(A3=3,2,0)+IF(A3=4,3,0) -> 201010100 | H3: 1 | I3: 0 | J3: 0 | L3: 1 | M3: 1 | N3: =Q3&R3&S3&T3&U3&V3 -> 20101011,1 | O3: 0 | P3: -1 | Q3: =VLOOKUP(E3,Sheet3!$C:$AP,40,0)*10+IF(B3=1,0,0)+IF(B3=2,1,0)+IF(B3=3,2,0)+IF(B3=4,3,0) -> 20101011 | R3: =IF(H3=1,",1","") -> ,1 | S3: =IF(AND(H3=2,I3=1,J3="hp",L3=1,M3=2),",-1","") | T3: =IF(AND(H3=2,I3=1,J3="hp",L3=1,M3=1),",(最大气血-hp)/最大气血*100","") | U3: =IF(AND(H3=2,I3=1,J3="hp,(hp/气血值)<=0.2",L3=1,M3=3),",气血值*1006","")
A4: 2 | B4: 4 | C4: =D4&E4&A4 -> 天涯月明章朔独还2 | D4: 天涯月明章 | E4: 朔独还 | F4: 减防 | G4: =VLOOKUP(E4,Sheet3!$C:$AP,40,0)*100+IF(A4=1,0,0)+IF(A4=2,1,0)+IF(A4=3,2,0)+IF(A4=4,3,0) -> 201010101 | H4: 1 | I4: 0 | J4: 0 | L4: 1 | M4: 1 | N4: =Q4&R4&S4&T4&U4&V4 -> 20101013,1 | O4: 0 | P4: -1 | Q4: =VLOOKUP(E4,Sheet3!$C:$AP,40,0)*10+IF(B4=1,0,0)+IF(B4=2,1,0)+IF(B4=3,2,0)+IF(B4=4,3,0) -> 20101013 | R4: =IF(H4=1,",1","") -> ,1 | S4: =IF(AND(H4=2,I4=1,J4="hp",L4=1,M4=2),",-1","") | T4: =IF(AND(H4=2,I4=1,J4="hp",L4=1,M4=1),",(最大气血-hp)/最大气血*100","") | U4: =IF(AND(H4=2,I4=1,J4="hp,(hp/气血值)<=0.2",L4=1,M4=3),",气血值*1006","")
A5: 1 | B5: 1 | C5: =D5&E5&A5 -> 天涯月明章执无言1 | D5: 天涯月明章 | E5: 执无言 | F5: 修改气血回复 | G5: =VLOOKUP(E5,Sheet3!$C:$AP,40,0)*100+IF(A5=1,0,0)+IF(A5=2,1,0)+IF(A5=3,2,0)+IF(A5=4,3,0) -> 201010200 | H5: 1 | I5: 0 | J5: 0 | L5: 1 | M5: 1 | N5: =Q5&R5&S5&T5&U5&V5 -> 20101020,1 | O5: 0 | P5: -1 | Q5: =VLOOKUP(E5,Sheet3!$C:$AP,40,0)*10+IF(B5=1,0,0)+IF(B5=2,1,0)+IF(B5=3,2,0)+IF(B5=4,3,0) -> 20101020 | R5: =IF(H5=1,",1","") -> ,1
A6: 1 | B6: 1 | C6: =D6&E6&A6 -> 天涯月明章涯无书1 | D6: 天涯月明章 | E6: 涯无书 | F6: 修改暴击几率 | G6: =VLOOKUP(E6,Sheet3!$C:$AP,40,0)*100+IF(A6=1,0,0)+IF(A6=2,1,0)+IF(A6=3,2,0)+IF(A6=4,3,0) -> 201010300 | H6: 1 | I6: 0 | J6: 0 | L6: 1 | M6: 1 | N6: =Q6&R6&S6&T6&U6&V6 -> 20101030,1 | O6: 0 | P6: -1 | Q6: =VLOOKUP(E6,Sheet3!$C:$AP,40,0)*10+IF(B6=1,0,0)+IF(B6=2,1,0)+IF(B6=3,2,0)+IF(B6=4,3,0) -> 20101030 | R6: =IF(H6=1,",1","") -> ,1
A7: 2 | B7: 2 | C7: =D7&E7&A7 -> 天涯月明章晓月残星2 | D7: 天涯月明章 | E7: 晓月残星 | F7: 增攻 | G7: =VLOOKUP(E7,Sheet3!$C:$AP,40,0)*100+IF(A7=1,0,0)+IF(A7=2,1,0)+IF(A7=3,2,0)+IF(A7=4,3,0) -> 201010401 | H7: 1 | I7: 0 | J7: 0 | L7: 1 | M7: 1 | N7: =Q7&R7&S7&T7&U7&V7 -> 20101041,1 | O7: 0 | P7: -1 | Q7: =VLOOKUP(E7,Sheet3!$C:$AP,40,0)*10+IF(B7=1,0,0)+IF(B7=2,1,0)+IF(B7=3,2,0)+IF(B7=4,3,0) -> 20101041 | R7: =IF(H7=1,",1","") -> ,1 | S7: =IF(AND(H7=2,I7=1,J7="hp",L7=1,M7=2),",-1","") | T7: =IF(AND(H7=2,I7=1,J7="hp",L7=1,M7=1),",(最大气血-hp)/最大气血*100","") | U7: =IF(AND(H7=2,I7=1,J7="hp,(hp/气血值)<=0.2",L7=1,M7=3),"气血值*1006","")
A8: 3 | B8: 4 | C8: =D8&E8&A8 -> 天涯月明章晓月残星3 | D8: 天涯月明章 | E8: 晓月残星 | F8: 减防 | G8: =VLOOKUP(E8,Sheet3!$C:$AP,40,0)*100+IF(A8=1,0,0)+IF(A8=2,1,0)+IF(A8=3,2,0)+IF(A8=4,3,0) -> 201010402 | H8: 1 | I8: 0 | J8: 0 | L8: 1 | M8: 1 | N8: =Q8&R8&S8&T8&U8&V8 -> 20101043,1 | O8: 0 | P8: -1 | Q8: =VLOOKUP(E8,Sheet3!$C:$AP,40,0)*10+IF(B8=1,0,0)+IF(B8=2,1,0)+IF(B8=3,2,0)+IF(B8=4,3,0) -> 20101043 | R8: =IF(H8=1,",1","") -> ,1 | S8: =IF(AND(H8=2,I8=1,J8="hp",L8=1,M8=2),",-1","") | T8: =IF(AND(H8=2,I8=1,J8="hp",L8=1,M8=1),",(最大气血-hp)/最大气血*100","") | U8: =IF(AND(H8=2,I8=1,J8="hp,(hp/气血值)<=0.2",L8=1,M8=3),"气血值*1006","")
A9: 4 | B9: 3 | C9: =D9&E9&A9 -> 天涯月明章晓月残星4 | D9: 天涯月明章 | E9: 晓月残星 | F9: 减CD | G9: =VLOOKUP(E9,Sheet3!$C:$AP,40,0)*100+IF(A9=1,0,0)+IF(A9=2,1,0)+IF(A9=3,2,0)+IF(A9=4,3,0) -> 201010403 | H9: 1 | I9: 0 | J9: 0 | L9: 1 | M9: 1 | N9: =Q9&R9&S9&T9&U9&V9 -> 20101044,1 | O9: 0 | P9: -1 | Q9: 20101044 | R9: =IF(H9=1,",1","") -> ,1 | S9: =IF(AND(H9=2,I9=1,J9="hp",L9=1,M9=2),",-1","") | T9: =IF(AND(H9=2,I9=1,J9="hp",L9=1,M9=1),",(最大气血-hp)/最大气血*100","") | U9: =IF(AND(H9=2,I9=1,J9="hp,(hp/气血值)<=0.2",L9=1,M9=3),"气血值*1006","")
A10: 1 | B10: 1 | C10: =D10&E10&A10 -> 天涯月明章人踟躇1 | D10: 天涯月明章 | E10: 人踟躇 | F10: 产生暴击后提高移动速度10% | G10: =VLOOKUP(E10,Sheet3!$C:$AP,40,0)*100+IF(A10=1,0,0)+IF(A10=2,1,0)+IF(A10=3,2,0)+IF(A10=4,3,0) -> 201010500 | H10: 3 | I10: 1 | J10: 1,伤害>1,1 | L10: 1 | M10: 1 | N10: =Q10&R10&S10&T10&U10&V10 -> 20101050,1 | O10: 0 | P10: -1 | Q10: =VLOOKUP(E10,Sheet3!$C:$AP,40,0)*10+IF(B10=1,0,0)+IF(B10=2,1,0)+IF(B10=3,2,0)+IF(B10=4,3,0) -> 20101050 | R10: =IF(H10=3,",1","") -> ,1 | S10: =IF(AND(H10=2,I10=1,J10="hp",L10=1,M10=2),",-1","") | T10: =IF(AND(H10=2,I10=1,J10="hp",L10=1,M10=1),",(最大气血-hp)/最大气血*100","") | U10: =IF(AND(H10=2,I10=1,J10="hp,(hp/气血值)<=0.2",L10=1,M10=3),"气血值*1006","")
A11: 1 | B11: 1 | C11: =D11&E11&A11 -> 天涯月明章携吴钩1 | D11: 天涯月明章 | E11: 携吴钩 | F11: 焚沧断海 | G11: =VLOOKUP(E11,Sheet3!$C:$AP,40,0)*100+IF(A11=1,0,0)+IF(A11=2,1,0)+IF(A11=3,2,0)+IF(A11=4,3,0) -> 201010600 | H11: 8 | I11: 1 | J11: 1020401 | L11: 1 | M11: 1 | N11: =Q11&R11&S11&T11&U11&V11 -> 20101060,1 | O11: 0 | P11: -1 | Q11: =VLOOKUP(E11,Sheet3!$C:$AP,40,0)*10+IF(B11=1,0,0)+IF(B11=2,1,0)+IF(B11=3,2,0)+IF(B11=4,3,0) -> 20101060 | R11: =IF(H11=8,",1","") -> ,1 | S11: =IF(AND(H11=2,I11=1,J11="hp",L11=1,M11=2),",-1","") | T11: =IF(AND(H11=2,I11=1,J11="hp",L11=1,M11=1),",(最大气血-hp)/最大气血*100","") | U11: =IF(AND(H11=2,I11=1,J11="hp,(hp/气血值)<=0.2",L11=1,M11=3),"气血值*1006","")
A12: 2 | B12: 2 | C12: =D12&E12&A12 -> 天涯月明章携吴钩2 | D12: 天涯月明章 | E12: 携吴钩 | F12: 临碣寒 | G12: =VLOOKUP(E12,Sheet3!$C:$AP,40,0)*100+IF(A12=1,0,0)+IF(A12=2,1,0)+IF(A12=3,2,0)+IF(A12=4,3,0) -> 201010601 | H12: 8 | I12: 1 | J12: 1020403 | L12: 1 | M12: 1 | N12: =Q12&R12&S12&T12&U12&V12 -> 20101061,1 | O12: 0 | P12: -1 | Q12: =VLOOKUP(E12,Sheet3!$C:$AP,40,0)*10+IF(B12=1,0,0)+IF(B12=2,1,0)+IF(B12=3,2,0)+IF(B12=4,3,0) -> 20101061 | R12: =IF(H12=8,",1","") -> ,1 | S12: =IF(AND(H12=2,I12=1,J12="hp",L12=1,M12=2),",-1","") | T12: =IF(AND(H12=2,I12=1,J12="hp",L12=1,M12=1),",(最大气血-hp)/最大气血*100","") | U12: =IF(AND(H12=2,I12=1,J12="hp,(hp/气血值)<=0.2",L12=1,M12=3),"气血值*1006","")
A13: 3 | B13: 3 | C13: =D13&E13&A13 -> 天涯月明章携吴钩3 | D13: 天涯月明章 | E13: 携吴钩 | F13: 骇浪惊涛 | G13: =VLOOKUP(E13,Sheet3!$C:$AP,40,0)*100+IF(A13=1,0,0)+IF(A13=2,1,0)+IF(A13=3,2,0)+IF(A13=4,3,0) -> 201010602 | H13: 8 | I13: 1 | J13: 1020405 | L13: 1 | M13: 1 | N13: =Q13&R13&S13&T13&U13&V13 -> 20101062,1 | O13: 0 | P13: -1 | Q13: =VLOOKUP(E13,Sheet3!$C:$AP,40,0)*10+IF(B13=1,0,0)+IF(B13=2,1,0)+IF(B13=3,2,0)+IF(B13=4,3,0) -> 20101062 | R13: =IF(H13=8,",1","") -> ,1 | S13: =IF(AND(H13=2,I13=1,J13="hp",L13=1,M13=2),",-1","") | T13: =IF(AND(H13=2,I13=1,J13="hp",L13=1,M13=1),",(最大气血-hp)/最大气血*100","") | U13: =IF(AND(H13=2,I13=1,J13="hp,(hp/气血值)<=0.2",L13=1,M13=3),"气血值*1006","")
A14: 2 | B14: 2 | C14: =D14&E14&A14 -> 天涯月明章折桂枝2 | D14: 天涯月明章 | E14: 折桂枝 | F14: 增攻 | G14: =VLOOKUP(E14,Sheet3!$C:$AP,40,0)*100+IF(A14=1,0,0)+IF(A14=2,1,0)+IF(A14=3,2,0)+IF(A14=4,3,0) -> 201010701 | H14: 1 | I14: 0 | J14: 0 | L14: 1 | M14: 1 | N14: =Q14&R14&S14&T14&U14&V14 -> 20101071,1 | O14: 0 | P14: -1 | Q14: =VLOOKUP(E14,Sheet3!$C:$AP,40,0)*10+IF(B14=1,0,0)+IF(B14=2,1,0)+IF(B14=3,2,0)+IF(B14=4,3,0) -> 20101071 | R14: =IF(H14=1,",1","") -> ,1 | S14: =IF(AND(H14=2,I14=1,J14="hp",L14=1,M14=2),",-1","") | T14: =IF(AND(H14=2,I14=1,J14="hp",L14=1,M14=1),",(最大气血-hp)/最大气血*100","") | U14: =IF(AND(H14=2,I14=1,J14="hp,(hp/气血值)<=0.2",L14=1,M14=3),"气血值*1006","")
A15: 3 | B15: 4 | C15: =D15&E15&A15 -> 天涯月明章折桂枝3 | D15: 天涯月明章 | E15: 折桂枝 | F15: 减防 | G15: =VLOOKUP(E15,Sheet3!$C:$AP,40,0)*100+IF(A15=1,0,0)+IF(A15=2,1,0)+IF(A15=3,2,0)+IF(A15=4,3,0) -> 201010702 | H15: 1 | I15: 0 | J15: 0 | L15: 1 | M15: 1 | N15: =Q15&R15&S15&T15&U15&V15 -> 20101073,1 | O15: 0 | P15: -1 | Q15: =VLOOKUP(E15,Sheet3!$C:$AP,40,0)*10+IF(B15=1,0,0)+IF(B15=2,1,0)+IF(B15=3,2,0)+IF(B15=4,3,0) -> 20101073 | R15: =IF(H15=1,",1","") -> ,1 | T15: =IF(AND(H15=2,I15=1,J15="hp",L15=1,M15=1),",(最大气血-hp)/最大气血*100","") | U15: =IF(AND(H15=2,I15=1,J15="hp,(hp/气血值)<=0.2",L15=1,M15=3),"气血值*1006","")
A16: 4 | B16: 5 | C16: =D16&E16&A16 -> 天涯月明章折桂枝4 | D16: 天涯月明章 | E16: 折桂枝 | F16: 减CD | G16: =VLOOKUP(E16,Sheet3!$C:$AP,40,0)*100+IF(A16=1,0,0)+IF(A16=2,1,0)+IF(A16=3,2,0)+IF(A16=4,3,0) -> 201010703 | H16: 1 | I16: 0 | J16: 0 | L16: 1 | M16: 1 | N16: =Q16&R16&S16&T16&U16&V16 -> 20101074,1 | O16: 0 | P16: -1 | Q16: 20101074 | R16: =IF(H16=1,",1","") -> ,1 | S16: =IF(AND(H16=2,I16=1,J16="hp",L16=1,M16=2),",-1","") | T16: =IF(AND(H16=2,I16=1,J16="hp",L16=1,M16=1),",(最大气血-hp)/最大气血*100","") | U16: =IF(AND(H16=2,I16=1,J16="hp,(hp/气血值)<=0.2",L16=1,M16=3),"气血值*1006","") | V16: =IF(AND(H16=1,I16=0,J16=0,L16=1,M16=3),"-(hp*0.1)","")
A17: 1 | B17: 2 | C17: =D17&E17&A17 -> 天涯月明章天涯共此1 | D17: 天涯月明章 | E17: 天涯共此 | F17: 增攻 | G17: =VLOOKUP(E17,Sheet3!$C:$AP,40,0)*100+IF(A17=1,0,0)+IF(A17=2,1,0)+IF(A17=3,2,0)+IF(A17=4,3,0) -> 201010800 | H17: 1 | I17: 0 | J17: 0 | L17: 1 | M17: 1 | N17: =Q17&R17&S17&T17&U17&V17 -> 20101081,1 | O17: 0 | P17: -1 | Q17: =VLOOKUP(E17,Sheet3!$C:$AP,40,0)*10+IF(B17=1,0,0)+IF(B17=2,1,0)+IF(B17=3,2,0)+IF(B17=4,3,0) -> 20101081 | R17: =IF(H17=1,",1","") -> ,1 | S17: =IF(AND(H17=2,I17=1,J17="hp",L17=1,M17=2),",-1","") | T17: =IF(AND(H17=2,I17=1,J17="hp",L17=1,M17=1),",(最大气血-hp)/最大气血*100","") | U17: =IF(AND(H17=2,I17=1,J17="hp,(hp/气血值)<=0.2",L17=1,M17=3),"气血值*1006","") | V17: =IF(AND(H17=1,I17=0,J17=0,L17=1,M17=3),"-(hp*0.1)","")
A18: 3 | B18: 4 | C18: =D18&E18&A18 -> 天涯月明章天涯共此3 | D18: 天涯月明章 | E18: 天涯共此 | F18: 焚沧断海 | G18: =VLOOKUP(E18,Sheet3!$C:$AP,40,0)*100+IF(A18=1,0,0)+IF(A18=2,1,0)+IF(A18=3,2,0)+IF(A18=4,3,0) -> 201010802 | H18: 8 | I18: 1 | J18: 1020401 | L18: 1 | M18: 1 | N18: =Q18&R18&S18&T18&U18&V18 -> 20101083,1 | O18: 0 | P18: -1 | Q18: =VLOOKUP(E18,Sheet3!$C:$AP,40,0)*10+IF(B18=1,0,0)+IF(B18=2,1,0)+IF(B18=3,2,0)+IF(B18=4,3,0) -> 20101083 | R18: =IF(H18=8,",1","") -> ,1 | S18: =IF(AND(H18=2,I18=1,J18="hp",L18=1,M18=2),",-1","") | T18: =IF(AND(H18=2,I18=1,J18="hp",L18=1,M18=1),",(最大气血-hp)/最大气血*100","") | U18: =IF(AND(H18=2,I18=1,J18="hp,(hp/气血值)<=0.2",L18=1,M18=3),"气血值*1006","") | V18: =IF(AND(H18=1,I18=0,J18=0,L18=1,M18=3),"-(hp*0.1)","")
A19: 4 | B19: 5 | C19: =D19&E19&A19 -> 天涯月明章天涯共此4 | D19: 天涯月明章 | E19: 天涯共此 | F19: 临碣寒 | G19: =VLOOKUP(E19,Sheet3!$C:$AP,40,0)*100+IF(A19=1,0,0)+IF(A19=2,1,0)+IF(A19=3,2,0)+IF(A19=4,3,0) -> 201010803 | H19: 8 | I19: 1 | J19: 1020403 | L19: 1 | M19: 1 | N19: =Q19&R19&S19&T19&U19&V19 -> 20101084,1 | O19: 0 | P19: -1 | Q19: =VLOOKUP(E19,Sheet3!$C:$AP,40,0)*10+IF(B19=1,0,0)+IF(B19=2,1,0)+IF(B19=3,2,0)+IF(B19=4,3,0)+IF(B19=5,4,0)+IF(B19=6,5,0) -> 20101084 | R19: =IF(H19=8,",1","") -> ,1 | S19: =IF(AND(H19=2,I19=1,J19="hp",L19=1,M19=2),",-1","") | T19: =IF(AND(H19=2,I19=1,J19="hp",L19=1,M19=1),",(最大气血-hp)/最大气血*100","") | U19: =IF(AND(H19=2,I19=1,J19="hp,(hp/气血值)<=0.2",L19=1,M19=3),"气血值*1006","") | V19: =IF(AND(H19=1,I19=0,J19=0,L19=1,M19=3),"-(hp*0.1)","")
A20: 5 | B20: 6 | C20: =D20&E20&A20 -> 天涯月明章天涯共此5 | D20: 天涯月明章 | E20: 天涯共此 | F20: 骇浪惊涛 | G20: =VLOOKUP(E20,Sheet3!$C:$AP,40,0)*100+IF(A20=1,0,0)+IF(A20=2,1,0)+IF(A20=3,2,0)+IF(A20=4,3,0)+IF(A20=5,4,0) -> 201010804 | H20: 8 | I20: 1 | J20: 1020405 | L20: 1 | M20: 1 | N20: =Q20&R20&S20&T20&U20&V20 -> 20101085,1 | O20: 0 | P20: -1 | Q20: =VLOOKUP(E20,Sheet3!$C:$AP,40,0)*10+IF(B20=1,0,0)+IF(B20=2,1,0)+IF(B20=3,2,0)+IF(B20=4,3,0)+IF(B20=5,4,0)+IF(B20=6,5,0) -> 20101085 | R20: =IF(H20=8,",1","") -> ,1 | S20: =IF(AND(H20=2,I20=1,J20="hp",L20=1,M20=2),",-1","") | T20: =IF(AND(H20=2,I20=1,J20="hp",L20=1,M20=1),",(最大气血-hp)/最大气血*100","") | U20: =IF(AND(H20=2,I20=1,J20="hp,(hp/气血值)<=0.2",L20=1,M20=3),"气血值*1006","") | V20: =IF(AND(H20=1,I20=0,J20=0,L20=1,M20=3),"-(hp*0.1)","")
A21: 7 | B21: 8 | C21: =D21&E21&A21 -> 天涯月明章晓月残星7 | D21: 天涯月明章 | E21: 晓月残星 | F21: 减防 | G21: 201010405 | H21: 1 | I21: 0 | J21: 0 | L21: 1 | M21: 1 | N21: 20101087,1 | O21: 0 | P21: -1 | Q21: =VLOOKUP(E21,Sheet3!$C:$AP,40,0)*10+IF(B21=1,0,0)+IF(B21=2,1,0)+IF(B21=3,2,0)+IF(B21=4,3,0) -> 20101040 | R21: =IF(H21=1,",1","") -> ,1 | S21: =IF(AND(H21=2,I21=1,J21="hp",L21=1,M21=2),",-1","") | T21: =IF(AND(H21=2,I21=1,J21="hp",L21=1,M21=1),",(最大气血-hp)/最大气血*100","") | U21: =IF(AND(H21=2,I21=1,J21="hp,(hp/气血值)<=0.2",L21=1,M21=3),"气血值*1006","")
A22: 1 | B22: 1 | C22: =D22&E22&A22 -> 天涯月明章共此时1 | D22: 天涯月明章 | E22: 共此时 | G22: =VLOOKUP(E22,Sheet3!$C:$AP,40,0)*100+IF(A22=1,0,0)+IF(A22=2,1,0)+IF(A22=3,2,0)+IF(A22=4,3,0) -> 201010900 | H22: 1 | I22: 0 | J22: 0 | L22: 1 | M22: 1 | N22: =Q22&R22&S22&T22&U22&V22 -> 20101090,1 | O22: 0 | P22: -1 | Q22: =VLOOKUP(E22,Sheet3!$C:$AP,40,0)*10+IF(B22=1,0,0)+IF(B22=2,1,0)+IF(B22=3,2,0)+IF(B22=4,3,0)+IF(B22=5,4,0)+IF(B22=6,5,0) -> 20101090 | R22: =IF(H22=1,",1","") -> ,1 | S22: =IF(AND(H22=2,I22=1,J22="hp",L22=1,M22=2),",-1","") | T22: =IF(AND(H22=2,I22=1,J22="hp",L22=1,M22=1),",(最大气血-hp)/最大气血*100","") | U22: =IF(AND(H22=2,I22=1,J22="hp,(hp/气血值)<=0.2",L22=1,M22=3),"气血值*1006","") | V22: =IF(AND(H22=1,I22=0,J22=0,L22=1,M22=3),"-(hp*0.1)","")
A23: 1 | B23: 1 | C23: =D23&E23&A23 -> 天涯月明章终慨叹1 | D23: 天涯月明章 | E23: 终慨叹 | F23: 减CD | G23: =VLOOKUP(E23,Sheet3!$C:$AP,40,0)*100+IF(A23=1,0,0)+IF(A23=2,1,0)+IF(A23=3,2,0)+IF(A23=4,3,0) -> 201011000 | H23: 1 | I23: 0 | J23: 0 | L23: 1 | M23: 1 | N23: =Q23&R23&S23&T23&U23&V23 -> 20101100,1 | O23: 0 | P23: -1 | Q23: =VLOOKUP(E23,Sheet3!$C:$AP,40,0)*10+IF(B23=1,0,0)+IF(B23=2,1,0)+IF(B23=3,2,0)+IF(B23=4,3,0)+IF(B23=5,4,0)+IF(B23=6,5,0) -> 20101100 | R23: =IF(H23=1,",1","") -> ,1 | S23: =IF(AND(H23=2,I23=1,J23="hp",L23=1,M23=2),",-1","") | T23: =IF(AND(H23=2,I23=1,J23="hp",L23=1,M23=1),",(最大气血-hp)/最大气血*100","") | U23: =IF(AND(H23=2,I23=1,J23="hp,(hp/气血值)<=0.2",L23=1,M23=3),"气血值*1006","") | V23: =IF(AND(H23=1,I23=0,J23=0,L23=1,M23=3),"-(hp*0.1)","")
A24: 2 | B24: 2 | C24: =D24&E24&A24 -> 天涯月明章无名气2 | D24: 天涯月明章 | E24: 无名气 | F24: 增攻 | G24: =VLOOKUP(E24,Sheet3!$C:$AP,40,0)*100+IF(A24=1,0,0)+IF(A24=2,1,0)+IF(A24=3,2,0)+IF(A24=4,3,0) -> 201011101 | H24: 1 | I24: 0 | J24: 0 | L24: 1 | M24: 1 | N24: =Q24&R24&S24&T24&U24&V24 -> 20101111,1 | O24: 0 | P24: -1 | Q24: =VLOOKUP(E24,Sheet3!$C:$AP,40,0)*10+IF(B24=1,0,0)+IF(B24=2,1,0)+IF(B24=3,2,0)+IF(B24=4,3,0)+IF(B24=5,4,0)+IF(B24=6,5,0) -> 20101111 | R24: =IF(H24=1,",1","") -> ,1 | S24: =IF(AND(H24=2,I24=1,J24="hp",L24=1,M24=2),",-1","") | T24: =IF(AND(H24=2,I24=1,J24="hp",L24=1,M24=1),",(最大气血-hp)/最大气血*100","") | U24: =IF(AND(H24=2,I24=1,J24="hp,(hp/气血值)<=0.2",L24=1,M24=3),"气血值*1006","") | V24: =IF(AND(H24=1,I24=0,J24=0,L24=1,M24=3),"-(hp*0.1)","")
A25: 4 | B25: 4 | C25: =D25&E25&A25 -> 天涯月明章无名气4 | D25: 天涯月明章 | E25: 无名气 | F25: 减防 | G25: =VLOOKUP(E25,Sheet3!$C:$AP,40,0)*100+IF(A25=1,0,0)+IF(A25=2,1,0)+IF(A25=3,2,0)+IF(A25=4,3,0) -> 201011103 | H25: 1 | I25: 0 | J25: 0 | L25: 1 | M25: 1 | N25: =Q25&R25&S25&T25&U25&V25 -> 20101113,1 | O25: 0 | P25: -1 | Q25: =VLOOKUP(E25,Sheet3!$C:$AP,40,0)*10+IF(B25=1,0,0)+IF(B25=2,1,0)+IF(B25=3,2,0)+IF(B25=4,3,0)+IF(B25=5,4,0)+IF(B25=6,5,0) -> 20101113 | R25: =IF(H25=1,",1","") -> ,1 | S25: =IF(AND(H25=2,I25=1,J25="hp",L25=1,M25=2),",-1","") | T25: =IF(AND(H25=2,I25=1,J25="hp",L25=1,M25=1),",(最大气血-hp)/最大气血*100","") | U25: =IF(AND(H25=2,I25=1,J25="hp,(hp/气血值)<=0.2",L25=1,M25=3),"气血值*1006","") | V25: =IF(AND(H25=1,I25=0,J25=0,L25=1,M25=3),"-(hp*0.1)","")
A26: 1 | B26: 1 | C26: =D26&E26&A26 -> 嗤魔祭血真经嗤魔万化1 | D26: 嗤魔祭血真经 | E26: 嗤魔万化 | F26: 气血消耗降低 | G26: =VLOOKUP(E26,Sheet3!$C:$AP,40,0)*100+IF(A26=1,0,0)+IF(A26=2,1,0)+IF(A26=3,2,0)+IF(A26=4,3,0) -> 201020100 | H26: 1 | I26: 0 | J26: 0 | L26: 1 | M26: 1 | N26: =Q26&R26&S26&T26&U26&V26 -> 20102010,1 | O26: 0 | P26: -1 | Q26: =VLOOKUP(E26,Sheet3!$C:$AP,40,0)*10+IF(B26=1,0,0)+IF(B26=2,1,0)+IF(B26=3,2,0)+IF(B26=4,3,0)+IF(B26=5,4,0)+IF(B26=6,5,0) -> 20102010 | R26: =IF(H26=1,",1","") -> ,1 | S26: =IF(AND(H26=2,I26=1,J26="hp",L26=1,M26=2),",-1","") | T26: =IF(AND(H26=2,I26=1,J26="hp",L26=1,M26=1),",(最大气血-hp)/最大气血*100","") | U26: =IF(AND(H26=2,I26=1,J26="hp,(hp/气血值)<=0.2",L26=1,M26=3),"气血值*1006","") | V26: =IF(AND(H26=1,I26=0,J26=0,L26=1,M26=3),"-(hp*0.1)","")
A27: 2 | B27: 2 | C27: =D27&E27&A27 -> 嗤魔祭血真经嗤魔万化2 | D27: 嗤魔祭血真经 | E27: 嗤魔万化 | F27: 减CD | G27: =VLOOKUP(E27,Sheet3!$C:$AP,40,0)*100+IF(A27=1,0,0)+IF(A27=2,1,0)+IF(A27=3,2,0)+IF(A27=4,3,0) -> 201020101 | H27: 1 | I27: 0 | J27: 0 | L27: 1 | M27: 1 | N27: =Q27&R27&S27&T27&U27&V27 -> 20102011,1 | O27: 0 | P27: -1 | Q27: =VLOOKUP(E27,Sheet3!$C:$AP,40,0)*10+IF(B27=1,0,0)+IF(B27=2,1,0)+IF(B27=3,2,0)+IF(B27=4,3,0)+IF(B27=5,4,0)+IF(B27=6,5,0) -> 20102011 | R27: =IF(H27=1,",1","") -> ,1 | S27: =IF(AND(H27=2,I27=1,J27="hp",L27=1,M27=2),",-1","") | T27: =IF(AND(H27=2,I27=1,J27="hp",L27=1,M27=1),",(最大气血-hp)/最大气血*100","") | U27: =IF(AND(H27=2,I27=1,J27="hp,(hp/气血值)<=0.2",L27=1,M27=3),"气血值*1006","") | V27: =IF(AND(H27=1,I27=0,J27=0,L27=1,M27=3),"-(hp*0.1)","")
A28: 1 | B28: 1 | C28: =D28&E28&A28 -> 嗤魔祭血真经鬼哭阴嚎1 | D28: 嗤魔祭血真经 | E28: 鬼哭阴嚎 | F28: 修改内劲 | G28: =VLOOKUP(E28,Sheet3!$C:$AP,40,0)*100+IF(A28=1,0,0)+IF(A28=2,1,0)+IF(A28=3,2,0)+IF(A28=4,3,0) -> 201020200 | H28: 9 | I28: 1 | J28: 9 | L28: 1 | M28: 1 | N28: =Q28&R28&S28&T28&U28&V28 -> 20102020,1 | O28: 0 | P28: -1 | Q28: =VLOOKUP(E28,Sheet3!$C:$AP,40,0)*10+IF(B28=1,0,0)+IF(B28=2,1,0)+IF(B28=3,2,0)+IF(B28=4,3,0)+IF(B28=5,4,0)+IF(B28=6,5,0) -> 20102020 | R28: =IF(H28=9,",1","") -> ,1 | S28: =IF(AND(H28=2,I28=1,J28="hp",L28=1,M28=2),",-1","") | T28: =IF(AND(H28=2,I28=1,J28="hp",L28=1,M28=1),",(最大气血-hp)/最大气血*100","") | U28: =IF(AND(H28=2,I28=1,J28="hp,(hp/气血值)<=0.2",L28=1,M28=3),"气血值*1006","") | V28: =IF(AND(H28=1,I28=0,J28=0,L28=1,M28=3),"-(hp*0.1)","")
A29: 1 | B29: 1 | C29: =D29&E29&A29 -> 嗤魔祭血真经附疽黄泉1 | D29: 嗤魔祭血真经 | E29: 附疽黄泉 | F29: 移出 | G29: =VLOOKUP(E29,Sheet3!$C:$AP,40,0)*100+IF(A29=1,0,0)+IF(A29=2,1,0)+IF(A29=3,2,0)+IF(A29=4,3,0) -> 201020300 | H29: 13 | I29: 1 | J29: 1 | L29: 1 | M29: 2 | N29: =Q29&R29&S29&T29&U29&V29 -> 20102030,-1 | O29: 0 | P29: -1 | Q29: =VLOOKUP(E29,Sheet3!$C:$AP,40,0)*10+IF(B29=1,0,0)+IF(B29=2,1,0)+IF(B29=3,2,0)+IF(B29=4,3,0)+IF(B29=5,4,0)+IF(B29=6,5,0) -> 20102030 | R29: =IF(H29=13,",-1","") -> ,-1 | S29: =IF(AND(H29=2,I29=1,J29="hp",L29=1,M29=2),",-1","") | T29: =IF(AND(H29=2,I29=1,J29="hp",L29=1,M29=1),",(最大气血-hp)/最大气血*100","") | U29: =IF(AND(H29=2,I29=1,J29="hp,(hp/气血值)<=0.2",L29=1,M29=3),"气血值*1006","") | V29: =IF(AND(H29=1,I29=0,J29=0,L29=1,M29=3),"-(hp*0.1)","")
A30: 2 | B30: 1 | C30: =D30&E30&A30 -> 嗤魔祭血真经附疽黄泉2 | D30: 嗤魔祭血真经 | E30: 附疽黄泉 | F30: 添加 | G30: =VLOOKUP(E30,Sheet3!$C:$AP,40,0)*100+IF(A30=1,0,0)+IF(A30=2,1,0)+IF(A30=3,2,0)+IF(A30=4,3,0) -> 201020301 | H30: 6 | I30: 1 | J30: 0,1,1 | L30: 1 | M30: 1 | N30: =Q30&R30&S30&T30&U30&V30 -> 20102030,debuff数量/1 | O30: 0 | P30: -1 | Q30: =VLOOKUP(E30,Sheet3!$C:$AP,40,0)*10+IF(B30=1,0,0)+IF(B30=2,1,0)+IF(B30=3,2,0)+IF(B30=4,3,0)+IF(B30=5,4,0)+IF(B30=6,5,0) -> 20102030 | R30: =IF(H30=6,",debuff数量/1","") -> ,debuff数量/1 | S30: =IF(AND(H30=2,I30=1,J30="hp",L30=1,M30=2),",-1","") | T30: =IF(AND(H30=2,I30=1,J30="hp",L30=1,M30=1),",(最大气血-hp)/最大气血*100","") | U30: =IF(AND(H30=2,I30=1,J30="hp,(hp/气血值)<=0.2",L30=1,M30=3),"气血值*1006","") | V30: =IF(AND(H30=1,I30=0,J30=0,L30=1,M30=3),"-(hp*0.1)","")
A31: 1 | B31: 1 | C31: =D31&E31&A31 -> 嗤魔祭血真经幽魂出窍1 | D31: 嗤魔祭血真经 | E31: 幽魂出窍 | F31: 气血消耗降低 | G31: =VLOOKUP(E31,Sheet3!$C:$AP,40,0)*100+IF(A31=1,0,0)+IF(A31=2,1,0)+IF(A31=3,2,0)+IF(A31=4,3,0) -> 201020400 | H31: 1 | I31: 0 | J31: 0 | L31: 1 | M31: 1 | N31: =Q31&R31&S31&T31&U31&V31 -> 20102040,1 | O31: 0 | P31: -1 | Q31: =VLOOKUP(E31,Sheet3!$C:$AP,40,0)*10+IF(B31=1,0,0)+IF(B31=2,1,0)+IF(B31=3,2,0)+IF(B31=4,3,0)+IF(B31=5,4,0)+IF(B31=6,5,0) -> 20102040 | R31: =IF(H31=1,",1","") -> ,1 | S31: =IF(AND(H31=2,I31=1,J31="hp",L31=1,M31=2),",-1","") | T31: =IF(AND(H31=2,I31=1,J31="hp",L31=1,M31=1),",(最大气血-hp)/最大气血*100","") | U31: =IF(AND(H31=2,I31=1,J31="hp,(hp/气血值)<=0.2",L31=1,M31=3),"气血值*1006","") | V31: =IF(AND(H31=1,I31=0,J31=0,L31=1,M31=3),"-(hp*0.1)","")
A32: 2 | B32: 2 | C32: =D32&E32&A32 -> 嗤魔祭血真经幽魂出窍2 | D32: 嗤魔祭血真经 | E32: 幽魂出窍 | F32: 减CD | G32: =VLOOKUP(E32,Sheet3!$C:$AP,40,0)*100+IF(A32=1,0,0)+IF(A32=2,1,0)+IF(A32=3,2,0)+IF(A32=4,3,0) -> 201020401 | H32: 1 | I32: 0 | J32: 0 | L32: 1 | M32: 1 | N32: =Q32&R32&S32&T32&U32&V32 -> 20102041,1 | O32: 0 | P32: -1 | Q32: =VLOOKUP(E32,Sheet3!$C:$AP,40,0)*10+IF(B32=1,0,0)+IF(B32=2,1,0)+IF(B32=3,2,0)+IF(B32=4,3,0)+IF(B32=5,4,0)+IF(B32=6,5,0) -> 20102041 | R32: =IF(H32=1,",1","") -> ,1 | S32: =IF(AND(H32=2,I32=1,J32="hp",L32=1,M32=2),",-1","") | T32: =IF(AND(H32=2,I32=1,J32="hp",L32=1,M32=1),",(最大气血-hp)/最大气血*100","") | U32: =IF(AND(H32=2,I32=1,J32="hp,(hp/气血值)<=0.2",L32=1,M32=3),"气血值*1006","") | V32: =IF(AND(H32=1,I32=0,J32=0,L32=1,M32=3),"-(hp*0.1)","")
A33: 1 | B33: 1 | C33: =D33&E33&A33 -> 嗤魔祭血真经残恶两生咒1 | D33: 嗤魔祭血真经 | E33: 残恶两生咒 | F33: 修改暴击几率 | G33: =VLOOKUP(E33,Sheet3!$C:$AP,40,0)*100+IF(A33=1,0,0)+IF(A33=2,1,0)+IF(A33=3,2,0)+IF(A33=4,3,0) -> 201020500 | H33: 3 | I33: 1 | J33: 0,伤害>1 | L33: 1 | M33: 1 | N33: =Q33&R33&S33&T33&U33&V33 -> 20102050,1 | O33: 0 | P33: -1 | Q33: =VLOOKUP(E33,Sheet3!$C:$AP,40,0)*10+IF(B33=1,0,0)+IF(B33=2,1,0)+IF(B33=3,2,0)+IF(B33=4,3,0) -> 20102050 | R33: =IF(H33=3,",1","") -> ,1 | S33: =IF(AND(H33=2,I33=1,J33="hp",L33=1,M33=2),",-1","") | T33: =IF(AND(H33=2,I33=1,J33="hp",L33=1,M33=1),",(最大气血-hp)/最大气血*100","") | U33: =IF(AND(H33=2,I33=1,J33="hp,(hp/气血值)<=0.2",L33=1,M33=3),"气血值*1006","") | V33: =IF(AND(H33=1,I33=0,J33=0,L33=1,M33=3),"-(hp*0.1)","")
A34: 1 | B34: 1 | C34: =D34&E34&A34 -> 嗤魔祭血真经恶鬼争食1 | D34: 嗤魔祭血真经 | E34: 恶鬼争食 | G34: =VLOOKUP(E34,Sheet3!$C:$AP,40,0)*100+IF(A34=1,0,0)+IF(A34=2,1,0)+IF(A34=3,2,0)+IF(A34=4,3,0) -> 201020600 | H34: 3 | I34: 1 | J34: 1,伤害>1,1 | L34: 1 | M34: 21 | N34: -30,0,1 | O34: 0 | P34: -1 | S34: =IF(AND(H34=2,I34=1,J34="hp",L34=1,M34=2),",-1","") | T34: =IF(AND(H34=2,I34=1,J34="hp",L34=1,M34=1),",(最大气血-hp)/最大气血*100","") | U34: =IF(AND(H34=2,I34=1,J34="hp,(hp/气血值)<=0.2",L34=1,M34=3),"气血值*1006","") | V34: =IF(AND(H34=1,I34=0,J34=0,L34=1,M34=3),"-(hp*0.1)","")
A35: 1 | B35: 1 | C35: =D35&E35&A35 -> 嗤魔祭血真经瘟啼无间1 | D35: 嗤魔祭血真经 | E35: 瘟啼无间 | F35: 气血消耗降低 | G35: =VLOOKUP(E35,Sheet3!$C:$AP,40,0)*100+IF(A35=1,0,0)+IF(A35=2,1,0)+IF(A35=3,2,0)+IF(A35=4,3,0) -> 201020700 | H35: 1 | I35: 0 | J35: 0 | L35: 1 | M35: 1 | N35: =Q35&R35&S35&T35&U35&V35 -> 20102070,1 | O35: 0 | P35: -1 | Q35: =VLOOKUP(E35,Sheet3!$C:$AP,40,0)*10+IF(B35=1,0,0)+IF(B35=2,1,0)+IF(B35=3,2,0)+IF(B35=4,3,0)+IF(B35=5,4,0)+IF(B35=6,5,0) -> 20102070 | R35: =IF(H35=1,",1","") -> ,1 | S35: =IF(AND(H35=2,I35=1,J35="hp",L35=1,M35=2),",-1","") | T35: =IF(AND(H35=2,I35=1,J35="hp",L35=1,M35=1),",(最大气血-hp)/最大气血*100","") | U35: =IF(AND(H35=2,I35=1,J35="hp,(hp/气血值)<=0.2",L35=1,M35=3),"气血值*1006","") | V35: =IF(AND(H35=1,I35=0,J35=0,L35=1,M35=3),"-(hp*0.1)","")
A36: 2 | B36: 2 | C36: =D36&E36&A36 -> 嗤魔祭血真经瘟啼无间2 | D36: 嗤魔祭血真经 | E36: 瘟啼无间 | F36: 减CD | G36: =VLOOKUP(E36,Sheet3!$C:$AP,40,0)*100+IF(A36=1,0,0)+IF(A36=2,1,0)+IF(A36=3,2,0)+IF(A36=4,3,0) -> 201020701 | H36: 1 | I36: 0 | J36: 0 | L36: 1 | M36: 1 | N36: =Q36&R36&S36&T36&U36&V36 -> 20102071,1 | O36: 0 | P36: -1 | Q36: =VLOOKUP(E36,Sheet3!$C:$AP,40,0)*10+IF(B36=1,0,0)+IF(B36=2,1,0)+IF(B36=3,2,0)+IF(B36=4,3,0)+IF(B36=5,4,0)+IF(B36=6,5,0) -> 20102071 | R36: =IF(H36=1,",1","") -> ,1 | S36: =IF(AND(H36=2,I36=1,J36="hp",L36=1,M36=2),",-1","") | T36: =IF(AND(H36=2,I36=1,J36="hp",L36=1,M36=1),",(最大气血-hp)/最大气血*100","") | U36: =IF(AND(H36=2,I36=1,J36="hp,(hp/气血值)<=0.2",L36=1,M36=3),"气血值*1006","") | V36: =IF(AND(H36=1,I36=0,J36=0,L36=1,M36=3),"-(hp*0.1)","")
A37: 1 | B37: 1 | C37: =D37&E37&A37 -> 嗤魔祭血真经嗤魔笑1 | D37: 嗤魔祭血真经 | E37: 嗤魔笑 | G37: =VLOOKUP(E37,Sheet3!$C:$AP,40,0)*100+IF(A37=1,0,0)+IF(A37=2,1,0)+IF(A37=3,2,0)+IF(A37=4,3,0) -> 201020800 | H37: 1 | I37: 0 | J37: 0 | L37: 1 | M37: 1 | N37: =Q37&R37&S37&T37&U37&V37 | O37: 0 | P37: -1 | S37: =IF(AND(H37=2,I37=1,J37="hp",L37=1,M37=2),",-1","") | T37: =IF(AND(H37=2,I37=1,J37="hp",L37=1,M37=1),",(最大气血-hp)/最大气血*100","") | U37: =IF(AND(H37=2,I37=1,J37="hp,(hp/气血值)<=0.2",L37=1,M37=3),"气血值*1006","") | V37: =IF(AND(H37=1,I37=0,J37=0,L37=1,M37=3),"-(hp*0.1)","")
A38: 1 | B38: 1 | C38: =D38&E38&A38 -> 嗤魔祭血真经残躯转1 | D38: 嗤魔祭血真经 | E38: 残躯转 | G38: =VLOOKUP(E38,Sheet3!$C:$AP,40,0)*100+IF(A38=1,0,0)+IF(A38=2,1,0)+IF(A38=3,2,0)+IF(A38=4,3,0) -> 201020900 | H38: 1 | I38: 0 | J38: 0 | L38: 1 | M38: 1 | N38: =Q38&R38&S38&T38&U38&V38 -> 20102090,1 | O38: 0 | P38: -1 | Q38: =VLOOKUP(E38,Sheet3!$C:$AP,40,0)*10+IF(B38=1,0,0)+IF(B38=2,1,0)+IF(B38=3,2,0)+IF(B38=4,3,0)+IF(B38=5,4,0)+IF(B38=6,5,0) -> 20102090 | R38: =IF(H38=1,",1","") -> ,1 | S38: =IF(AND(H38=2,I38=1,J38="hp",L38=1,M38=2),",-1","") | T38: =IF(AND(H38=2,I38=1,J38="hp",L38=1,M38=1),",(最大气血-hp)/最大气血*100","") | U38: =IF(AND(H38=2,I38=1,J38="hp,(hp/气血值)<=0.2",L38=1,M38=3),"气血值*1006","") | V38: =IF(AND(H38=1,I38=0,J38=0,L38=1,M38=3),"-(hp*0.1)","")
A39: 1 | B39: 1 | C39: =D39&E39&A39 -> 嗤魔祭血真经返世魔1 | D39: 嗤魔祭血真经 | E39: 返世魔 | F39: 减CD | G39: =VLOOKUP(E39,Sheet3!$C:$AP,40,0)*100+IF(A39=1,0,0)+IF(A39=2,1,0)+IF(A39=3,2,0)+IF(A39=4,3,0) -> 201021000 | H39: 1 | I39: 0 | J39: 0 | L39: 1 | M39: 1 | N39: =Q39&R39&S39&T39&U39&V39 -> 20102100,1 | O39: 0 | P39: -1 | Q39: =VLOOKUP(E39,Sheet3!$C:$AP,40,0)*10+IF(B39=1,0,0)+IF(B39=2,1,0)+IF(B39=3,2,0)+IF(B39=4,3,0)+IF(B39=5,4,0)+IF(B39=6,5,0) -> 20102100 | R39: =IF(H39=1,",1","") -> ,1 | S39: =IF(AND(H39=2,I39=1,J39="hp",L39=1,M39=2),",-1","") | T39: =IF(AND(H39=2,I39=1,J39="hp",L39=1,M39=1),",(最大气血-hp)/最大气血*100","") | U39: =IF(AND(H39=2,I39=1,J39="hp,(hp/气血值)<=0.2",L39=1,M39=3),"气血值*1006","") | V39: =IF(AND(H39=1,I39=0,J39=0,L39=1,M39=3),"-(hp*0.1)","")
A40: 2 | B40: 1 | C40: =D40&E40&A40 -> 嗤魔祭血真经浊饮恶酒2 | D40: 嗤魔祭血真经 | E40: 浊饮恶酒 | F40: 添加 | G40: =VLOOKUP(E40,Sheet3!$C:$AP,40,0)*100+IF(A40=1,0,0)+IF(A40=2,1,0)+IF(A40=3,2,0)+IF(A40=4,3,0) -> 201021101 | H40: 6 | I40: 1 | J40: 0,1,1 | L40: 1 | M40: 1 | N40: =Q40&R40&S40&T40&U40&V40 -> 20102110,debuff数量/1 | O40: 0 | P40: -1 | Q40: =VLOOKUP(E40,Sheet3!$C:$AP,40,0)*10+IF(B40=1,0,0)+IF(B40=2,1,0)+IF(B40=3,2,0)+IF(B40=4,3,0)+IF(B40=5,4,0)+IF(B40=6,5,0) -> 20102110 | R40: =IF(H40=6,",debuff数量/1","") -> ,debuff数量/1 | S40: =IF(AND(H40=2,I40=1,J40="hp",L40=1,M40=2),",-1","") | T40: =IF(AND(H40=2,I40=1,J40="hp",L40=1,M40=1),",(最大气血-hp)/最大气血*100","") | U40: =IF(AND(H40=2,I40=1,J40="hp,(hp/气血值)<=0.2",L40=1,M40=3),"气血值*1006","") | V40: =IF(AND(H40=1,I40=0,J40=0,L40=1,M40=3),"-(hp*0.1)","")
...

Sheet BuffData
G1: buff类型 | H1: 显示图标 | I1: 显示名字 | J1: 说明 | K1: 互斥组 | L1: 互斥优先级 | M1: 持续时间 | N1: 最大层数 | O1: 效果是否可叠加 | P1: 持续时间是否可叠加 | Q1: 是否debuff | R1: 额外参数 | S1: 是否显示详细参数
E2: 备注 | F2: id | G2: buffTypeInt | H2: icon | I2: name | J2: desc | K2: mutexGroup | L2: mutexPriority | M2: duration | N2: maxLayer | O2: isEffectOverling | P2: isDurationOverling | Q2: isDebuff | R2: exParamListStr | S2: isShowParam
A3: 世界BUFF | B3: 气血上限 | D3: 被动 | E3: 10010 | F3: 10010 | G3: 1 | H3: fightbuff/10010 | I3: Poisoned | J3: Poison hide effect. HP cap -20% 12hr | M3: -1 | N3: 1 | O3: FALSE | P3: FALSE | Q3: FALSE | R3: 最大气血,-(最大气血*0.2) | S3: TRUE | T3: fightbuff/ | U3: 10010
A4: 世界BUFF | B4: 增加外功攻击 | C4: 修改闪避 | D4: 被动 | E4: 10027 | F4: 10027 | G4: 1 | H4: fightbuff/10027 | I4: Feel good | J4: Body flow good. Fist attack up. 12hr | M4: -1 | N4: 1 | O4: FALSE | P4: FALSE | Q4: FALSE | R4: 外功攻击,外功攻击*0.1 | S4: TRUE | T4: fightbuff/ | U4: 10027
A5: 世界BUFF | B5: 提升内功攻击 | D5: 被动 | E5: 10028 | F5: 10028 | G5: 1 | H5: fightbuff/10028 | I5: Calm mind | J5: Qi feel nice. Magic attack up. 12hr | M5: -1 | N5: 1 | O5: FALSE | P5: FALSE | Q5: FALSE | R5: 内功攻击,内功攻击*0.1 | S5: TRUE | T5: fightbuff/ | U5: 10028
A6: 世界BUFF | B6: 提升气血恢复属性 | D6: 被动 | E6: 10029 | F6: 10029 | G6: 1 | H6: fightbuff/10029 | I6: Full energy | J6: Energy full. Stamina recover up. 12hr | M6: -1 | N6: 1 | O6: FALSE | P6: FALSE | Q6: FALSE | R6: 体力恢复,2 | S6: TRUE | T6: fightbuff/ | U6: 10029
A7: 世界BUFF | B7: 气血回复提高 | D7: 被动 | E7: 10030 | F7: 10030 | G7: 1 | H7: fightbuff/10030 | I7: Rare food | J7: Taste super good. Can't stop eat. | M7: -1 | N7: 1 | O7: FALSE | P7: FALSE | Q7: FALSE | R7: 气血恢复,气血恢复*0.1+3 | S7: FALSE | T7: fightbuff/ | U7: 10030
A8: 世界BUFF | B8: 提升内外功攻击 | D8: 被动 | E8: 10031 | F8: 10031 | G8: 1 | H8: fightbuff/10031 | I8: Tiger art | J8: Master teach. Power double. | M8: -1 | N8: 1 | O8: FALSE | P8: FALSE | Q8: FALSE | R8: 外功攻击,外功攻击*0.5;内功攻击,内功攻击*0.5 | S8: FALSE | T8: fightbuff/ | U8: 10031
A9: 世界BUFF | B9: 提高内息 | D9: 被动 | E9: 10032 | F9: 10032 | G9: 1 | H9: fightbuff/10032 | I9: Smooth qi | J9: Practice done. Body comfy. | M9: -1 | N9: 1 | O9: FALSE | P9: FALSE | Q9: FALSE | R9: 内息,3 | S9: FALSE | T9: fightbuff/ | U9: 10032
A10: 世界BUFF | B10: 提高武力 | D10: 被动 | E10: 10033 | F10: 10033 | G10: 1 | H10: fightbuff/10033 | I10: Stay ready | J10: Alert mind sharp. Ready fight. | M10: -1 | N10: 1 | O10: FALSE | P10: FALSE | Q10: FALSE | R10: 武力,3 | S10: FALSE | T10: fightbuff/ | U10: 10033
A11: 世界BUFF | B11: 提高身法 | D11: 被动 | E11: 10034 | F11: 10034 | G11: 1 | H11: fightbuff/10034 | I11: Swift move | J11: Focus spirit. Fly like bird. | M11: -1 | N11: 1 | O11: FALSE | P11: FALSE | Q11: FALSE | R11: 身法,3 | S11: FALSE | T11: fightbuff/ | U11: 10034
A12: 世界BUFF | B12: 提高内外功攻击 | D12: 被动 | E12: 10035 | F12: 10035 | G12: 1 | H12: fightbuff/10035 | I12: Scare first | J12: People fear you. No move. | M12: -1 | N12: 1 | O12: FALSE | P12: FALSE | Q12: FALSE | R12: 外功攻击,外功攻击*0.1;内功攻击,内功攻击*0.1 | S12: FALSE | T12: fightbuff/ | U12: 10035
A13: 世界BUFF | B13: 内外功攻击降低50％ | D13: 被动 | E13: 10036 | F13: 10036 | G13: 1 | H13: fightbuff/10036 | I13: Bad hurt | J13: Hurt bad. Bone break. Danger. | M13: -1 | N13: 1 | O13: FALSE | P13: FALSE | Q13: TRUE | R13: 外功攻击,-(外功攻击*0.5);内功攻击,-(内功攻击*0.5) | S13: FALSE | T13: fightbuff/ | U13: 10036
A14: 天赋 | B14: 反伤 | D14: 被动 | E14: 10037 | F14: 10037 | G14: 1 | H14: fightbuff/WuJi | I14: Lone wolf | J14: No teammate: Damage+20% Def+20% | M14: -1 | N14: 1 | O14: FALSE | P14: FALSE | Q14: FALSE | R14: 最终伤害增加,0.2;外功防御,外功防御*0.2;内功防御,内功防御*0.2 | S14: TRUE | T14: fightbuff/ | U14: =VLOOKUP(B14,示例!$P:$Q,2,0) -> WuJi
A15: 世界BUFF | B15: 提升气血恢复属性 | D15: 被动 | E15: 10040 | F15: 10040 | G15: 1 | H15: fightbuff/10040 | I15: Full power | J15: Rest recover stamina. 12hr | M15: -1 | N15: 1 | O15: FALSE | P15: FALSE | Q15: FALSE | R15: 体力恢复,1 | S15: TRUE | T15: fightbuff/ | U15: 10040
B16: 霸体 | C16: 极难难度远程 | F16: 10041 | G16: 4 | H16: fightbuff/GongJiTiSheng | I16: Red magic | J16: Secret magic. Skull eye. Meat ball. | M16: -1 | N16: 1 | O16: FALSE | P16: FALSE | Q16: FALSE | R16: 1 | S16: TRUE | T16: fightbuff/ | U16: GongJiTiSheng
A17: 世界BUFF | B17: 气血上限 | D17: 被动 | E17: 10042 | F17: 10042 | G17: 1 | H17: fightbuff/10010 | I17: Strange poison | J17: Poison burn inside. HP cap -10% 1month | M17: -1 | N17: 1 | O17: FALSE | P17: FALSE | Q17: FALSE | R17: 最大气血,-(最大气血*0.1) | S17: TRUE | T17: fightbuff/ | U17: 10042
A18: 世界BUFF | B18: 增加移动速度 | D18: 被动 | E18: 10043 | F18: 10043 | G18: 1 | H18: fightbuff/10029 | I18: Lucky feel | J18: Mind clear. Move fast fight. 1month | M18: -1 | N18: 1 | O18: FALSE | P18: FALSE | Q18: FALSE | R18: 移动速度,移动速度*0.05 | S18: TRUE | T18: fightbuff/ | U18: 10043
A19: 世界BUFF | B19: 增加移动速度 | D19: 被动 | E19: 10043 | F19: 10044 | G19: 1 | H19: fightbuff/10029 | I19: Slower move | J19: Move slow -10% | M19: -1 | N19: 1 | O19: FALSE | P19: FALSE | Q19: FALSE | R19: 移动速度,-(移动速度*0.1) | S19: TRUE | T19: fightbuff/ | U19: 10043
A20: 世界BUFF | B20: 增加移动速度 | D20: 被动 | E20: 10043 | F20: 10045 | G20: 1 | H20: fightbuff/10029 | I20: Less blood | J20: HP down -20% | M20: -1 | N20: 1 | O20: FALSE | P20: FALSE | Q20: FALSE | R20: 最大气血,-(最大气血*0.2) | S20: TRUE | T20: fightbuff/ | U20: 10043
A21: 世界BUFF | B21: 增加移动速度 | D21: 被动 | E21: 10043 | F21: 10046 | G21: 1 | H21: fightbuff/10029 | I21: Weak armor | J21: Defense down -20% | M21: -1 | N21: 1 | O21: FALSE | P21: FALSE | Q21: FALSE | R21: 外功防御,-(外功防御*0.2);内功防御,-(内功防御*0.2) | S21: TRUE | T21: fightbuff/ | U21: 10043
A22: 世界BUFF | B22: 增加移动速度 | D22: 被动 | E22: 10043 | F22: 10047 | G22: 1 | H22: fightbuff/10029 | I22: No item | J22: No use item | M22: -1 | N22: 1 | O22: FALSE | P22: FALSE | Q22: FALSE | S22: FALSE | T22: fightbuff/ | U22: 10043
A23: 世界BUFF | B23: 增加移动速度 | D23: 被动 | E23: 10043 | F23: 10048 | G23: 1 | H23: fightbuff/10029 | I23: No skill | J23: No basic skill | M23: -1 | N23: 1 | O23: FALSE | P23: FALSE | Q23: FALSE | S23: FALSE | T23: fightbuff/ | U23: 10043
A24: 天涯月明章 | B24: 天涯月明章 | C24: 增攻减防 | D24: 被动 | E24: 2010101 | F24: 20101010 | G24: 1 | H24: fightbuff/1001 | I24: Solitaire | J24: Damage +3% | K24: 1 | L24: 1 | M24: 10 | N24: 1 | O24: FALSE | P24: FALSE | Q24: FALSE | R24: 最终伤害增加,0.03; | S24: TRUE | T24: fightbuff/ | U24: =VLOOKUP(B24,示例!$P:$Q,2,0) -> 1001
A25: 天涯月明章 | C25: 增攻减防添加 | D25: 被动 | E25: 2010101 | F25: 20101011 | G25: 2 | I25: Solitaire | J25: Attack save | K25: 2 | L25: 1 | M25: -1 | N25: 1 | O25: FALSE | P25: FALSE | Q25: FALSE | R25: 2010101,6,20101010 | S25: TRUE | T25: fightbuff/ | U25: =VLOOKUP(B25,示例!$P:$Q,2,0) -> #N/A
A26: 天涯月明章 | B26: 降低防御（内外功） | C26: 增攻减防 | D26: 被动 | E26: 2010101 | F26: 20101012 | G26: 1 | H26: fightbuff/1002 | I26: Solitaire | J26: Fist/magic def -5% | K26: 3 | L26: 1 | M26: 10 | N26: 1 | O26: FALSE | P26: FALSE | Q26: FALSE | R26: 外功防御,-(外功防御*0.05);内功防御,-(内功防御*0.05) | S26: TRUE | T26: fightbuff/ | U26: =VLOOKUP(B26,示例!$P:$Q,2,0) -> 1002
A27: 天涯月明章 | C27: 增攻减防添加 | D27: 被动 | E27: 2010101 | F27: 20101013 | G27: 2 | I27: Solitaire | J27: Def save | K27: 4 | L27: 1 | M27: -1 | N27: 1 | O27: FALSE | P27: FALSE | Q27: FALSE | R27: 2010101,6,20101012 | S27: TRUE | T27: fightbuff/ | U27: =VLOOKUP(B27,示例!$P:$Q,2,0) -> #N/A
A28: 天涯月明章 | B28: 提升气血恢复属性 | C28: 修改气血回复属性 | D28: 被动 | E28: 2010102 | F28: 20101020 | G28: 1 | H28: fightbuff/1003 | I28: Silent | J28: HP recover up | M28: -1 | N28: 1 | O28: FALSE | P28: FALSE | Q28: FALSE | R28: 气血恢复,气血恢复*0.05+1 | S28: TRUE | T28: fightbuff/ | U28: =VLOOKUP(B28,示例!$P:$Q,2,0) -> 1003
A29: 天涯月明章 | B29: 提升暴击几率 | C29: 修改暴击几率 | D29: 被动 | E29: 2010103 | F29: 20101030 | G29: 1 | H29: fightbuff/1004 | I29: Cliff book | J29: Crit chance up | M29: -1 | N29: 1 | O29: FALSE | P29: FALSE | Q29: FALSE | R29: 暴击,(身法+5)*涯无书暴击系数 | S29: TRUE | T29: fightbuff/ | U29: =VLOOKUP(B29,示例!$P:$Q,2,0) -> 1004
A30: 天涯月明章 | B30: 增加攻击（内外功） | C30: 增攻减防 | D30: 主动 | E30: 2010104 | F30: 20101040 | G30: 1 | H30: fightbuff/GongJiTiSheng | I30: Moon star | J30: Shuo skill: dmg+2% cd-5s | K30: 1 | L30: 1 | M30: 10 | N30: 1 | O30: FALSE | P30: FALSE | Q30: FALSE | R30: 最终伤害增加,0.02 | S30: TRUE | T30: fightbuff/ | U30: =VLOOKUP(B30,示例!$P:$Q,2,0) -> GongJiTiSheng
A31: 天涯月明章 | C31: 增攻减防添加 | D31: 主动 | E31: 2010104 | F31: 20101041 | G31: 2 | I31: Moon star | J31: Attack save | K31: 2 | L31: 1 | M31: -1 | N31: 1 | O31: FALSE | P31: FALSE | Q31: FALSE | R31: 2010101,6,20101040 | S31: TRUE | T31: fightbuff/ | U31: =VLOOKUP(B31,示例!$P:$Q,2,0) -> #N/A
A32: 天涯月明章 | C32: 增攻减防 | D32: 主动 | E32: 2010104 | F32: 20101042 | G32: 1 | I32: Moon star | J32: Shuo: def-3% | K32: 3 | L32: 1 | M32: 10 | N32: 1 | O32: FALSE | P32: FALSE | Q32: FALSE | R32: 外功防御,-(外功防御*0.03);内功防御,-(内功防御*0.03) | S32: TRUE | T32: fightbuff/ | U32: =VLOOKUP(B32,示例!$P:$Q,2,0) -> #N/A
A33: 天涯月明章 | C33: 增攻减防添加 | D33: 主动 | E33: 2010104 | F33: 20101043 | G33: 2 | I33: Moon star | J33: Def save | K33: 4 | L33: 1 | M33: -1 | N33: 1 | O33: FALSE | P33: FALSE | Q33: FALSE | R33: 2010101,6,20101042 | S33: TRUE | T33: fightbuff/ | U33: =VLOOKUP(B33,示例!$P:$Q,2,0) -> #N/A
A34: 天涯月明章 | C34: 减CD | D34: 主动 | E34: 2010104 | F34: 20101044 | G34: 6 | I34: Moon star | J34: Change cd | M34: -1 | N34: 1 | O34: FALSE | P34: FALSE | Q34: FALSE | R34: 2010101,cd,-5 | S34: TRUE | T34: fightbuff/ | U34: =VLOOKUP(B34,示例!$P:$Q,2,0) -> #N/A
A35: 天涯月明章 | B35: 增加移动速度 | C35: 焚沧断海 | D35: 被动 | E35: 2010105 | F35: 20101050 | G35: 1 | H35: fightbuff/1063 | I35: Wait step | J35: Move speed+10% 5s | M35: 5 | N35: 1 | O35: FALSE | P35: FALSE | Q35: FALSE | R35: 移动速度,移动速度*0.1 | S35: TRUE | T35: fightbuff/ | U35: =VLOOKUP(B35,示例!$P:$Q,2,0) -> 1063
A36: 天涯月明章 | B36: 增加暴击伤害 | C36: 焚沧断海 | D36: 被动 | E36: 2010106 | F36: 20101060 | G36: 1 | H36: fightbuff/1005 | I36: Carry hook | J36: Canghai blade crit dmg+10% | M36: -1 | N36: 1 | O36: FALSE | P36: FALSE | Q36: FALSE | R36: 暴伤,0.4 | S36: FALSE | T36: fightbuff/ | U36: =VLOOKUP(B36,示例!$P:$Q,2,0) -> 1005
A37: 天涯月明章 | C37: 临碣寒 | D37: 被动 | E37: 2010106 | F37: 20101061 | G37: 1 | I37: Carry hook | J37: Liejie crit hurt up | M37: -1 | N37: 1 | O37: FALSE | P37: FALSE | Q37: FALSE | R37: 暴伤,0.3 | S37: FALSE | T37: fightbuff/ | U37: =VLOOKUP(B37,示例!$P:$Q,2,0) -> #N/A
A38: 天涯月明章 | C38: 骇浪惊涛 | D38: 被动 | E38: 2010106 | F38: 20101062 | G38: 1 | I38: Carry hook | J38: Langtao crit hurt up | M38: -1 | N38: 1 | O38: FALSE | P38: FALSE | Q38: FALSE | R38: 暴伤,0.3 | S38: FALSE | T38: fightbuff/ | U38: =VLOOKUP(B38,示例!$P:$Q,2,0) -> #N/A
