Workbook

Sheet NPC
A1: touchId | B1: 交互名称 | C1: 性别 | D1: 年龄 | E1: 寿命 | F1: 身份图标 | G1: 父亲Id | H1: 母亲Id | I1: 配偶touchId | J1: 师父touchId | K1: 徒弟touchId | L1: 子女touchId | M1: 同怀touchId | N1: 眷侣touchId | O1: 金兰touchId | P1: 仇敌touchId | Q1: 喜欢 | R1: 讨厌 | S1: 立场值 | T1: 特质 | U1: 善值 | V1: 恶值 | W1: 饱食 | X1: 精力 | Y1: 门派Id | Z1: 门派位阶 | AA1: 角色银两 | AB1: 初始道具列表 | AC1: 随机抽取道具 | AD1: 现居住地址 | AE1: 在视野外是否还需渲染动画 | AF1: 可参与武林大会 | AG1: 是否接入切磋功能 | AH1: 切磋胜利 | AI1: 切磋失败 | AJ1: 成为同伴后对话 | AK1: 分道扬镳时的对话 | AL1: 自带场景buffer
A2: id | B2: name | C2: sex | D2: age | E2: lifeSpan | F2: tagIcon | G2: fId | H2: mId | I2: mateId | J2: teacherId | K2: apprenticeId | L2: kidsId | M2: siblingsId | N2: spouseId | O2: partnerId | P2: enemyId | Q2: likeList | R2: hateList | S2: lichang | T2: characteristic | U2: kindness | V2: evil | W2: satisfied | X2: energy | Y2: sect | Z2: sectLv | AA2: money | AB2: itemList | AC2: randomItems | AD2: live | AE2: KeepSipneAnim | AF2: canJoinWulin | AG2: WhetherToBattle | AH2: dialog_battleSucc | AI2: dialog_battleFail | AJ2: dialog_bePartner | AK2: dialog_whenLeaveTeam | AL2: mapbuffer
A3: 1100001001 | B3: 毛毛 | C3: 1 | D3: 9 | E3: 60 | G3: 0 | H3: 0 | I3: 0 | J3: 0 | K3: 0 | L3: 0 | M3: 0 | N3: 0 | O3: 0 | P3: 0 | Q3: 1;3 | R3: 28 | S3: 75 | T3: 2034 | U3: 30 | V3: 0 | W3: 30 | X3: 60 | Y3: 0 | Z3: 0 | AA3: 0 | AB3: 908004 | AC3: 6|1_1|1_3|1_1 | AD3: 11000 | AE3: 0 | AF3: 0 | AG3: 0 | AH3: [少侠||姑娘]好身手，假以时日想必能扬名武林！ | AI3: 胜败乃兵家常事，[少侠||姑娘]可精研武艺，日后再与在下切磋。 | AJ3: 30 | AK3: 33
A4: 1100001002 | B4: 杜颜白 | C4: 1 | D4: 37 | E4: 60 | G4: 0 | H4: 0 | I4: 0 | J4: 0 | K4: 0 | L4: 0 | M4: 0 | N4: 0 | O4: 0 | P4: 0 | Q4: 21;22 | R4: 29 | S4: 80 | T4: 2003;2018;2020;2031 | U4: 80 | V4: -10 | W4: 76 | X4: 87 | Y4: 0 | Z4: 0 | AA4: 600 | AB4: 95102015;95301065;95102025 | AC4: 1|2_4|3_6|1_1#5|2_4|1_2|1_1#6|1_1|1_3|1_1 | AD4: 11000 | AE4: 0 | AF4: 0 | AG4: 1 | AH4: 28 | AI4: 29 | AJ4: 30 | AK4: 33
A5: 1100001003 | B5: 麻木的少年 | C5: 1 | D5: 15 | E5: 20 | G5: 0 | H5: 0 | I5: 0 | J5: 0 | K5: 0 | L5: 0 | M5: 0 | N5: 0 | O5: 0 | P5: 0 | Q5: 9; | R5: 28 | S5: 50 | T5: 2024 | U5: 10 | V5: 0 | W5: 38 | X5: 30 | Y5: 0 | Z5: 0 | AA5: 0 | AC5: 6|1_1|1_3|1_1 | AD5: 11000 | AE5: 0 | AF5: 0 | AG5: 0 | AH5: 28 | AI5: 29 | AJ5: 30 | AK5: 33
A6: 1100001004 | B6: 豆丁 | C6: 1 | D6: 7 | E6: 60 | G6: 0 | H6: 0 | I6: 0 | J6: 0 | K6: 0 | L6: 0 | M6: 0 | N6: 0 | O6: 0 | P6: 0 | Q6: 1; | R6: 28 | S6: 70 | T6: 2034 | U6: 20 | V6: 0 | W6: 40 | X6: 57 | Y6: 0 | Z6: 0 | AA6: 0 | AC6: 6|1_1|1_3|1_1 | AD6: 11000 | AE6: 0 | AF6: 0 | AG6: 0 | AH6: 28 | AI6: 29 | AJ6: 30 | AK6: 33
A7: 1100001005 | B7: 小若 | C7: 2 | D7: 6 | E7: 60 | G7: 0 | H7: 0 | I7: 0 | J7: 0 | K7: 0 | L7: 0 | M7: 0 | N7: 0 | O7: 0 | P7: 0 | Q7: 24;25 | R7: 28 | S7: 70 | T7: 2035 | U7: 20 | V7: 0 | W7: 39 | X7: 54 | Y7: 0 | Z7: 0 | AA7: 0 | AC7: 6|1_1|1_3|1_1 | AD7: 11000 | AE7: 0 | AF7: 0 | AG7: 0 | AH7: 28 | AI7: 29 | AJ7: 30 | AK7: 33
A8: 1100001006 | B8: 依依 | C8: 2 | D8: 6 | E8: 60 | G8: 0 | H8: 0 | I8: 0 | J8: 0 | K8: 0 | L8: 0 | M8: 0 | N8: 0 | O8: 0 | P8: 0 | Q8: 32; | R8: 28 | S8: 70 | T8: 2002 | U8: 20 | V8: 0 | W8: 39 | X8: 60 | Y8: 0 | Z8: 0 | AA8: 0 | AC8: 6|1_1|1_3|1_1 | AD8: 11000 | AE8: 0 | AF8: 0 | AG8: 0 | AH8: 28 | AI8: 29 | AJ8: 30 | AK8: 33
A9: 1100002001 | B9: 人贩看守 | C9: 1 | D9: 31 | E9: 60 | G9: 0 | H9: 0 | I9: 0 | J9: 0 | K9: 0 | L9: 0 | M9: 0 | N9: 0 | O9: 0 | P9: 0 | Q9: 18;5 | R9: 32 | S9: 32 | T9: 2028 | U9: 10 | V9: -40 | W9: 79 | X9: 50 | Y9: 0 | Z9: 0 | AA9: 79 | AB9: 902002;907010 | AC9: 1|1_3|2_4|1_1#5|1_3|1_2|1_1#6|1_1|1_3|1_1 | AD9: 11000 | AE9: 0 | AF9: 0 | AG9: 0 | AH9: 28 | AI9: 29 | AJ9: 30 | AK9: 33
A10: 1100002002 | B10: 大当家西虎 | C10: 1 | D10: 36 | E10: 60 | G10: 0 | H10: 0 | I10: 0 | J10: 0 | K10: 0 | L10: 0 | M10: 1100002003 | N10: 0 | O10: 0 | P10: 0 | Q10: 3;34 | R10: 20 | S10: 22 | T10: 1001;1004;2029 | U10: 0 | V10: -75 | W10: 83 | X10: 92 | Y10: 0 | Z10: 0 | AA10: 850 | AB10: 902006;901101;103001;101002 | AC10: 1|2_4|3_6|1_1#5|2_4|1_2|1_1#6|1_1|1_3|1_1 | AD10: 11000 | AE10: 0 | AF10: 0 | AG10: 0 | AH10: 28 | AI10: 29 | AJ10: 30 | AK10: 33
A11: 1100002003 | B11: 二当家北豺 | C11: 1 | D11: 33 | E11: 60 | G11: 0 | H11: 0 | I11: 0 | J11: 0 | K11: 0 | L11: 0 | M11: 1100002002 | N11: 0 | O11: 0 | P11: 0 | Q11: 31;28 | R11: 20 | S11: 15 | T11: 2002;2028;3001 | U11: 0 | V11: -80 | W11: 85 | X11: 87 | Y11: 0 | Z11: 0 | AA11: 720 | AB11: 907023;907008;902006;901101 | AC11: 1|2_4|3_6|1_1#5|2_4|1_2|1_1#6|1_1|1_3|1_1 | AD11: 11000 | AE11: 0 | AF11: 0 | AG11: 0 | AH11: 28 | AI11: 29 | AJ11: 30 | AK11: 33
A12: 1100002004 | B12: 瘦弱匪徒 | C12: 1 | D12: 29 | E12: 60 | G12: 0 | H12: 0 | I12: 1160001104 | J12: 0 | K12: 0 | L12: 1160001105 | M12: 0 | N12: 0 | O12: 0 | P12: 0 | Q12: 8 | R12: 5 | S12: 46 | T12: 1005;2017 | U12: 20 | V12: -10 | W12: 50 | X12: 67 | Y12: 0 | Z12: 0 | AA12: 50 | AB12: 902003 | AC12: 1|1_3|2_4|1_1#5|1_3|1_2|1_1#6|1_1|1_3|1_1 | AD12: 11000 | AE12: 0 | AF12: 0 | AG12: 0 | AH12: 28 | AI12: 29 | AJ12: 30 | AK12: 33
A13: 1100002005 | B13: 醉酒匪徒 | C13: 1 | D13: 27 | E13: 60 | G13: 0 | H13: 0 | I13: 0 | J13: 0 | K13: 0 | L13: 0 | M13: 0 | N13: 0 | O13: 0 | P13: 0 | Q13: 5 | R13: 19 | S13: 39 | T13: 2017 | U13: 4 | V13: -30 | W13: 75 | X13: 20 | Y13: 0 | Z13: 0 | AA13: 258 | AB13: 907010;907009 | AC13: 1|1_3|2_4|1_1#5|1_3|1_2|1_1#6|1_1|1_3|1_1 | AD13: 11000 | AE13: 0 | AF13: 0 | AG13: 0 | AH13: 28 | AI13: 29 | AJ13: 30 | AK13: 33
A14: 1100002006 | B14: 人贩匪徒 | C14: 1 | D14: 30 | E14: 60 | G14: 0 | H14: 0 | I14: 0 | J14: 0 | K14: 0 | L14: 0 | M14: 0 | N14: 0 | O14: 0 | P14: 0 | Q14: 18 | R14: 19 | S14: 37 | T14: 2031 | U14: 3 | V14: -30 | W14: 71 | X14: 74 | Y14: 0 | Z14: 0 | AA14: 107 | AB14: 907011;907010 | AC14: 1|1_3|2_4|1_1#5|1_3|1_2|1_1#6|1_1|1_3|1_1 | AD14: 11000 | AE14: 0 | AF14: 0 | AG14: 1 | AH14: 28 | AI14: 29 | AJ14: 30 | AK14: 33
A15: 1100002007 | B15: 人贩匪徒 | C15: 1 | D15: 29 | E15: 60 | G15: 0 | H15: 0 | I15: 0 | J15: 0 | K15: 0 | L15: 0 | M15: 0 | N15: 0 | O15: 0 | P15: 0 | Q15: 18 | R15: 19 | S15: 31 | T15: 1004 | U15: 7 | V15: -30 | W15: 78 | X15: 84 | Y15: 0 | Z15: 0 | AA15: 212 | AB15: 907011;901001 | AC15: 1|1_3|2_4|1_1#5|1_3|1_2|1_1#6|1_1|1_3|1_1 | AD15: 11000 | AE15: 0 | AF15: 0 | AG15: 1 | AH15: 28 | AI15: 29 | AJ15: 30 | AK15: 33
A16: 1100002008 | B16: 人贩匪徒 | C16: 1 | D16: 33 | E16: 60 | G16: 0 | H16: 0 | I16: 0 | J16: 0 | K16: 0 | L16: 0 | M16: 0 | N16: 0 | O16: 0 | P16: 0 | Q16: 18 | R16: 19 | S16: 38 | T16: 2022 | U16: 8 | V16: -30 | W16: 81 | X16: 72 | Y16: 0 | Z16: 0 | AA16: 231 | AB16: 907011;901002 | AC16: 1|1_3|2_4|1_1#5|1_3|1_2|1_1#6|1_1|1_3|1_1 | AD16: 11000 | AE16: 0 | AF16: 0 | AG16: 1 | AH16: 28 | AI16: 29 | AJ16: 30 | AK16: 33
A17: 1110001001 | B17: 村中少年 | C17: 1 | D17: 17 | E17: 60 | G17: 1110001005 | H17: 0 | I17: 0 | J17: 0 | K17: 0 | L17: 0 | M17: 0 | N17: 0 | O17: 1110001003 | P17: 0 | Q17: 3;34 | R17: 9;10;11 | S17: 65 | T17: 3004;2018;2005;2026 | U17: 35 | V17: 0 | W17: 87 | X17: 82 | Y17: 0 | Z17: 0 | AA17: 515 | AB17: 902009;901003;101001;200001 | AC17: 3|1_1|1_4|1_2#6|1_1|1_4|1_1#2|1_3|1_3|1_3 | AD17: 12000 | AE17: 0 | AF17: 0 | AG17: 1 | AH17: 28 | AI17: 29 | AJ17: 30 | AK17: 33
A18: 1110001002 | B18: 王阿生 | C18: 1 | D18: 17 | E18: 60 | G18: 1110001005 | H18: 0 | I18: 0 | J18: 0 | K18: 0 | L18: 0 | M18: 0 | N18: 0 | O18: 1110001003 | P18: 0 | Q18: 3;34 | R18: 9;10;11 | S18: 65 | T18: 3004;2018;2005;2026 | U18: 35 | V18: 0 | W18: 87 | X18: 82 | Y18: 0 | Z18: 0 | AA18: 515 | AB18: 902009;901003;101001;200001 | AC18: 3|1_1|1_4|1_2#6|1_1|1_4|1_1#2|1_3|1_3|1_3 | AD18: 12000 | AE18: 0 | AF18: 0 | AG18: 1 | AH18: 28 | AI18: 29 | AJ18: 30 | AK18: 33
A19: 1110001003 | B19: 小钰 | C19: 2 | D19: 16 | E19: 60 | G19: 1110001004 | H19: 0 | I19: 0 | J19: 0 | K19: 0 | L19: 0 | M19: 0 | N19: 0 | O19: 1110001002 | P19: 0 | Q19: 32;29 | R19: 7 | S19: 60 | T19: 1005;2012;2022 | U19: 40 | V19: 0 | W19: 80 | X19: 90 | Y19: 0 | Z19: 0 | AA19: 664 | AB19: 902019;904001;902012 | AC19: 3|1_1|1_4|1_2#6|1_1|1_4|1_1#2|1_3|1_3|1_3 | AD19: 12000 | AE19: 0 | AF19: 0 | AG19: 0 | AH19: 28 | AI19: 29 | AJ19: 30 | AK19: 33
A20: 1110001004 | B20: 小钰爹 | C20: 1 | D20: 42 | E20: 60 | G20: 0 | H20: 0 | I20: 0 | J20: 0 | K20: 0 | L20: 1110001003 | M20: 0 | N20: 0 | O20: 1150001001 | P20: 0 | Q20: 5 | R20: 20;21;22 | S20: 50 | T20: 3004;2035;1003;2019 | U20: 64 | V20: -44 | W20: 83 | X20: 77 | Y20: 0 | Z20: 0 | AA20: 1014 | AB20: 902007;902004;95201013;103202 | AC20: 1|2_4|3_6|1_1#5|2_4|1_2|1_1#6|1_1|1_3|1_1 | AD20: 12000 | AE20: 0 | AF20: 0 | AG20: 1 | AH20: 28 | AI20: 29 | AJ20: 30 | AK20: 33
A21: 1110001005 | B21: 王村长 | C21: 1 | D21: 45 | E21: 60 | G21: 0 | H21: 0 | I21: 0 | J21: 0 | K21: 0 | L21: 1110001002 | M21: 0 | N21: 0 | O21: 0 | P21: 0 | Q21: 22;16;17 | R21: 33 | S21: 93 | T21: 2019 | U21: 88 | V21: 0 | W21: 84 | X21: 98 | Y21: 0 | Z21: 0 | AA21: 1789 | AB21: 902013;901303;901004;102302 | AC21: 1|2_4|3_6|1_1#5|2_4|1_2|1_1#6|1_1|1_3|1_1 | AD21: 12000 | AE21: 0 | AF21: 0 | AG21: 1 | AH21: 28 | AI21: 29 | AJ21: 30 | AK21: 33
A22: 1110001006 | B22: 果果 | C22: 2 | D22: 6 | E22: 60 | G22: 1110003001 | H22: 0 | I22: 0 | J22: 0 | K22: 0 | L22: 0 | M22: 0 | N22: 0 | O22: 0 | P22: 0 | Q22: 25;31 | R22: 5 | S22: 66 | T22: 2022 | U22: 30 | V22: 0 | W22: 71 | X22: 100 | Y22: 0 | Z22: 0 | AA22: 105 | AB22: 907012;907014 | AC22: 3|1_1|1_3|1_1#6|1_1|1_3|1_1 | AD22: 12000 | AE22: 0 | AF22: 0 | AG22: 0 | AH22: 28 | AI22: 29 | AJ22: 30 | AK22: 33
A23: 1110001007 | B23: 跑跑 | C23: 1 | D23: 9 | E23: 60 | G23: 0 | H23: 0 | I23: 0 | J23: 0 | K23: 0 | L23: 0 | M23: 0 | N23: 0 | O23: 0 | P23: 0 | Q23: 1;30 | R23: 11 | S23: 58 | T23: 2012 | U23: 15 | V23: -8 | W23: 76 | X23: 71 | Y23: 0 | Z23: 0 | AA23: 124 | AB23: 907021;907028;907034 | AC23: 3|1_1|1_3|1_1#6|1_1|1_3|1_1 | AD23: 12000 | AE23: 0 | AF23: 0 | AG23: 0 | AH23: 28 | AI23: 29 | AJ23: 30 | AK23: 33
A24: 1110001008 | B24: 蹦蹦 | C24: 1 | D24: 8 | E24: 60 | G24: 0 | H24: 0 | I24: 0 | J24: 0 | K24: 0 | L24: 0 | M24: 0 | N24: 0 | O24: 0 | P24: 0 | Q24: 25;24 | R24: 6 | S24: 56 | T24: 2005 | U24: 15 | V24: -5 | W24: 90 | X24: 95 | Y24: 0 | Z24: 0 | AA24: 45 | AB24: 907035;907036 | AC24: 3|1_1|1_3|1_1#6|1_1|1_3|1_1 | AD24: 12000 | AE24: 0 | AF24: 0 | AG24: 0 | AH24: 28 | AI24: 29 | AJ24: 30 | AK24: 33
A25: 1110001009 | B25: 跳跳 | C25: 1 | D25: 7 | E25: 60 | G25: 0 | H25: 0 | I25: 0 | J25: 0 | K25: 0 | L25: 0 | M25: 0 | N25: 0 | O25: 0 | P25: 0 | Q25: 25;24 | R25: 10 | S25: 59 | T25: 2010 | U25: 15 | V25: -5 | W25: 97 | X25: 88 | Y25: 0 | Z25: 0 | AA25: 42 | AB25: 907020;907016 | AC25: 3|1_1|1_3|1_1#6|1_1|1_3|1_1 | AD25: 12000 | AE25: 0 | AF25: 0 | AG25: 0 | AH25: 28 | AI25: 29 | AJ25: 30 | AK25: 33
A26: 1110001010 | B26: 杜颜白 | C26: 1 | D26: 37 | E26: 60 | G26: 0 | H26: 0 | I26: 0 | J26: 0 | K26: 0 | L26: 0 | M26: 0 | N26: 0 | O26: 0 | P26: 0 | Q26: 21;22 | R26: 29 | S26: 80 | T26: 2003;2018;2020;2031 | U26: 80 | V26: -10 | W26: 76 | X26: 87 | Y26: 0 | Z26: 0 | AA26: 600 | AB26: 95102015;95301065;95102025 | AC26: 1|2_4|3_6|1_1#5|2_4|1_2|1_1#6|1_1|1_3|1_1 | AD26: 12000 | AE26: 0 | AF26: 0 | AG26: 1 | AH26: 28 | AI26: 29 | AJ26: 30 | AK26: 33
A27: 1110002001 | B27: 今川留 | C27: 1 | D27: 35 | E27: 60 | G27: 0 | H27: 0 | I27: 0 | J27: 0 | K27: 0 | L27: 0 | M27: 0 | N27: 0 | O27: 0 | P27: 0 | Q27: 16;13;28 | R27: 21;25 | S27: 14 | T27: 3002;2018 ;1004 | U27: 10 | V27: -57 | W27: 75 | X27: 77 | Y27: 0 | Z27: 0 | AA27: 3822 | AB27: 110202;800102 | AC27: 1|2_4|3_6|1_1#5|2_4|1_2|1_1#6|1_1|1_3|1_1 | AD27: 12000 | AE27: 0 | AF27: 0 | AG27: 1 | AH27: 28 | AI27: 29 | AJ27: 30 | AK27: 33
A28: 1110002002 | B28: 柳星雨 | C28: 2 | D28: 33 | E28: 60 | G28: 0 | H28: 0 | I28: 0 | J28: 0 | K28: 0 | L28: 0 | M28: 0 | N28: 0 | O28: 0 | P28: 0 | Q28: 29;11 | R28: 21;22 | S28: 47 | T28: 2015;2012;2001;2024 | U28: 37 | V28: -46 | W28: 89 | X28: 92 | Y28: 0 | Z28: 0 | AA28: 7910 | AB28: 95301015;600102;901401;106202 | AC28: 1|2_4|3_6|1_1#5|2_4|1_2|1_1#6|1_1|1_3|1_1 | AD28: 12000 | AE28: 0 | AF28: 1 | AG28: 1 | AH28: 28 | AI28: 29 | AJ28: 30 | AK28: 33
A29: 1110002003 | B29: 水寨供奉 | C29: 1 | D29: 35 | E29: 60 | G29: 0 | H29: 0 | I29: 0 | J29: 0 | K29: 0 | L29: 0 | M29: 0 | N29: 0 | O29: 0 | P29: 0 | Q29: 16;13;28 | R29: 21;25 | S29: 14 | T29: 3002;2018 ;1004 | U29: 10 | V29: -57 | W29: 75 | X29: 77 | Y29: 0 | Z29: 0 | AA29: 3822 | AB29: 110202;800102 | AC29: 1|2_4|3_6|1_1#5|2_4|1_2|1_1#6|1_1|1_3|1_1 | AD29: 12000 | AE29: 0 | AF29: 0 | AG29: 1 | AH29: 28 | AI29: 29 | AJ29: 30 | AK29: 33
A30: 1110002004 | B30: 山贼首领 | C30: 1 | D30: 37 | E30: 60 | G30: 0 | H30: 0 | I30: 0 | J30: 0 | K30: 0 | L30: 0 | M30: 0 | N30: 0 | O30: 0 | P30: 0 | Q30: 18;5 | R30: 32 | S30: 20 | T30: 2020 | U30: 0 | V30: -72 | W30: 79 | X30: 92 | Y30: 0 | Z30: 0 | AA30: 1268 | AB30: 300001;109002;95503002;95503011 | AC30: 1|1_4|3_6|1_1#5|1_4|1_2|1_1#6|1_1|1_3|1_1 | AD30: 12000 | AE30: 0 | AF30: 0 | AG30: 1 | AH30: 28 | AI30: 29 | AJ30: 30 | AK30: 33
A31: 1110002005 | B31: 酒铺小贩 | C31: 1 | D31: 31 | E31: 60 | G31: 0 | H31: 0 | I31: 0 | J31: 0 | K31: 0 | L31: 0 | M31: 0 | N31: 0 | O31: 0 | P31: 0 | Q31: 5;34 | R31: 6 | S31: 28 | T31: 1003 | U31: 6 | V31: -48 | W31: 77 | X31: 77 | Y31: 0 | Z31: 0 | AA31: 475 | AB31: 902001;902002;902005;104001 | AC31: 1|1_3|2_4|1_1#5|1_3|1_2|1_1#6|1_1|1_3|1_1 | AD31: 12000 | AE31: 0 | AF31: 0 | AG31: 1 | AH31: 28 | AI31: 29 | AJ31: 30 | AK31: 33
A32: 1110002006 | B32: 山贼护卫 | C32: 1 | D32: 29 | E32: 60 | G32: 0 | H32: 0 | I32: 0 | J32: 0 | K32: 0 | L32: 0 | M32: 0 | N32: 0 | O32: 0 | P32: 0 | Q32: 7;3 | R32: 26 | S32: 31 | T32: 2032 | U32: 7 | V32: -21 | W32: 87 | X32: 93 | Y32: 0 | Z32: 0 | AA32: 411 | AB32: 105001;907013;103001 | AC32: 1|1_3|2_4|1_1#5|1_3|1_2|1_1#6|1_1|1_3|1_1 | AD32: 12000 | AE32: 0 | AF32: 0 | AG32: 1 | AH32: 28 | AI32: 29 | AJ32: 30 | AK32: 33
A33: 1110002007 | B33: 肖婆婆 | C33: 2 | D33: 51 | E33: 60 | G33: 0 | H33: 0 | I33: 0 | J33: 0 | K33: 0 | L33: 0 | M33: 0 | N33: 0 | O33: 0 | P33: 0 | Q33: 31;20 | R33: 32 | S33: 24 | T33: 2024 | U33: 3 | V33: -55 | W33: 77 | X33: 74 | Y33: 0 | Z33: 0 | AA33: 725 | AB33: 200001;300001;901103 | AC33: 1|2_4|3_6|1_1#5|2_4|1_2|1_1#6|1_1|1_3|1_1 | AD33: 12000 | AE33: 0 | AF33: 0 | AG33: 1 | AH33: 28 | AI33: 29 | AJ33: 30 | AK33: 33
A34: 1110002008 | B34: 穷酸书生 | C34: 1 | D34: 32 | E34: 60 | G34: 0 | H34: 0 | I34: 1120003005 | J34: 0 | K34: 0 | L34: 0 | M34: 0 | N34: 0 | O34: 0 | P34: 0 | Q34: 9;10;11;34 | R34: 7 | S34: 27 | T34: 2014;2021;2012 | U34: 2 | V34: -47 | W34: 72 | X34: 73 | Y34: 0 | Z34: 0 | AA34: 182 | AB34: 95502011;904015;102002;901003 | AC34: 1|2_4|3_6|1_1#5|2_4|1_2|1_1#6|1_1|1_3|1_1 | AD34: 12000 | AE34: 0 | AF34: 0 | AG34: 1 | AH34: 28 | AI34: 29 | AJ34: 30 | AK34: 33
A35: 1110002009 | B35: 糖人张 | C35: 1 | D35: 56 | E35: 60 | F35: Tag/1007 | G35: 0 | H35: 0 | I35: 0 | J35: 0 | K35: 0 | L35: 0 | M35: 0 | N35: 0 | O35: 0 | P35: 0 | Q35: 24;25;34 | R35: 11 | S35: 24 | T35: 2025 | U35: 6 | V35: -53 | W35: 92 | X35: 63 | Y35: 0 | Z35: 0 | AA35: 826 | AB35: 907039;907041;95506002;95506003;95506011 | AC35: 1|2_4|3_6|1_1#5|2_4|1_2|1_1#6|1_1|1_3|1_1 | AD35: 12000 | AE35: 0 | AF35: 0 | AG35: 1 | AH35: 28 | AI35: 29 | AJ35: 30 | AK35: 33
A36: 1110002010 | B36: 酒铺小二 | C36: 1 | D36: 31 | E36: 60 | G36: 0 | H36: 0 | I36: 0 | J36: 0 | K36: 0 | L36: 0 | M36: 0 | N36: 0 | O36: 0 | P36: 0 | Q36: 5;27 | R36: 9 | S36: 25 | T36: 2028 | U36: 6 | V36: -48 | W36: 94 | X36: 80 | Y36: 0 | Z36: 0 | AA36: 652 | AC36: 1|1_3|2_4|1_1#5|1_3|1_2|1_1#6|1_1|1_3|1_1 | AD36: 12000 | AE36: 0 | AF36: 0 | AG36: 1 | AH36: 28 | AI36: 29 | AJ36: 30 | AK36: 33
A37: 1110002011 | B37: 胎记男 | C37: 1 | D37: 28 | E37: 60 | G37: 0 | H37: 0 | I37: 0 | J37: 0 | K37: 0 | L37: 0 | M37: 0 | N37: 0 | O37: 0 | P37: 0 | Q37: 18;31 | R37: 9 | S37: 26 | T37: 1006 | U37: 13 | V37: -21 | W37: 89 | X37: 74 | Y37: 0 | Z37: 0 | AA37: 790 | AB37: 902008;907016 | AC37: 1|1_3|2_4|1_1#5|1_3|1_2|1_1#6|1_1|1_3|1_1 | AD37: 12000 | AE37: 0 | AF37: 0 | AG37: 1 | AH37: 28 | AI37: 29 | AJ37: 30 | AK37: 33
A38: 1110002014 | B38: 山贼匪徒 | C38: 1 | D38: 26 | E38: 60 | G38: 0 | H38: 0 | I38: 0 | J38: 0 | K38: 0 | L38: 0 | M38: 0 | N38: 0 | O38: 0 | P38: 0 | Q38: 18;13 | R38: 10 | S38: 21 | T38: 3004 | U38: 13 | V38: -28 | W38: 85 | X38: 77 | Y38: 0 | Z38: 0 | AA38: 731 | AB38: 907037;907027;907010 | AC38: 1|1_3|2_4|1_1#5|1_3|1_2|1_1#6|1_1|1_3|1_1 | AD38: 12000 | AE38: 0 | AF38: 0 | AG38: 1 | AH38: 28 | AI38: 29 | AJ38: 30 | AK38: 33
A39: 1110002015 | B39: 山贼前哨 | C39: 1 | D39: 31 | E39: 60 | G39: 0 | H39: 0 | I39: 0 | J39: 0 | K39: 0 | L39: 0 | M39: 0 | N39: 0 | O39: 0 | P39: 0 | Q39: 18;23 | R39: 11 | S39: 18 | T39: 2024 | U39: 8 | V39: -31 | W39: 81 | X39: 95 | Y39: 0 | Z39: 0 | AA39: 209 | AB39: 907033;907040;902001;901001 | AC39: 1|1_3|2_4|1_1#5|1_3|1_2|1_1#6|1_1|1_3|1_1 | AD39: 12000 | AE39: 0 | AF39: 0 | AG39: 1 | AH39: 28 | AI39: 29 | AJ39: 30 | AK39: 33
A40: 1110002016 | B40: 山贼前哨 | C40: 1 | D40: 36 | E40: 60 | G40: 0 | H40: 0 | I40: 0 | J40: 0 | K40: 0 | L40: 0 | M40: 0 | N40: 0 | O40: 0 | P40: 0 | Q40: 18;27 | R40: 12 | S40: 29 | T40: 3001 | U40: 9 | V40: -27 | W40: 73 | X40: 94 | Y40: 0 | Z40: 0 | AA40: 342 | AB40: 902001;901004;500001 | AC40: 1|1_3|2_4|1_1#5|1_3|1_2|1_1#6|1_1|1_3|1_1 | AD40: 12000 | AE40: 0 | AF40: 0 | AG40: 1 | AH40: 28 | AI40: 29 | AJ40: 30 | AK40: 33
...

Sheet NpcDialogLips
A1: ID | B1: 名称 | C1: 显示参数 | D1: 显示条件 | E1: 显示值 | F1: 执行参数 | G1: 执行条件 | H1: 执行值 | I1: 不满足提示 | J1: 方法 | K1: 概率 | N1: CD时间 | O1: 成功参数 | P1: 成功赋值 | Q1: 失败参数 | R1: 失败赋值 | S1: 成功对话ID | T1: 失败对话ID | U1: 战斗胜利对话ID | V1: 战斗失败对话ID | W1: 限制次数 | X1: 限制恢复CD | Y1: 受限提示 | Z1: 特殊参数 | AA1: 成功提示 | AB1: 失败提示
A2: id | B2: name | C2: param | D2: term | E2: value | F2: eParam | G2: eTerm | H2: eValue | I2: lipsTips | J2: fun | K2: mathP | L2: mathN | M2: battle | N2: cdTime | O2: succParam | P2: succValue | Q2: failParam | R2: failValue | S2: succDialog | T2: failDialog | U2: succAttackDialog | V2: failAttackDialog | W2: count | X2: regainTime | Y2: RestrictTips | Z2: tsParam | AA2: succTips | AB2: failTips
A3: 30 | B3: 浏览货品 | C3: touchId | D3: // | E3: 1110003002 | J3: Shop12001 | K3: 100 | N3: 0 | W3: 1000
A4: 31 | B4: 浏览货品 | C4: touchId | D4: // | E4: 1110002005 | J4: Shop12002 | K4: 100 | N4: 0 | W4: 1000
A5: 32 | B5: 浏览货品 | C5: touchId | D5: // | E5: 1110003006 | J5: Shop12003 | K5: 100 | N5: 0 | W5: 1000
A6: 33 | B6: 浏览货品 | C6: touchId | D6: // | E6: 1110003007 | J6: Shop12004 | K6: 100 | N6: 0 | W6: 1000
A7: 34 | B7: 浏览货品 | C7: touchId | D7: // | E7: 1110002009 | J7: Shop12005 | K7: 100 | N7: 0 | W7: 1000
A8: 36 | B8: 浏览货品 | J8: Shop12002 | K8: 100 | N8: 0 | W8: 1000
A9: 37 | B9: 睡到某时 | J9: Sleep | K9: 100 | N9: 0 | W9: 1000
A10: 38 | B10: 睡到天亮 | J10: SleepDawn | K10: 100 | N10: 0 | W10: 1000
A11: 39 | B11: 武馆交易 | J11: GymsShop,CloseUI | K11: 100 | N11: 0 | W11: 1000
A12: 40 | B12: 上门踢馆 | K12: 100 | N12: 0 | S12: 112 | W12: 1 | X12: 7200 | Y12: 阁下近日已挑战过此处，且待五日后再来为好。
A13: 41 | B13: 开始挑战 | J13: GymsBattle3 | K13: 100 | N13: 0 | U13: 113 | V13: 116 | W13: 1000
A14: 42 | B14: 开始挑战 | J14: GymsBattle2 | K14: 100 | N14: 0 | U14: 114 | V14: 116 | W14: 1000
A15: 43 | B15: 开始挑战 | J15: GymsBattle1 | K15: 100 | N15: 0 | U15: 115 | V15: 116 | W15: 1000
A16: 44 | B16: 夺取武馆 | J16: GymsOwn | K16: 100 | N16: 0 | S16: 119 | W16: 1000
A17: 45 | B17: 礼貌离开 | K17: 100 | N17: 0 | O17: PlayerLove(),1000+ | P17: 30+,sliver | S17: 120 | W17: 1000
A18: 46 | B18: 接受挑战 | J18: GymsBattle4 | K18: 100 | N18: 0 | U18: 117 | V18: 118 | W18: 1000
A19: 47 | B19: 无奈离开 | J19: GymsLose,CloseUI | K19: 100 | N19: 0 | W19: 1000
A20: 48 | B20: 赶走挑战者 | J20: GymsKeep,CloseUI | K20: 100 | N20: 0 | W20: 1000
A21: 49 | B21: 武馆交易（免费） | C21: gymsOwnerId | D21: // | E21: 1 | J21: GymsShop,CloseUI | K21: 100 | N21: 0 | W21: 1000
A22: 50 | B22: 调整武馆镇守 | C22: gymsOwnerId | D22: // | E22: 1 | F22: gymsDefierId | G22: // | H22: 0 | I22: 正有挑战者来犯 | J22: GymsGuardSet | K22: 100 | N22: 0 | W22: 1000
A23: 51 | B23: 召回同伴 | J23: GymsGuardRemove,CloseUI | K23: 100 | N23: 0 | W23: 1000
A24: 60 | B24: 打探行踪 | J24: NpcSrcout | K24: 100 | N24: 0 | W24: 1000
A25: 61 | B25: 取消委托 | J25: NpcSrcoutRemove | K25: 100 | N25: 0 | W25: 1000
A26: 100 | B26: 随心畅谈 | C26: age,state | D26: >,!/ | E26: 9,2 | F26: love | G26: > | H26: -31 | I26: 需好感度≥-30 | K26: 100 | N26: 0 | S26: 1001 | W26: 1000
A27: 200 | B27: 礼尚往来 | C27: age,state | D27: >,!/ | E27: 9,2 | F27: love | G27: > | H27: -31 | I27: 需好感度≥-30 | K27: 100 | N27: 0 | S27: 2001 | W27: 1000
A28: 300 | B28: 图谋不轨 | C28: age,JiaoQing<FuMu> | D28: >,!/ | E28: 9,1 | K28: 100 | N28: 0 | S28: 3001 | W28: 1000
A29: 400 | B29: 江湖结缘 | C29: age,state,JiaoQing<FuMu> | D29: >,!/,!/ | E29: 9,2,1 | K29: 100 | N29: 0 | S29: 4001 | W29: 1000
A30: 700 | B30: 技艺武学 | C30: age,state | D30: >,!/ | E30: 13,2 | K30: 100 | N30: 0 | S30: 7001 | W30: 1000
A31: 500 | B31: 暂且离去 | J31: CloseUI | K31: 100 | N31: 0 | W31: 1000
A32: 600 | B32: 返回 | J32: ReturnTopDialog | K32: 100 | N32: 0 | W32: 1000
A33: 601 | B33: 返回 | J33: ReturnBack | K33: 100 | N33: 0 | W33: 1000
A34: 110 | B34: 简单问候 | C34: love | D34: < | E34: 20 | F34: 4 | G34: < | H34: SP | I34: 精力值不足 | J34: CutTo你二人简问互答，诉近日之见闻，相谈甚欢…… | K34: 100 | N34: 0 | O34: PlayerLove(),5- | P34: 1+,LessenSP() | S34: 1101 | W34: 1 | X34: 1440 | Y34: 今日已经问候过此人，不妨十二时辰之后再来。
A35: 111 | B35: 简单问候 | C35: love | D35: < | E35: 0 | J35: CutTo你二人简问互答，诉近日之见闻，相谈甚欢…… | K35: 100 | N35: 0 | O35: PlayerLove(),10- | P35: 3+,LessenSP() | S35: 1101 | W35: 1 | X35: 1440 | Y35: 今日已经问候过此人，不妨十二时辰之后再来。
A36: 120 | B36: 畅谈心事 | C36: love | D36: > | E36: 19 | F36: 9 | G36: < | H36: SP | I36: 精力值不足 | J36: CutTo你与其言语互诉，置腹畅谈，言语酣畅，不觉内心大慰。 | K36: 80 | N36: 0 | O36: PlayerLove(),10- | P36: 2+,LessenSP() | Q36: 10- | R36: LessenSP() | S36: 1201 | T36: 1202 | W36: 2 | X36: 1440 | Y36: 今日一番长谈后，其人甚为疲倦，不妨十二时辰之后再来。
A37: 121 | B37: 畅谈心事 | K37: 50 | N37: 0 | O37: PlayerLove(),10- | P37: 1+,LessenSP() | Q37: 10- | R37: LessenSP() | S37: 1201 | T37: 1202 | W37: 2 | X37: 1440 | Y37: 今日一番长谈后，其人甚为疲倦，不妨十二时辰之后再来。
A38: 130 | B38: 探讨武学 | C38: attribute | D38: > | E38: attribute | F38: attribute | G38: < | H38: attribute | I38: 境界需至少与对方相当 | K38: attribute | L38: attribute | N38: 0 | O38: PlayerLove(),10-,xiuWei,10+ | P38: 5+,LessenSP(),10+,xiuWei | Q38: 10- | R38: LessenSP() | S38: 1301 | T38: 1302 | W38: 1 | X38: 1440 | Y38: 今日一番长谈后，其人甚为疲倦，不妨十二时辰之后再来。
A39: 131 | B39: 探讨武学 | C39: attribute | D39: < | E39: attribute | F39: love,9 | G39: >,< | H39: 29,SP | I39: 需好感度≥30,精力值不足 | J39: CutTo你与其言语互诉，摹武假演，为其讲述此招武学之精意…… | K39: attribute | L39: attribute | N39: 0 | O39: PlayerLove(),10-,xiuWei,10+ | P39: 5+,LessenSP(),10+,xiuWei | Q39: 10- | R39: LessenSP() | S39: 1301 | T39: 1302 | W39: 1 | X39: 1440 | Y39: 今日一番长谈后，其人甚为疲倦，不妨十二时辰之后再来。
A40: 132 | B40: 探讨武学 | C40: attribute | D40: // | E40: attribute | F40: love,9 | G40: >,< | H40: 29,SP | I40: 需好感度≥30,精力值不足 | J40: CutTo你与其言语互诉，摹武假演，为其讲述此招武学之精意…… | K40: attribute | L40: attribute | N40: 0 | O40: PlayerLove(),10-,xiuWei,10+ | P40: 5+,LessenSP(),10+,xiuWei | Q40: 10- | R40: LessenSP() | S40: 1301 | T40: 1302 | W40: 1 | X40: 1440 | Y40: 今日一番长谈后，其人甚为疲倦，不妨十二时辰之后再来。
...

Sheet NpcDialog
A1: 对话ID | B1: 对话 | C1: Lips选项
A2: id | B2: dialog | C2: lipsID
A3: 1 | B3: 1 | C3: 100,200,300,400,700,4602,4502,500 | D3: 初始
A4: 98 | B4: 14 | C4: 385,170,176,177,178,179,390,391,392,394,386,387,388,389,374,500 | D4: 帮派地牢
A5: 99 | B5: 江湖秘闻，武林逸事，有心自可得之，阁下若有何事，不妨明言。 | C5: 60,61,500 | D5: 探子
A6: 101 | B6: 14 | C6: 385,170,176,177,178,179,390,391,392,394,386,387,388,389,374,500 | D6: 俘获
A7: 102 | B7: 1 | C7: 30,31,32,33,34,100,200,300,400,700,500 | D7: 剧情
A8: 103 | B8: 27 | C8: 100,400,700,500 | D8: 同伴
A9: 104 | B9: 30 | C9: 100,400,700,500 | D9: 剧情同伴
A10: 105 | B10: 33 | C10: 500 | D10: 同伴分道扬镳
A11: 106 | B11: 客官请坐，吃饭还是住店。 | C11: 36,37,38,500 | D11: 掌柜
A12: 107 | B12: 32 | C12: 169,172,173,174,175,500 | D12: 尸首
A13: 108 | B13: 17 | C13: 39,40,500 | D13: 武馆馆主
A14: 109 | B14: 17 | C14: 50,49,500 | D14: 武馆大弟子
A15: 110 | B15: 17 | C15: 500 | D15: 武馆小弟子
A16: 111 | B16: 17 | C16: 46,500 | D16: 武馆挑战者
A17: 112 | B17: 既然朋友有兴致，便让吾之小徒儿与阁下搭手试招……只怕，我这徒儿学艺不精，若是致阁下有所伤残……哼，不若早些退去。 | C17: 41,500 | D17: 武馆踢馆1
A18: 113 | B18: 阁下好武艺，今日这梁子便算结下了！若再不退去，我首席弟子下场，生死不论！劝你速离，莫要丢了性命！ | C18: 42 | D18: 武馆踢馆2
A19: 114 | B19: 当真深藏不露……我这便亲自出马，教你识得人外有人，天外有天！夺我武馆，痴心妄想！ | C19: 43 | D19: 武馆踢馆3
A20: 115 | B20: 在下技不如人……甘拜，甘拜下风……可否，且放过鄙武馆，此乃我唯一营生啊…… | C20: 44,45 | D20: 武馆踢馆胜利
A21: 116 | B21: 如此伎俩，却妄学甚踢馆斗狠？徒儿们，送客！ | C21: 500 | D21: 武馆踢馆失败
A22: 117 | B22: 在下技不如人，输得心甘情愿，是吾狂妄自大……要杀要剐，悉听尊便。 | C22: 48 | D22: 武馆对抗挑战者胜利
A23: 118 | B23: 既如此，这间武馆便归我了！ | C23: 47 | D23: 武馆对抗挑战者失败
A24: 119 | B24: 阁下夺我武馆，断人财路，如此行径……终有一日，我定当寻汝报此仇！ | C24: 500 | D24: 武馆馆主被强夺武馆
A25: 120 | B25: 阁下宅心仁厚，实……实令在下汗颜，些许银两不成敬意，还望大侠收下…… | C25: 500 | D25: 武馆馆主被击败后，礼貌离开
A26: 121 | B26: 17 | C26: 51,500 | D26: 武馆守卫
A27: 200 | B27: 21 | C27: 375,392,601,500 | D27: 勒索成功
A28: 201 | B28: 22 | C28: 392,601,500 | D28: 勒索失败
A29: 1001 | B29: 15 | C29: 110,120,601 | D29: 随心畅谈
A30: 2001 | B30: 1 | C30: 210,220,230,601 | D30: 礼尚往来
A31: 3001 | C31: 310,320,330,340,370,3700,601 | D31: 图谋不轨
A32: 3002 | C32: 310,320,330,340,370,3700,500 | D32: 对剧情Npc行凶作恶
A33: 4001 | B33: 1 | C33: 4400,4120,4121,4122,4220,4221,4320,4321,4322,4323,4100,4101,4102,4103,4104,4105,4106,4107,4108,4109,4110,412,411,4200,4201,4202,4203,4204,4205,4206,4207,4208,4209,421,422,423,4300,4301,4302,4303,4304,4305,4306,431,434,435,436,432,4700,4701,4702,4703,4704,4705,4706,4707,4708,4709,4710,4711,472,471,4800,4801,4802,4803,4804,4805,4806,4807,4808,4809,4810,482,481,4900,4901,4902,4903,4904,4905,4906,4907,4908,4909,4910,492,491,4600,4500,4501,601 | D33: 江湖结缘
A34: 1101 | B34: 数日时间竟有如此多趣闻，江湖际遇实是出乎意料…… | C34: 600
A35: 1201 | B35: 能倾听你的心底私事，想来是被阁下当成了至亲至近之人，江湖人海茫茫，能被阁下信任也算是我的善缘了。 | C35: 600
A36: 1202 | B36: 我知道阁下心事重重，但我自己也是俗务缠身。无暇与阁下闲谈，还请多多包涵。 | C36: 600
A37: 1301 | B37: 能得阁下指点，实在是让我受益匪浅。 | C37: 600
A38: 1302 | B38: 阁下虽然武功造诣在我之上，但刚刚的一番指点确实不得要领。且恕在下无礼，还请阁下不要再多言了。 | C38: 600
A39: 2101 | B39: 太好了，这正是我所喜欢的东西，多谢阁下不吝相赠。 | C39: 600
A40: 2102 | B40: 阁下欲赠我礼品，确实令我十分欣喜，但恐在下身无长物，无以回赠，因而愧不敢受。 | C40: 600
...

Sheet NpcXingWei
A1: 行为ID | B1: 行为类别 | C1: 母行为 | D1: 行为名 | E1: 行为限制 | F1: 精力消耗 | G1: 人情消耗 | H1: 好感度要求 | I1: 行为操作流程 | J1: 行为结果 | K1: 结果参数1 | L1: 结果参数2 | M1: 结果参数3（倍数） | N1: 备注 | O1: 谈话id
A2: id | B2: type | C2: typeM | D2: name | E2: acupointId | F2: jlNum | G2: rqNum | H2: loveNum | I2: selectType | J2: result | K2: c1 | L2: c2 | M2: c3 | N2: tip | O2: talkId
A3: 1 | B3: 1 | C3: 0 | D3: 闲谈 | E3: 无限制 | F3: 10 | G3: 0 | H3: 0 | I3: 选择话题库 | J3: 好感度增加 | K3: 3 | L3: 0 | M3: 0 | N3: 0 | O3: 10001
A4: 2 | B4: 2 | C4: 0 | D4: 向对方求取道具 | E4: 仅能求取对方身上携带道具 | F4: 10 | G4: 0 | H4: 40 | I4: 选择对方携带道具 | J4: 0 | K4: 0 | L4: 0 | M4: 0 | N4: 0 | O4: 20001
A5: 3 | B5: 2 | C5: 0 | D5: 向对方求取银两 | E5: 求取数不得超过对方身上银两 | F5: 10 | G5: 0 | H5: 40 | I5: 输入银两数 | J5: 0 | K5: 0 | L5: 0 | M5: 0 | N5: 0 | O5: 20001
A6: 4 | B6: 3 | C6: 0 | D6: 赠送财物 | E6: 自身携带道具 | F6: 10 | G6: 0 | H6: 0 | I6: 选择赠送礼物（含银两）及数量 | J6: 提升好感度和人情 | K6: 0 | L6: 0 | M6: 2 | N6: 只能选一种，可以选多个 | O6: 30001
A7: 5 | B7: 3 | C7: 0 | D7: 切磋武学 | E7: 无限制 | F7: 15 | G7: 0 | H7: 0 | I7: 战斗 | J7: 胜利提升好感度 | K7: 5 | L7: 0 | M7: 0 | N7: 0 | O7: 30002
A8: 6 | B8: 4 | C8: 0 | D8: 挑衅对方 | E8: 无限制 | F8: 5 | G8: 0 | H8: 0 | I8: 0 | J8: 降低好感度； 概率触发战斗； | K8: 5 | L8: 0 | M8: 0 | N8: 0 | O8: 40001
A9: 7 | B9: 4 | C9: 0 | D9: 偷窃财物 | E9: 查看过对方行囊 | F9: 10 | G9: 0 | H9: 0 | I9: 选择偷窃的道具或银两数量 | J9: 成功获得道具； 失败触发战斗； 降低好感度 | K9: 5 | L9: 0 | M9: 0 | N9: 0 | O9: 40002
A10: 8 | B10: 4 | C10: 0 | D10: 抢夺财物 | E10: 求取失败后触发 | F10: 10 | G10: 0 | H10: 0 | I10: 选择抢夺的道具或银两数量 | J10: 触发战斗，成功必定获得道具； 降低好感度 | K10: 5 | L10: 0 | M10: 0 | N10: 0 | O10: 40003
A11: 9 | B11: 4 | C11: 0 | D11: 拔刀相向 | E11: 0 | F11: 10 | G11: 0 | H11: 0 | I11: 触发战斗 | J11: 胜利； 失败； | K11: 5 | L11: 0 | M11: 0 | N11: 0 | O11: 40004
A12: 10 | B12: 5 | C12: 0 | D12: 赶尽杀绝 | E12: 战斗胜利 | F12: 10 | G12: 0 | H12: 0 | I12: 0 | J12: 杀死对方； 降低关系好感度； 提升相对善恶值； | K12: 5 | L12: 5 | M12: 0 | N12: 0 | O12: 50001
A13: 11 | B13: 5 | C13: 0 | D13: 肆意凌辱 | E13: 战斗胜利 | F13: 10 | G13: 0 | H13: 0 | I13: 0 | J13: 给对方留下DeBuff； 降低好感度； | K13: 5 | L13: 0 | M13: 0 | N13: 0 | O13: 50004
A14: 12 | B14: 5 | C14: 0 | D14: 放其一马 | F14: 10 | G14: 0 | H14: 0 | I14: 0 | J14: 降低好感度； 增加人情值； | K14: 5 | L14: 5 | M14: 0 | N14: 0 | O14: 50005
A15: 13 | B15: 5 | C15: 0 | D15: 伤害 | E15: 战斗胜利 | F15: 2 | G15: 0 | H15: 0 | I15: 0 | J15: 给对方留下DeBuff； 降低好感度； | K15: 5 | L15: 0 | M15: 0 | N15: 0 | O15: 50003
A16: 14 | B16: 5 | C16: 0 | D16: 绑架 | E16: 战斗胜利 | F16: 3 | G16: 0 | H16: 0 | I16: 0 | J16: 将对方掳走，携带在身上 | K16: 0 | L16: 0 | M16: 0 | N16: 0 | O16: 50006
A17: 15 | B17: 6 | C17: 0 | D17: 求饶 | E17: 战斗失败 | F17: 0 | G17: 0 | H17: 0 | I17: 0 | J17: 0 | K17: 5 | L17: 5 | M17: 0 | N17: 0 | O17: 60004
A18: 16 | B18: 6 | C18: 0 | D18: 要杀要剐，悉听尊便 | E18: 战斗失败 | F18: 0 | G18: 0 | H18: 0 | I18: 0 | J18: 0 | K18: 0 | L18: 0 | M18: 0 | N18: 0 | O18: 60001
A19: 17 | B19: 6 | C19: 0 | D19: 自行了断 | E19: 战斗失败 | F19: 0 | G19: 0 | H19: 0 | I19: 0 | J19: 0 | K19: 0 | L19: 0 | M19: 0 | N19: 0 | O19: 60002
A20: 18 | B20: 6 | C20: 0 | D20: 献物求生 | E20: 战斗失败 | F20: 0 | G20: 0 | H20: 0 | I20: 选择道具 | J20: 0 | K20: 5 | L20: 5 | M20: 0 | N20: 0 | O20: 60003
A21: 19 | B21: 7 | C21: 0 | D21: 义结金兰 | E21: 好感度越高，成功率越高。无性别限制，仅在未建立关系时显示 | F21: 10 | G21: 0 | H21: 70 | I21: 0 | J21: 成功：与对方成为异性兄弟； 失败：降低好感度 | K21: 5 | L21: 0 | M21: 0 | N21: 0 | O21: 70001
A22: 20 | B22: 7 | C22: 0 | D22: 倾诉爱意 | E22: 好感度越高，成功率越高。限制异性且无血缘关系，且非眷侣，非配偶显示。 | F22: 10 | G22: 0 | H22: 0 | I22: 0 | J22: 成功：与对方成为眷侣 失败：降低好感度 | K22: 5 | L22: 0 | M22: 0 | N22: 0 | O22: 70002
A23: 21 | B23: 7 | C23: 0 | D23: 共结连理 | E23: 必须是眷侣且没有和其他人成功共结连理显示，好感度越高，成功率越高。 | F23: 10 | G23: 0 | H23: 90 | I23: 0 | J23: 成功：与对方成为配偶 失败：降低好感度 | K23: 5 | L23: 0 | M23: 0 | N23: 0 | O23: 70003
A24: 22 | B24: 7 | C24: 19 | D24: 亲近 | E24: 仅关系为金兰显示 | F24: 1 | G24: 0 | H24: 50 | I24: 0 | J24: 0 | K24: 0 | L24: 0 | M24: 0 | N24: 0 | O24: 70004
A25: 23 | B25: 7 | C25: 19 | D25: 割袍断义 | E25: 仅关系为金兰显示 | F25: 0 | G25: 0 | H25: 50 | I25: 0 | J25: 0 | K25: 0 | L25: 0 | M25: 0 | N25: 0 | O25: 70005
A26: 24 | B26: 7 | C26: 21 | D26: 倾诉爱意 | E26: 仅关系为金兰显示 | F26: 5 | G26: 0 | H26: 0 | I26: 0 | J26: 0 | K26: 5 | L26: 0 | M26: 0 | N26: 0 | O26: 0
A27: 24 | B27: 7 | C27: 20 | D27: 风花雪月 | E27: 仅关系为眷侣显示 | F27: 10 | G27: 0 | H27: 70 | I27: 0 | J27: 0 | K27: 10 | L27: 0 | M27: 0 | N27: 0 | O27: 70006
A28: 25 | B28: 7 | C28: 20 | D28: 分手 | E28: 仅关系为眷侣显示 | F28: 0 | G28: 0 | H28: 0 | I28: 0 | J28: 0 | K28: 0 | L28: 0 | M28: 0 | N28: 0 | O28: 70007
A29: 26 | B29: 7 | C29: 21 | D29: 亲近 | E29: 仅关系为配偶显示 | F29: 1 | G29: 0 | H29: 80 | I29: 0 | J29: 0 | K29: 5 | L29: 0 | M29: 0 | N29: 0 | O29: 70008
A30: 27 | B30: 7 | C30: 21 | D30: 风华雪月 | E30: 仅关系为配偶显示 | F30: 10 | G30: 0 | H30: 80 | I30: 0 | J30: 0 | K30: 10 | L30: 0 | M30: 0 | N30: 0 | O30: 70009
A31: 28 | B31: 7 | C31: 21 | D31: 休书 | E31: 仅关系为配偶显示 | F31: 0 | G31: 0 | H31: 0 | I31: 0 | J31: 0 | K31: 0 | L31: 0 | M31: 0 | N31: 0 | O31: 70010
A32: 29 | B32: 1 | C32: 0 | D32: 踢馆（小弟子） | E32: 仅踢馆第一关显示 | F32: 5 | G32: 0 | H32: 0 | I32: 0 | J32: 0 | K32: 0 | L32: 0 | M32: 0 | N32: 0 | O32: 3
A33: 30 | B33: 1 | C33: 0 | D33: 踢馆（大弟子） | E33: 仅踢馆第二关显示 | F33: 5 | G33: 0 | H33: 0 | I33: 0 | J33: 0 | K33: 0 | L33: 0 | M33: 0 | N33: 0 | O33: 4
A34: 31 | B34: 1 | C34: 0 | D34: 踢馆（馆主） | E34: 仅踢馆第三关显示 | F34: 5 | G34: 0 | H34: 0 | I34: 0 | J34: 0 | K34: 0 | L34: 0 | M34: 0 | N34: 0 | O34: 5
A35: 32 | B35: 1 | C35: 0 | D35: 商店 | E35: 武馆永久显示 | F35: 0 | G35: 0 | H35: 0 | I35: 0 | J35: 0 | K35: 0 | L35: 0 | M35: 0 | N35: 0 | O35: 0
A36: 33 | B36: 1 | C36: 0 | D36: 馆主收益 | E36: 馆主身份显示 | F36: 0 | G36: 0 | H36: 0 | I36: 0 | J36: 0 | K36: 0 | L36: 0 | M36: 0 | N36: 0 | O36: 0

Sheet dialogChange
A1: ID | B1: A条件 | C1: A值 | D1: B条件 | E1: B值 | F1: 对话内容 | G1: 说明
A2: id | B2: aParam | C2: aValue | D2: bParam | E2: bValue | F2: content | G2: explain
A3: 1 | B3: SetSP(),PlayerLove(),1-,2- | C3: 25-,5-,friendsEr,lichang | F3: 蛇毒在体内淤积，不得排出。致使a内息受阻，全身乏力。幸而毒不致命，若来日多加修养调息，身体或也可以完全恢复。 | G3: 蛇毒在体内淤积，不得排出。致使a内息受阻，全身乏力。幸而毒不致命，若来日多加修养调息，身体或也可以完全恢复。
A4: 2 | B4: SetSP(),PlayerLove() | C4: 10-,10+ | D4: 3+,4+,15- | E4: friendsSan,lichang,LessenSP() | F4: p见a身中蛇毒，当即耗费内力帮助他打通内息，助其将毒素排出体外。方使其内脏免受蛇毒之害。 | G4: p见a身中蛇毒，当即耗费内力帮助他打通内息，助其将毒素排出体外。方使其内脏免受蛇毒之害。
A5: 3 | B5: SetSP(),PlayerLove() | C5: 10-,40- | D5: 1-,2-,20+,500+,15- | E5: friendsEr,lichang,xiuWei,sliver,LessenSP() | F5: 趁a无力反抗之际，p忽在暗中施以毒手，使其奄奄一息，生命垂危。 | G5: 趁a无力反抗之际，p忽在暗中施以毒手，使其奄奄一息，生命垂危。
A6: 4 | B6: SetSP(),npcLove<id> | C6: 25-,10- | D6: SetSP(),npcLove<id> | E6: 25-,10- | F6: a与b在几十个回合后两败俱伤，无力再斗下去。心中对对方的仇怨也更加深了几分。 | G6: a与b在几十个回合后两败俱伤，无力再斗下去。心中对对方的仇怨也更加深了几分。
A7: 5 | B7: PlayerLove() | C7: 10- | D7: PlayerLove(),3+,4+,15- | E7: 10-,friendsSan,lichang,LessenSP() | F7: 因为忌惮p武功高强，在江湖中又颇有名望，a和b双方决定暂时罢手，相约他日再做了断。 | G7: 因为忌惮p武功高强，在江湖中又颇有名望，a和b双方决定暂时罢手，相约他日再做了断。
A8: 6 | B8: PlayerLove() | C8: 10+ | D8: PlayerLove(),3-,4-,10+,15- | E8: 10-,friendsEr,lichang,xiuWei,LessenSP() | F8: 双拳难敌四手，b在a得到p出手相助之后，立刻难以支撑，数招之后负伤逃走。 | G8: 双拳难敌四手，b在a得到p出手相助之后，立刻难以支撑，数招之后负伤逃走。
A9: 7 | B9: PlayerLove() | C9: 10- | D9: PlayerLove(),3-,4-,10+,15- | E9: 10+,friendsEr,lichang,xiuWei,LessenSP() | F9: 双拳难敌四手，a在b得到p出手相助之后，立刻难以支撑，数招之后负伤逃走。 | G9: 双拳难敌四手，a在b得到p出手相助之后，立刻难以支撑，数招之后负伤逃走。
A10: 8 | B10: goldCoin | C10: 1000+ | F10: a讲到精彩之处，人们不禁纷纷喝彩鼓掌，不少路人拿出散碎银两来打赏。 | G10: a讲到精彩之处，人们不禁纷纷喝彩鼓掌，不少路人拿出散碎银两来打赏。
A11: 9 | B11: goldCoin,PlayerLove() | C11: 700+,10+ | D11: 500+,3+,4+,10- | E11: sliver,friendsSan,lichang,LessenSP() | F11: p听闻a所讲的轶事恰是自己日前亲眼所见，便在一旁帮腔协助。半晌下来，两人都得了不少的赏钱。 | G11: p听闻a所讲的轶事恰是自己日前亲眼所见，便在一旁帮腔协助。半晌下来，两人都得了不少的赏钱。
A12: 10 | B12: PlayerLove() | C12: 10- | D12: 3-,4-,10+,15- | E12: friendsEr,lichang,XiuWei,LessenSP() | F12: p听闻自己日前亲眼所见之事被a添油加醋，忍不住出手将a教训一番。 | G12: p听闻自己日前亲眼所见之事被a添油加醋，忍不住出手将a教训一番。
A13: 11 | B13: npcLove<id>,SetSP() | C13: 10+,10- | D13: npcLove<id>,SetSP() | E13: 10+,10- | F13: a与b把酒畅谈，喝了个痛快。两人的江湖情意也愈发深厚了。 | G13: a与b把酒畅谈，喝了个痛快。两人的江湖情意也愈发深厚了。
A14: 12 | B14: npcLove<id>,PlayerLove() ,500- | C14: 10+,10+,sliver | D14: npcLove<id>,PlayerLove(),5+,4+,10- | E14: 10+,10+,friendsSan,lichang,LessenSP() | F14: p真是性情中人，见到a与b痛饮畅谈、兴高采烈，便豪爽地主动请客，与两位同桌同饮。 | G14: p真是性情中人，见到a与b痛饮畅谈、兴高采烈，便豪爽地主动请客，与两位同桌同饮。
A15: 13 | B15: PlayerLove() | C15: 5- | D15: PlayerLove(),1+,2+,10-,20+ | E15: 5-,friendsSan,lichang,LessenSP(),xiuWei | F15: a与b喝到尽兴之时，难免吵闹喧哗，惹得邻座食客没法安心用餐，p实在难忍，出手教训了二人一番。 | G15: a与b喝到尽兴之时，难免吵闹喧哗，惹得邻座食客没法安心用餐，p实在难忍，出手教训了二人一番。
A16: 14 | B16: SetSP(),1-,2- | C16: 5-,friendsEr,lichang | F16: a在许久之后觉得慢慢恢复了。全身酸痛乏力却暂时搞不清病因在哪。 | G16: a在许久之后觉得慢慢恢复了。全身酸痛乏力却暂时搞不清病因在哪。
A17: 15 | B17: SetSP(),PlayerLove() | C17: 5-,5- | D17: 500+,10-,3-,4-,300- | E17: sliver,LessenSP(),friendsEr,lichang,sliver | F17: p趁着a无力反抗之际，上前施以拳脚，抢走了a的钱袋。 | G17: p趁着a无力反抗之际，上前施以拳脚，抢走了a的钱袋。
A18: 16 | B18: SetSP(),PlayerLove() | C18: 5+,10+ | D18: 3+,4+,10- | E18: friendsSan,lichang,LessenSP() | F18: p掐住a的人中，将其唤醒后。简单照料一番。待其恢复后才放心离开。 | G18: p掐住a的人中，将其唤醒后。简单照料一番。待其恢复后才放心离开。
A19: 17 | B19: xiuWei,SetSP() | C19: 150+,20- | F19: 一回生，二回熟。用心复习之后，a的修为和功力都有所增进。 | G19: 一回生，二回熟。用心复习之后，a的修为和功力都有所增进。
A20: 18 | B20: xiuWei,SetSP(),PlayerLove() | C20: 10+,10-,10+ | D20: 10+,10-,1+,3+ | E20: xiuWei,LessenSP(),friendsSan,lichang | F20: p见到a正在独自习武，自忖对方功力与自己相当，便上前以武会友，搭手陪练。 | G20: p见到a正在独自习武，自忖对方功力与自己相当，便上前以武会友，搭手陪练。
A21: 19 | B21: xiuWei,SetSP(),PlayerLove(),10+,10-,1+,3+ | C21: 30+,10-,10+,xiuWei,LessenSP(),friendsSan,lichang | F21: p将自己习武的经验分享给a，让其触类旁通，这一遭修行堪比平日数次所得。 | G21: p将自己习武的经验分享给a，让其触类旁通，这一遭修行堪比平日数次所得。
A22: 20 | B22: SetSP(),PlayerLove(),5-,6-,15- | C22: 25-,10-,friendsEr,lichang,LessenSP() | F22: a正在专心习武之际，忽遭p偷袭。半日修习不但未有精进，反因被袭负伤。心中颇为愤恨。 | G22: a正在专心习武之际，忽遭p偷袭。半日修习不但未有精进，反因被袭负伤。心中颇为愤恨。
A23: 21 | B23: xiuWei,SetSP() | C23: 15+,20- | F23: 果然熟能生巧，a勤加练习之后，武学进境和修为感悟都有了些许提升。 | G23: 果然熟能生巧，a勤加练习之后，武学进境和修为感悟都有了些许提升。
A24: 22 | B24: xiuWei,SetSP(),PlayerLove() | C24: 10+,10-,10+ | D24: 10-,3+,4+,20+ | E24: LessenSP(),friendsSan,lichang,xiuWei | F24: p见到a正在独自打坐修行，便请求上前与其同修，二人四掌合十后内息交互，流经周身。各有丰厚收益。 | G24: p见到a正在独自打坐修行，便请求上前与其同修，二人四掌合十后内息交互，流经周身。各有丰厚收益。
A25: 23 | B25: xiuWei,SetSP(),PlayerLove(),5+,6+,15- | C25: 20+,10-,10+,friendsSan,lichang,LessenSP() | F25: p见其独自修行进步缓慢，便以自身内力相助其打通经脉。让a颇为感激这一臂之力。 | G25: p见其独自修行进步缓慢，便以自身内力相助其打通经脉。让a颇为感激这一臂之力。
A26: 24 | B26: SetSP(),PlayerLove(),5-,6-,15-,20+ | C26: 10-,10-,friendsEr,lichang,LessenSP(),xiuWei | F26: a正在潜心修炼内功之时，忽遭p偷袭，不但前功尽弃且反受重伤。心中颇为愤恨。 | G26: a正在潜心修炼内功之时，忽遭p偷袭，不但前功尽弃且反受重伤。心中颇为愤恨。
A27: 25 | B27: xiuWei,SetSP() | C27: 15+,25- | F27: a施展着招式迎风起舞，将刚刚参悟的谜题一一验证。武功修为大有进境。 | G27: a施展着招式迎风起舞，将刚刚参悟的谜题一一验证。武功修为大有进境。
A28: 26 | B28: xiuWei,SetSP(),PlayerLove(),20+,20-,3+,5+ | C28: 20+,20-,15+,xiuWei,LessenSP(),friendsSan,lichang | F28: p见到a正在独自习武，上前与其陪手对练。二人拆招换式你来我往，各有收益。 | G28: p见到a正在独自习武，上前与其陪手对练。二人拆招换式你来我往，各有收益。
A29: 27 | B29: xiuWei,SetSP(),PlayerLove(),20+,20-,3+,5+ | C29: 50+,10-,10+,xiuWei,LessenSP(),friendsSan,lichang | F29: a所练招式虽然精妙，p却仍能想出破解之法并不吝传授，半日下来，二人武学都有不小的进步。 | G29: a所练招式虽然精妙，p却仍能想出破解之法并不吝传授，半日下来，二人武学都有不小的进步。
A30: 28 | B30: SetSP(),PlayerLove(),20+,20-,3-,5- | C30: 10-,10+,xiuWei,LessenSP(),friendsEr,lichang | F30: 繁琐复杂的招式让a筋疲力尽，p却趁人之危，藉此偷袭。使其受伤颇重，堪堪活命。 | G30: 繁琐复杂的招式让a筋疲力尽，p却趁人之危，藉此偷袭。使其受伤颇重，堪堪活命。
A31: 29 | B31: xiuWei,SetSP() | C31: 35+,25- | F31: 凝神静气半晌之后，a终于百尺竿头更近一步，突破自身极限并从修炼中大获收益。 | G31: 凝神静气半晌之后，a终于百尺竿头更近一步，突破自身极限并从修炼中大获收益。
A32: 30 | B32: xiuWei,SetSP(),PlayerLove(),20+,20-,3+,5+ | C32: 50+,10-,10+,xiuWei,LessenSP(),friendsSan,lichang | F32: p见到a正在独自打坐修行，便请求上前与其同修，二人四掌合十后内息交互，流经周身，各有丰厚收益。 | G32: p见到a正在独自打坐修行，便请求上前与其同修，二人四掌合十后内息交互，流经周身，各有丰厚收益。
A33: 31 | B33: xiuWei,SetSP(),PlayerLove(),20-,3+,5+ | C33: 50+,10-,10+,LessenSP(),friendsSan,lichang | F33: p在a即将冲破玄关之际，鼎力相助，耗费精力帮其打通周身经络。 | G33: p在a即将冲破玄关之际，鼎力相助，耗费精力帮其打通周身经络。
A34: 32 | B34: PlayerLove(),SetSP(),20-,3-,5- | C34: 10-,25-,LessenSP(),friendsEr,lichang | F34: a正在潜心冲关紧要之刻，忽遭p偷袭，顿时内息紊乱，气血大损。 | G34: a正在潜心冲关紧要之刻，忽遭p偷袭，顿时内息紊乱，气血大损。
A35: 33 | B35: SetSP() | C35: 40+ | F35: 经过了一段时间的调息，a的精力恢复了些许。 | G35: 经过了一段时间的调息，a的精力恢复了些许。
A36: 34 | B36: PlayerLove(),SetSP(),10-,3+,5+ | C36: 20+,20+,LessenSP(),friendsSan,lichang | F36: 恻隐难忍的p就近买了些食物药材送给a，助其快速恢复。 | G36: 恻隐难忍的p就近买了些食物药材送给a，助其快速恢复。
A37: 35 | B37: PlayerLove(),SetSP(),10-,3-,5- | C37: 10-,20-,LessenSP(),friendsEr,lichang | F37: a被仇视已久p抓住机会突施毒手，一惊之下仓皇逃跑。 | G37: a被仇视已久p抓住机会突施毒手，一惊之下仓皇逃跑。
A38: 36 | B38: npcLove<id>,SetSP(),xiuWei | C38: 10+,30-,100+ | D38: npcLove<id>,SetSP(),xiuWei | E38: 10+,30-,100+ | F38: a与b斗至酣处，丝毫未觉已经过去了两个时辰，难分高下的他们精疲力竭，商定他日再战。 | G38: a与b斗至酣处，丝毫未觉已经过去了两个时辰，难分高下的他们精疲力竭，商定他日再战。
A39: 37 | B39: PlayerLove() | C39: 10+ | D39: 10-,3+,5+,10+,10+ | E39: LessenSP(),friendsSan,lichang,xiuWei,PlayerLove() | F39: p突然闪身出现，举兵刃架开双方刀剑，止住缠斗。a和b均暗自赞叹来者武艺高强，心生敬意。 | G39: p突然闪身出现，举兵刃架开双方刀剑，止住缠斗。a和b均暗自赞叹来者武艺高强，心生敬意。
A40: 38 | B40: PlayerLove() | C40: 10+ | D40: 10-,3-,5-,10+,10+ | E40: LessenSP(),friendsEr,lichang,xiuWei,PlayerLove() | F40: 随着p的参战，势均力敌的局面开始慢慢失衡，b逐渐支撑不住，最后被a打伤逃走。 | G40: 随着p的参战，势均力敌的局面开始慢慢失衡，b逐渐支撑不住，最后被a打伤逃走。
...

Sheet Dialog
A1: ID | B1: 参数 | C1: 条件 | D1: 参数 | E1: 内容 | F1: 类型 | G1: 优先级
A2: id | B2: playerParam | C2: term | D2: npcParam | E2: content | F2: type | G2: weight
A3: 1 | B3: ager | C3: // | D3: age | E3: 这位朋友，你我年龄相仿，有话但讲无妨。 | F3: 1 | G3: 1
A4: 2 | B4: ager | C4: > | D4: age | E4: 这位朋友，有何见教？ | F4: 1 | G4: 1
A5: 3 | B5: ager,40 | C5: <,< | D5: age,age | E5: 阁下说话爽快些，有事不妨直说。 | F5: 1 | G5: 1
A6: 4 | B6: gold | C6: > | D6: money | E6: 阁下必是富贵之人，鄙人随时效劳。 | F6: 1 | G6: 1
A7: 5 | B7: 1000 | C7: < | D7: age | E7: 看起来这位客官也不像个有钱的样子，想买些什么就自便吧。 | F7: 1 | G7: 1
A8: 6 | B8: attribute | C8: > | D8: attribute | E8: 这位大侠境界高深，在下十分钦佩。 | F8: 1 | G8: 1
A9: 7 | B9: attribute | C9: < | D9: attribute | E9: 阁下修为根基尚浅、闯荡江湖还需多加磨炼。 | F9: 1 | G9: 1
A10: 8 | B10: sect,sect | C10: //,!/ | D10: sect,0 | E10: 阁下与我既有同门手足之谊，自然不必见外，若有所需，但讲无妨。 | F10: 1 | G10: 2
A11: 9 | B11: sex | C11: // | D11: 1 | E11: 在下有礼了，不知这位兄台有何指教？ | F11: 1 | G11: 1
A12: 10 | B12: sex | C12: !/ | D12: 1 | E12: 在下有礼了，不知这位姑娘有何指教？ | F12: 1 | G12: 1
A13: 11 | B13: 1000 | C13: < | D13: age | E13: 小可见过前辈，不知道前辈有何指教？ | F13: 1 | G13: 1
A14: 12 | B14: sex,ager | C14: //,< | D14: 1,age | E14: 小兄弟不必拘束，有话直说就好。 | F14: 1 | G14: 1
A15: 13 | B15: sex,ager | C15: !/,> | D15: 1,age | E15: 这位姐姐可是有事相询？ | F15: 1 | G15: 1
A16: 14 | B16: sex,ager | C16: !/,< | D16: 1,age | E16: 这位妹妹可是有事相询？ | F16: 1 | G16: 1
A17: 15 | B17: 1000 | C17: < | D17: age | E17: 既已结为知交，有何需要不妨直说，无需多虑。 | F17: 1 | G17: 1
A18: 16 | B18: 0 | C18: // | D18: love | E18: 这位朋友看着面生，不知何事要与在下相谈？ | F18: 1 | G18: 1
A19: 17 | B19: 80,sex | C19: <,// | D19: love,1 | E19: 好兄弟，共患难，有事尽管说来，在下一定尽力。 | F19: 1 | G19: 1
A20: 18 | B20: 80,sex | C20: <,!/ | D20: love,1 | E20: 好姐妹，有何指教？ | F20: 1 | G20: 2
A21: 19 | B21: 1 | C21: // | D21: JiaoQing<JinLan> | E21: 既有金兰之义，又为生死之交，若有差遣吩咐，直言便是了。 | F21: 1 | G21: 3
A22: 20 | B22: 1 | C22: // | D22: JiaoQing<JuanLv> | E22: 你我既已深情相许，倾心相交。无论何事皆可直言，无须忌讳。 | F22: 1 | G22: 3
A23: 21 | B23: sex,1 | C23: //,// | D23: 1,JiaoQing<PeiOu> | E23: 郎君，妾身既已许卿，相公之事，便是我之事…… | F23: 1 | G23: 3
A24: 22 | B24: sex,1 | C24: !/,// | D24: 1,JiaoQing<PeiOu> | E24: 夫人，你我既已结发，便不负一生相守，娘子之语，便是我分内所在。 | F24: 1 | G24: 3
A25: 23 | B25: 1 | C25: // | D25: state | E25: 阁下有事可否待我吃完再谈？又或者坐下一同进膳？ | F25: 1 | G25: 9
A26: 24 | B26: 2 | C26: // | D26: state | E26: 此人已陷入沉睡，对周遭事物少有防备…… | F26: 1 | G26: 99
A27: 25 | B27: 3 | C27: // | D27: state | E27: 正在山野路旁赏景采摘的{0}看见你走来，缓缓开口道:“想不到这位朋友也有如此雅兴，要结伴一起赏花吗？” | F27: 1 | G27: 9
A28: 26 | B28: 3 | C28: // | D28: state | E28: {0}饶有兴致的看着刚刚采到的草药，开口问道:“你可识得这株花草吗?” | F28: 1 | G28: 9
A29: 27 | B29: 4 | C29: // | D29: state | E29: ({0}似乎正在聚精会神的观察和思考着什么，看起来不太方便被打扰的样子。) | F29: 1 | G29: 9
A30: 28 | B30: 5 | C30: // | D30: state | E30: 身形矫健的{0}收起了架势，擦了擦头上的汗，转身对你说到：“有钱捧个钱场，无钱捧个人场，都是真功夫！” | F30: 1 | G30: 9
A31: 29 | B31: 6 | C31: // | D31: state | E31: （一身蓑衣的{0}扭头看向你，朝你摆了摆手）嘘……慢点，别把鱼儿惊跑了。 | F31: 1 | G31: 9
A32: 30 | B32: 6 | C32: // | D32: state | E32: （{0}把钓上来的鱼装进竹篓之后，又用力的向前抛了一杆）朋友可有闲情雅致，陪我一起垂钓一番？ | F32: 1 | G32: 9
A33: 31 | B33: 7 | C33: // | D33: state | E33: 放下工具后直起腰身，擦了擦额头上的汗，对你说到：“呼……这活儿甚是辛苦，朋友，你有何事如此着急？” | F33: 1 | G33: 9
A34: 32 | B34: 7 | C34: // | D34: state | E34: 蹲在地上干活的{0}看见你走近，缓缓的站了起来，沙哑的开口道：“这位朋友，有事站在原地说就好，莫要踩到我这块地。” | F34: 1 | G34: 9
A35: 33 | B35: 8 | C35: // | D35: state | E35: 在下适才实在难忍那厮折辱，教训了那厮一番……莫要引来仇怨才是…… | F35: 1 | G35: 9
A36: 34 | B36: 9 | C36: // | D36: state | E36: 文人模样的{0}在路边在路边桌案上手执纸笔正在写着什么。听到你步声渐进，头也不抬地说道：“代写书信五文钱一封。” | F36: 1 | G36: 9
... A38: 36 | B38: 11 | C38: // | D38: state | E38: （神态疲惫、面色苍白的{0}懒散的坐在地上，一言不发。） | F38: 1 | G38: 9
A39: 37 | B39: 99,1 | C39: //,!/ | D39: state,sex | E39: 这位朋友，且恕小女子有孕在身，不便施礼。若有何事请直言便好。 | F39: 1 | G39: 9
A40: 38 | B40: 99,1 | C40: //,!/ | D40: state,sex | E40: 若是有什么事情，还请阁下快些言讲出来，小女子身怀六甲，眼下便要回房休息去了。 | F40: 1 | G40: 9
A41: 39 | B41: 99,1 | C41: //,!/ | D41: state,sex | E41: 小女子方才从郎中处得知脉象呈喜，此间正要早些回家休息，这位朋友若是有什么事情，还请简单直言。 | F41: 1 | G41: 9
...

Sheet dialogTerm
A1: 条件ID | B1: 条件 | C1: 比较 | D1: 值 | E1: 不满足提示
A2: id | B2: param | C2: term | D2: value | E2: notTips
A3: 0 | E3: 空条件
A4: 1 | B4: sliver | C4: > | D4: 100 | E4: (金钱>100)
A5: 2 | B5: SP | C5: > | D5: 10 | E5: (精力>10)
A6: 3 | B6: SP | C6: > | D6: 20 | E6: (精力>20)
A7: 4 | B7: attribute | C7: > | D7: 3 | E7: (境界>3)
A8: 5 | B8: attribute | C8: > | D8: attribute | E8: (境界高于对方)
A9: 6 | B9: WxNum | C9: > | D9: 15 | E9: (悟性>20)

Sheet NpcXingWeiTalk
A1: ID | B1: 类别 | C1: 说明 | D1: 我方请求内容 | E1: 对方对你请求内容的回应 | F1: npc判定成功 | G1: npc判定失败 | H1: npc第二级行为判定成功 | I1: npc第二级行为判定失败
A2: id | B2: type | C2: tip | D2: connect | E2: connect2 | F2: Success1 | G2: failure1 | H2: Success2 | I2: failure2
A3: 1 | B3: 1 | C3: 打招呼 | D3: 0 | E3: 0 | F3: 哦？不想在此又与阁下见面了。 | G3: 初次相见，却不知有何见教？ | H3: 0 | I3: 0
A4: 2 | B4: 1 | C4: 武馆（挑战前对话） | D4: 0 | E4: {0}：欢迎你的到来，有什么可以为你效劳的呢？ | F4: 0 | G4: 0 | H4: 0 | I4: 0
A5: 3 | B5: 1 | C5: 武馆（踢馆小弟子） | D5: 0 | E5: {0}：想挑战我，先跟我小弟子门打一场吧 | F5: {0}：没想到你有点本事啊 | G5: {0}：你连我小弟子都打不过，还想挑战我？ | H5: 0 | I5: 0
A6: 4 | B6: 1 | C6: 武馆（踢馆大弟子） | D6: 0 | E6: {0}：想挑战我，先跟我大弟子门打一场吧 | F6: {0}：不错，你有资格挑战我。 | G6: {0}：你连我大弟子都打不过，还想挑战我？。 | H6: 0 | I6: 0
A7: 5 | B7: 1 | C7: 武馆（踢馆馆主） | D7: 0 | E7: {0}：总于。。。。要我出场了吗 | F7: {0}：不可能。。。。。。好吧。。。。。馆主是你的了 | G7: {0}：你很厉害，不过你比我还差点 | H7: 0 | I7: 0
A8: 10001 | B8: 1 | C8: 闲聊 | D8: 0 | E8: {0}：特意来找我相谈，可是最近江湖上有了什么新鲜事儿？ | F8: {0}：早就想知道关于这件事的消息了，多谢大侠告知。 | G8: {0}：此事我早已听说，不过平平无奇的世俗琐事而已，不值一提。 | H8: 0 | I8: 0
A9: 20001 | B9: 2 | C9: 请求东西 | D9: {0}：朋友身上这件宝贝恰是在下苦求难得之物，不知是否可以慷慨相赠。 | E9: {0}听了你的请求，稍微犹豫了一会 | F9: {0}：这本是我颇费周折得来之物，不过既然是朋友想要，自然不该吝啬，你拿去便是了。 | G9: {0}：实不相瞒，这东西正是我眼下当用之物，确实不方便赠予阁下，还请见谅 | H9: 0 | I9: 0
A10: 30001 | B10: 3 | C10: 送礼 | D10: {0}：最近新得了一个小物件，想到朋友你应该会喜欢，便特意送来给你了。 | E10: {0}满脸期待，伸手接过你给的物品，仔细的看了看。 | F10: {0}：太棒了，这是我喜欢的东西&{0}：这东西虽然不是我喜欢的，但是还不错，我收下了 | G10: {0}：这礼物确实是我喜欢的，只恐在下身无长物，无以回赠，因而愧不敢受。 | H10: 0 | I10: 0
A11: 30002 | B11: 3 | C11: 切磋武学 | D11: {0}：近日来疏于练习，拳脚都有些生疏了，不如你我切磋一番如何？ | E11: {0}听闻“切磋”二字，不自觉的舒展了一下筋骨 | F11: {0}：我也正有此意，请赐教 | G11: {0}：今日身体略有不适，还是改日再与阁下切磋吧 | H11: {0}:想不到你武功早已今非昔比，在下输得心服口服 | I11: {0}：承让，阁下这拳脚功夫确实还需勤加练习才是。
A12: 40001 | B12: 4 | C12: 嘲讽 | D12: {0}：看你这般模样，武功、才学、品德都是武林之中下下品，实在是江湖之笑柄。 | E12: {0}眉头微皱的看了看你 | F12: {0}：阁下如此言行，莫不是诚心要惹是生非？ | G12: {0}：我不屑与你一般见识，也请阁下就此作罢，莫要再咄咄逼人了。 | H12: {0}：看阁下气焰嚣张，还以为武功了得，却不想如此不堪一击。 | I12: {0}：恃强凌弱而已，哼！
A13: 40002 | B13: 4 | C13: 偷窃 | D13: 0 | E13: {0}在你伸手行窃的瞬间感到了一丝异样。 | F13: {0}：鸡鸣狗盗之辈，看招！ | G13: 轻微的异样并未引起{0}的格外注意，稍一晃神之后，就继续忙着自己的事情了 | H13: {0}：今日饶你一命，若再敢行窃，必然把你绑送官府。 | I13: {0}：没想到你这蟊贼也有一身好武功，我无话可说。
A14: 40003 | B14: 4 | C14: 抢夺 | D14: {0}：这位朋友，若是想安稳的活过今日，就把身上值钱的东西交出来吧。 | E14: 见你横在面前，{0}后退了两步 | F14: {0}：青天白日便敢如此行凶，实在是欺人太甚 | G14: 0 | H14: {0}：恃强凌弱而已，哼！我既技不如人，无话可说。 | I14: {0}：今日饶你一命，若再敢行凶抢劫，必然把你绑送官府
A15: 40004 | B15: 4 | C15: 袭击 | D15: {0} | E15: {0}耳边听得你一击袭来，敏捷的躲开之后，转头向你，目光如炬。 | F15: {0}：我与阁下有何仇怨，为何拔刀相向？ | G15: 0 | H15: {0}：山野蛮夫，逞凶斗狠而已，算什么英雄好汉，要杀要剐悉听尊便。 | I15: {0}：你这歹人，今日有次一败，看你日后还敢行凶否?
A16: 50001 | B16: 5 | C16: 斩杀 | D16: 你杀心骤起，决意置{0}于死地。 | E16: 0 | F16: {0}：无非一死而已，动手吧 | G16: {0}：多谢不杀之恩 | H16: 0 | I16: 0
A17: 50004 | B17: 5 | C17: 羞辱 | D17: 你朝着{0}重重的吐了一口口水，而后对其一番污言秽语。 | E17: 0 | F17: {0}：今日奇耻大辱，在下记下了，他日定当讨要个说法 | G17: {0}轻蔑的冷笑了一声，对你的无礼言行置之不理。 | H17: 0 | I17: 0
A18: 50005 | B18: 5 | C18: 放其一马 | D18: 念在{0}平日里作恶不深，你决定大人不记小人过，放他一马。 | E18: 0 | F18: {0}：多谢您高抬贵手，后会有期 | G18: 0 | H18: 0 | I18: 0
A19: 50003 | B19: 5 | C19: 伤害 | D19: 你举起兵刃，决意痛下毒手，砍向对方要害，独留对方一口活气而已 | E19: 0 | F19: {0}：你这心如蛇蝎的恶徒，必遭天谴 | G19: 0 | H19: 0 | I19: 0
A20: 50006 | B20: 5 | C20: 绑架 | D20: 暂未实现 | E20: 0 | F20: 暂未实现 | G20: {0}：暂未实现 | H20: 0 | I20: 0
A21: 60001 | B21: 6 | C21: 要杀要剐，悉听尊便 | D21: 0 | E21: {0}：今日一败，无非一死而已。要杀要剐，悉听尊便 | F21: 0 | G21: 0 | H21: 0 | I21: 0
A22: 60002 | B22: 6 | C22: 自行了断 | D22: 0 | E22: {0}：今日受此大辱，岂能继续苟活世间。 | F22: 0 | G22: 0 | H22: 0 | I22: 0
A23: 60003 | B23: 6 | C23: 献物求生 | D23: 0 | E23: {0}：求大侠高抬贵手放我一命，若是大侠不弃，我愿将此宝物双手奉上 | F23: 0 | G23: 0 | H23: 0 | I23: 0
A24: 60004 | B24: 6 | C24: 求饶 | D24: 0 | E24: {0}：小的命不足惜，还望大人不记小人过，放我一条性命，来日自当为阁下当牛做马 | F24: 0 | G24: 0 | H24: 0 | I24: 0
A25: 70001 | B25: 7 | C25: 义结金兰 | D25: {0}：你我二人性情相近，志趣相投，不知道我鄙人否有幸与阁下不知道阁下义结金兰 | E25: {0}听闻你的一番言语，激动之情溢于言表。 | F25: {0}：此一番你我二人结义，实在是三生有幸。 | G25: {0}：此番厚爱实在是愧不敢当，怎奈人各有志，我与阁下非同路之人，恕在下难以从命了。 | H25: 0 | I25: 0
A26: 70002 | B26: 7 | C26: 倾诉爱意 | D26: {0}：我对你仰慕已久，不知是否有幸结识？ | E26: {0}听闻你突如其来的表白，一下子怔住了。 | F26: {0}：被阁下青睐，实属有幸，望来日可以朝暮相伴，三生相约。 | G26: {0}：我孤身一身闯荡江湖惯了，儿女私情不足虑也，你我还是萍水相逢的好。 | H26: 0 | I26: 0
A27: 70003 | B27: 7 | C27: 共结连理 | D27: {0}：你我相识日久，其实我对你早已倾心，不知可愿与共结连理，我白首偕老？ | E27: {0}听闻你突如其来的表白，一下子怔住了。 | F27: {0}：愿你我二人结发白首，直至山无角楞，江水为竭。 | G27: {0}：若要约定三生，自当有媒妁之言，高堂之命，你如此轻言出口，委实让人难以应允。 | H27: 0 | I27: 0
A28: 70004 | B28: 7 | C28: 义结金兰/亲近 | D28: {0}：你我二人今日重逢，不如举杯三千，百无禁忌恣意欢谑一次，如何？ | E28: 0 | F28: {0}：快哉！ | G28: 0 | H28: 0 | I28: 0
A29: 70005 | B29: 7 | C29: 义结金兰/割袍断义 | D29: {0}：自此之后，你我兄弟恩断义绝，再无瓜葛，望你好自为之！ | E29: {0}脸上的表情略有些复杂，似乎一半惊诧，一般愤怒。 | F29: {0}：兄弟当真要与我割袍断义？如此也好，免得耽误了兄弟的前程。 | G29: 0 | H29: 0 | I29: 0
A30: 70006 | B30: 7 | C30: 眷侣/风花雪月 | D30: {0}：近日江湖奔波，颇为辛劳，不如你我今日不言刀剑，只谈风月，如何？ | E30: {0}闻听你所言，面颊上绯色浮动，如晕渐浓。 | F30: {0}：依……依你便是~ | G30: {0}：这……周公之礼，还是留在你我合卺礼成之后，如何？ | H30: 0 | I30: 0
A31: 70007 | B31: 7 | C31: 眷侣/分手 | D31: {0}：我与你之间相处日久，愈发觉得琴瑟难鸣，不如早些分开吧 | E31: {0}不敢置信的看着你。 | F31: {0}：不曾想到你如此负心薄幸，今日遂了你的心愿，你我各觅佳偶便是 | G31: 0 | H31: 0 | I31: 0
A32: 70008 | B32: 7 | C32: 配偶/亲近 | D32: {0}：今日良辰美景，不如晚些一同赏月如何？ | E32: 0 | F32: {0}：月下观景，人生幸事也。心上人在侧，亦人生幸事也。 | G32: 0 | H32: 0 | I32: 0
A33: 70009 | B33: 7 | C33: 配偶/共度良宵 | D33: {0}：如此花月美景，你我郎情妾意，何不早些就寝，尽享春宵一刻。 | E33: {0}听了你的请求，脸上一阵惊讶，一阵羞赧，一阵不知所措。 | F33: {0}：依你便是~ | G33: {0}：每天都只想男欢女爱之事，不知上进。 | I33: 0
A34: 70010 | B34: 7 | C34: 配偶/休书 | D34: {0}：你我缘尽于此，今日与你休书一封，来日便不再是夫妻了。 | E34: {0}一脸不可置信，瞪大的双眼慢慢涌出泪水来 | F34: {0}：罢了，曾经的海誓山盟不过是过眼云烟而已，此言既已出口，还望你他日不会后悔。 | H34: 0 | I34: 0

Sheet ActionDialog
A1: 对话ID | B1: 初始对话 | C1: 初始选项 | D1: 初始方法 | E1: 条件ID | F1: 改变参数ID | G1: 成功对话 | H1: 成功选项 | I1: 成功方法 | J1: 失败对话 | K1: 失败选项 | L1: 失败方法
A2: id | B2: initDialog | C2: initLips | D2: initFun | E2: termID | F2: changeID | G2: succeedDialog | H2: succeedLips | I2: succeedFun | J2: failDialog | K2: failLips | L2: failFun
A3: 9 | B3: 阁下要打听何人？ | C3: 搜索,离开 | D3: Find,CloseUI
A4: 10 | B4: 此处房产冬暖夏凉，适宜住人。 | C4: 购买({0}文),开锁,离开 | D4: BuyHouse,OpenLock,CloseUI
A5: 11 | B5: 私家宅邸，闲人免入。 | C5: 购买({0}文),开锁,离开 | D5: BuyHouse,OpenLock,CloseUI
A6: 12 | B6: 此处房产已归属你的名下。 | C6: 离开 | D6: CloseUI
A7: 15 | B7: 这位朋友若有闲暇，不妨与在下一同去酒馆小酌几杯可好？ | C7: 赴约,拒绝 | D7: Friend,NoFriend | G7: 那我先行在酒铺找个安静的雅间，静等阁下了。 | H7: 暂且离去。 | I7: GoQPJG | J7: 下次有空，再来相约。 | K7: 暂且离去。 | L7: CloseUI
A8: 17 | B8: 关押着人质的牢门。 | C8: 放置,离开 | D8: PutNpc,CloseUI
A9: 18 | B9: 存取物品的箱子，无甚特别之处。 | C9: 存取物品,离开 | D9: StorageBox,CloseUI
A10: 19 | B10: 朱门半掩，幔舞似幻，隐现佳人妙影…… | C10: 掀帘而入,离开 | D10: EnterRoom,CloseUI

Sheet PlayerAction
A1: ID | B1: 参数 | C1: 条件 | D1: 值 | E1: 触发概率 | F1: 场合 | G1: 时辰要求 | H1: 天气要求 | I1: 改变参数 | J1: 赋值 | K1: 被动参数 | L1: 赋值 | M1: 文字说明 | N1: 对话ID | O1: 持续时间 | P1: CD时间(秒) | Q1: 权重 | R1: 权重分组 | S1: 事件广播参数
A2: id | B2: selfParam | C2: term | D2: sideParam | E2: prob | F2: place | G2: time | H2: weather | I2: changeParam | J2: changeValue | K2: playerParam | L2: playerValue | M2: explain | N2: dialogID | O2: duration | P2: cdTime | Q2: weight | R2: weightGroup | S2: msgTypeParam
A3: 1 | B3: attribute,goldCoin,lichang,500,id,kithKin<>,love | C3: //,<,<,<,!/,!/,< | D3: attribute,500,30,sliver,kithKin<>,1,1 | E3: 100 | F3: 1 | G3: 4,9 | H3: 0 | I3: goldCoin,100- | J3: 100+,sliver | M3: <color=#E64D00>a</color>趁<color=#E64D00>p</color>不备，悄然偷窃了些许钱财。 | N3: 1480 | O3: 50 | P3: 1600 | Q3: 5 | R3: 1 | S3: 2
A4: 2 | B4: attribute,goldCoin,lichang,500,id,kithKin<>,love | C4: <,<,<,<,!/,!/,< | D4: attribute,500,30,sliver,kithKin<>,1,1 | E4: 100 | F4: 1 | G4: 4,9 | H4: 0 | I4: goldCoin,100- | J4: 100+,sliver | M4: <color=#E64D00>a</color>趁<color=#E64D00>p</color>不备，悄然偷窃了些许钱财。 | N4: 1480 | O4: 50 | P4: 1600 | Q4: 5 | R4: 1 | S4: 2
A5: 3 | B5: attribute,goldCoin,lichang,500,3600,id,kithKin<>,love | C5: >,<,<,<,<,!/,!/,< | D5: attribute,500,30,sliver,gameTime,kithKin<>,1,1 | E5: 100 | F5: 1 | G5: 4,9 | H5: 0 | I5: goldCoin,100- | J5: 100+,sliver | M5: <color=#E64D00>a</color>趁<color=#E64D00>p</color>不备，悄然偷窃了些许钱财。 | N5: 1480 | O5: 50 | P5: 1600 | Q5: 5 | R5: 1 | S5: 2
A6: 4 | B6: attribute,goldCoin,lichang,id,kithKin<>,love | C6: //,<,<,!/,!/,< | D6: attribute,300,30,kithKin<>,1,1 | E6: 100 | F6: 1 | G6: 4,9 | H6: 0 | M6: <color=#E64D00>a</color>左寻右觅，但终未能成功窃取<color=#E64D00>p</color>钱财。 | N6: 1490 | O6: 50 | P6: 1600 | Q6: 5 | R6: 1 | S6: 2
A7: 5 | B7: attribute,goldCoin,lichang,id,kithKin<>,love | C7: <,<,<,!/,!/,< | D7: attribute,300,30,kithKin<>,1,1 | E7: 100 | F7: 1 | G7: 4,9 | H7: 0 | M7: <color=#E64D00>a</color>左寻右觅，但终未能成功窃取<color=#E64D00>p</color>钱财。 | N7: 1490 | O7: 50 | P7: 1600 | Q7: 5 | R7: 1 | S7: 2
A8: 6 | B8: attribute,goldCoin,lichang,3600,id,kithKin<>,love | C8: >,<,<,<,!/,!/,< | D8: attribute,300,30,gameTime,kithKin<>,1,1 | E8: 100 | F8: 1 | G8: 4,9 | H8: 0 | M8: <color=#E64D00>a</color>左寻右觅，但终未能成功窃取<color=#E64D00>p</color>钱财。 | N8: 1490 | O8: 50 | P8: 1600 | Q8: 5 | R8: 1 | S8: 2
A9: 7 | B9: attribute,goldCoin,lichang,500,id,kithKin<>,love | C9: //,<,<,<,!/,!/,< | D9: attribute,500,30,sliver,kithKin<>,1,1 | E9: 100 | F9: 1 | G9: 10,3 | H9: 0 | I9: goldCoin,100- | J9: 100+,sliver | M9: <color=#E64D00>a</color>趁<color=#E64D00>p</color>不备，悄然偷窃了些许钱财。 | N9: 1480 | O9: 50 | P9: 1600 | Q9: 15 | R9: 1 | S9: 2
A10: 8 | B10: attribute,goldCoin,lichang,500,id,kithKin<>,love | C10: <,<,<,<,!/,!/,< | D10: attribute,500,30,sliver,kithKin<>,1,1 | E10: 100 | F10: 1 | G10: 10,3 | H10: 0 | I10: goldCoin,100- | J10: 100+,sliver | M10: <color=#E64D00>a</color>趁<color=#E64D00>p</color>不备，悄然偷窃了些许钱财。 | N10: 1480 | O10: 50 | P10: 1600 | Q10: 15 | R10: 1 | S10: 2
A11: 9 | B11: attribute,goldCoin,lichang,500,3600,id,kithKin<>,love | C11: >,<,<,<,<,!/,!/,< | D11: attribute,500,30,sliver,gameTime,kithKin<>,1,1 | E11: 100 | F11: 1 | G11: 10,3 | H11: 0 | I11: goldCoin,100- | J11: 100+,sliver | M11: <color=#E64D00>a</color>趁<color=#E64D00>p</color>不备，悄然偷窃了些许钱财。 | N11: 1480 | O11: 50 | P11: 1600 | Q11: 15 | R11: 1 | S11: 2
A12: 10 | B12: attribute,goldCoin,lichang,id,kithKin<>,love | C12: //,<,<,!/,!/,< | D12: attribute,300,30,kithKin<>,1,1 | E12: 100 | F12: 1 | G12: 10,3 | H12: 0 | M12: <color=#E64D00>a</color>左寻右觅，但终未能成功窃取<color=#E64D00>p</color>钱财。 | N12: 1490 | O12: 50 | P12: 1600 | Q12: 15 | R12: 1 | S12: 2
A13: 11 | B13: attribute,goldCoin,lichang,id,kithKin<>,love | C13: <,<,<,!/,!/,< | D13: attribute,300,30,kithKin<>,1,1 | E13: 100 | F13: 1 | G13: 10,3 | H13: 0 | M13: <color=#E64D00>a</color>左寻右觅，但终未能成功窃取<color=#E64D00>p</color>钱财。 | N13: 1490 | O13: 50 | P13: 1600 | Q13: 15 | R13: 1 | S13: 2
A14: 12 | B14: attribute,goldCoin,lichang,3600,id,kithKin<>,love | C14: >,<,<,<,!/,!/,< | D14: attribute,300,30,gameTime,kithKin<>,1,1 | E14: 100 | F14: 1 | G14: 10,3 | H14: 0 | M14: <color=#E64D00>a</color>左寻右觅，但终未能成功窃取<color=#E64D00>p</color>钱财。 | N14: 1490 | O14: 50 | P14: 1600 | Q14: 15 | R14: 1 | S14: 2
A15: 13 | B15: lichang,lichang,45,55,goldCoin,id,kithKin<> | C15: >,<,<,>,>,!/,!/ | D15: 45,55,lichang,lichang,100,kithKin<>,1 | E15: 100 | F15: 1 | G15: 0 | H15: 0 | I15: goldCoin,PlayerLove(),100+ | J15: 100-,10+,sliver | M15: <color=#E64D00>a</color>听闻与<color=#E64D00>p</color>立场相近，特来相谈，一番攀谈之下，只觉与<color=#E64D00>p</color>言锋相合，特赠予了<color=#E64D00>p</color>些许银两。 | N15: 1500 | O15: 40 | P15: 1600 | Q15: 60 | R15: 2 | S15: 2
A16: 14 | B16: attribute,lichang,love,id,kithKin<>,love | C16: //,<,<,!/,!/,< | D16: attribute,40,0,kithKin<>,1,1 | E16: 0 | F16: 1 | G16: 4,9 | H16: 0 | I16: lichang,GetRandomItemAtPlayer() | J16: 10-,1 | M16: 心怀不轨的<color=#E64D00>a</color>暗中下手，窃取了<color=#E64D00>p</color>囊中物什…… | N16: 1510 | O16: 40 | P16: 1600 | Q16: 0 | R16: 1 | S16: 2
A17: 15 | B17: attribute,lichang,love,id,kithKin<>,love | C17: <,<,<,!/,!/,< | D17: attribute,40,0,kithKin<>,1,1 | E17: 0 | F17: 1 | G17: 4,9 | H17: 0 | I17: lichang,GetRandomItemAtPlayer() | J17: 10-,1 | M17: 心怀不轨的<color=#E64D00>a</color>暗中下手，窃取了<color=#E64D00>p</color>囊中物什…… | N17: 1510 | O17: 40 | P17: 1600 | Q17: 0 | R17: 1 | S17: 2
A18: 16 | B18: attribute,lichang,love,3600,id,kithKin<>,love | C18: >,<,<,<,!/,!/,< | D18: attribute,40,0,gameTime,kithKin<>,1,1 | E18: 0 | F18: 1 | G18: 4,9 | H18: 0 | I18: lichang,GetRandomItemAtPlayer() | J18: 10-,1 | M18: 心怀不轨的<color=#E64D00>a</color>暗中下手，窃取了<color=#E64D00>p</color>囊中物什…… | N18: 1510 | O18: 40 | P18: 1600 | Q18: 0 | R18: 1 | S18: 2
A19: 17 | B19: lichang,xiuWei,id,kithKin<> | C19: <,>,!/,!/ | D19: 40,200,kithKin<>,1 | E19: 100 | F19: 1 | G19: 4,9 | H19: 0 | I19: lichang,PlayerLove() | J19: 5+,5+ | M19: 行走江湖，当以武会友，<color=#E64D00>a</color>发起挑战，望请赐教，切莫避战。 | N19: 1520 | O19: 40 | P19: 1600 | Q19: 30 | R19: 2 | S19: 2
A20: 18 | B20: love,id,kithKin<> | C20: >,!/,!/ | D20: 10,kithKin<>,1 | E20: 100 | F20: 0 | G20: 0 | H20: 0 | I20: PlayerLove() | J20: 5+ | M20: <color=#E64D00>a</color>从远处遥望见昔日好友<color=#E64D00>p</color>，片刻间飞奔而至，滔滔不绝之下，与<color=#E64D00>p</color>相谈甚欢。 | N20: 1410 | O20: 60 | P20: 1600 | Q20: 31 | R20: 2 | S20: 2
A21: 19 | B21: love,id,kithKin<> | C21: <,!/,!/ | D21: -49,kithKin<>,1 | E21: 100 | F21: 0 | G21: 4,10 | H21: 0 | I21: lichang,PlayerLove() | J21: 5-,5- | M21: <color=#E64D00>a</color>发现了仇家<color=#E64D00>p</color>的行踪，从远处拔出刀冲向<color=#E64D00>p</color>，与<color=#E64D00>p</color>死命相搏。 | N21: 1420 | O21: 60 | P21: 1600 | Q21: 32 | R21: 1 | S21: 2
A22: 20 | B22: love,id,kithKin<> | C22: <,!/,!/ | D22: -30,kithKin<>,1 | E22: 100 | F22: 0 | G22: 4,10 | H22: 0 | I22: lichang,PlayerLove() | J22: 5-,5- | M22: 与<color=#E64D00>p</color>素有仇怨的<color=#E64D00>a</color>当街横在<color=#E64D00>p</color>面前，指着<color=#E64D00>p</color>向街坊邻居大肆辱骂了起来。 | N22: 1430 | O22: 60 | P22: 1600 | Q22: 33 | R22: 1 | S22: 2
A23: 21 | B23: love,100,id,kithKin<> | C23: <,<,!/,!/ | D23: -10,sliver,kithKin<>,1 | E23: 100 | F23: 0 | G23: 4,10 | H23: 0 | I23: goldCoin,100- | J23: 100+,sliver | M23: 对<color=#E64D00>p</color>怀恨在心的<color=#E64D00>a</color>暗中跟踪<color=#E64D00>p</color>，趁<color=#E64D00>p</color>不备，悄然偷窃了<color=#E64D00>p</color>钱财。 | N23: 1440 | O23: 60 | P23: 1600 | Q23: 40 | R23: 1 | S23: 2
A24: 22 | B24: relationship,JiaoQing<JinLan> | C24: //,// | D24: 1,1 | E24: 100 | F24: 0 | G24: 4,10 | H24: 0 | I24: PlayerLove() | J24: 5+ | M24: <color=#E64D00>a</color>听闻金兰好友<color=#E64D00>p</color>在此地行走，特意赶来与<color=#E64D00>p</color>相聚，将附近江湖之事尽数告知于<color=#E64D00>p</color>。 | N24: 1450 | O24: 60 | P24: 1600 | Q24: 40 | R24: 2 | S24: 2
A25: 23 | B25: relationship,JiaoQing<JuanLv> | C25: //,// | D25: 2,1 | E25: 100 | F25: 0 | G25: 4,10 | H25: 0 | I25: PlayerLove(),energy | J25: 8+,5- | M25: <color=#E64D00>a</color>听闻红颜眷侣<color=#E64D00>p</color>在此处，思念甚厚，特来寻<color=#E64D00>p</color>相聚片刻。 | N25: 1460 | O25: 60 | P25: 1600 | Q25: 41 | R25: 2 | S25: 2
A26: 24 | B26: relationship,JiaoQing<PeiOu> | C26: //,// | D26: 3,1 | E26: 100 | F26: 0 | G26: 4,10 | H26: 0 | I26: PlayerLove() | J26: 5+ | M26: 与<color=#E64D00>p</color>万分恩爱的<color=#E64D00>a</color>倍感思念，特来寻<color=#E64D00>p</color>相聚片刻。 | N26: 1470 | O26: 60 | P26: 1600 | Q26: 42 | R26: 2 | S26: 2
A27: 25 | B27: love,lichang,lichang,54,69,14,kithKin<>,JiaoQing<ChouDi> | C27: //,>,<,<,>,>,!/,!/ | D27: 0,54,69,lichang,lichang,friendsSan,1,1 | E27: 100 | F27: 0 | G27: 4,10 | H27: 0 | M27: <color=#E64D00>a</color>听闻与<color=#E64D00>p</color>立场相近，特来相谈。 | N27: 210010 | O27: 60 | P27: 1600 | Q27: 30 | R27: 2 | S27: 2
A28: 26 | B28: JiaoQing<ZhiJiao>,love | C28: //,> | D28: 1,64 | E28: 100 | F28: 0 | G28: 4,10 | H28: 0 | M28: <color=#E64D00>a</color>从远处遥望见知交老友<color=#E64D00>p</color>，片刻间飞奔而至。 | N28: 210020 | O28: 60 | P28: 1600 | Q28: 31 | R28: 2 | S28: 2
A29: 27 | B29: love,age,kithKin<>,JiaoQing<ChouDi> | C29: >,>,!/,!/ | D29: 59,44,1,1 | E29: 100 | F29: 0 | G29: 4,10 | H29: 0 | M29: <color=#E64D00>a</color>听闻相交许久的后生晚辈<color=#E64D00>p</color>于此地走动，特来相谈。 | N29: 210030 | O29: 60 | P29: 1600 | Q29: 15 | R29: 2 | S29: 2
A30: 28 | B30: sex,JiaoQing<PeiOu>,JiaoQing<JuanLv>,love,lichang,lichang,28,45 | C30: !/,!/,!/,>,>,<,<,> | D30: sex,1,1,49,28,45,lichang,lichang | E30: 100 | F30: 0 | G30: 4,10 | H30: 0 | M30: <color=#E64D00>a</color>对<color=#E64D00>p</color>暗生情愫，心下暗许…… | N30: 210040 | O30: 60 | P30: 1600 | Q30: 10 | R30: 2 | S30: 2
A31: 29 | B31: sex,JiaoQing<PeiOu>,JiaoQing<JuanLv>,love,lichang,lichang,44,61 | C31: !/,!/,!/,>,>,<,<,> | D31: sex,1,1,49,44,61,lichang,lichang | E31: 100 | F31: 0 | G31: 4,10 | H31: 0 | M31: <color=#E64D00>a</color>对<color=#E64D00>p</color>暗生情愫，心下暗许…… | N31: 210040 | O31: 60 | P31: 1600 | Q31: 20 | R31: 2 | S31: 2
A32: 30 | B32: sex,JiaoQing<PeiOu>,JiaoQing<JuanLv>,love,lichang,lichang,60,77 | C32: !/,!/,!/,>,>,<,<,> | D32: sex,1,1,49,60,77,lichang,lichang | E32: 100 | F32: 0 | G32: 4,10 | H32: 0 | M32: <color=#E64D00>a</color>对<color=#E64D00>p</color>暗生情愫，心下暗许…… | N32: 210040 | O32: 60 | P32: 1600 | Q32: 20 | R32: 2 | S32: 2
A33: 31 | B33: sex,JiaoQing<PeiOu>,JiaoQing<JuanLv>,love,lichang,lichang,28,45 | C33: !/,!/,!/,>,>,<,<,> | D33: sex,1,1,69,28,45,lichang,lichang | E33: 100 | F33: 0 | G33: 4,10 | H33: 0 | M33: 与<color=#E64D00>p</color>互有好感多时的<color=#E64D00>a</color>决意向<color=#E64D00>p</color>表明心迹…… | N33: 210050 | O33: 60 | P33: 1600 | Q33: 40 | R33: 2 | S33: 2
A34: 32 | B34: sex,JiaoQing<PeiOu>,JiaoQing<JuanLv>,love,lichang,lichang,44,61 | C34: !/,!/,!/,>,>,<,<,> | D34: sex,1,1,69,44,61,lichang,lichang | E34: 100 | F34: 0 | G34: 4,10 | H34: 0 | M34: 与<color=#E64D00>p</color>互有好感多时的<color=#E64D00>a</color>决意向<color=#E64D00>p</color>表明心迹…… | N34: 210050 | O34: 60 | P34: 1600 | Q34: 41 | R34: 2 | S34: 2
