Workbook

Sheet Refresh
A1: 野怪ID | B1: 野怪称号 | C1: 野怪归属地 | D1: 野怪级别 | E1: 野怪图片 | F1: 野怪物种 | G1: 序号 | H1: 存在游戏模式中 | I1: 刷新坐标 | J1: 对话库Id | K1: 战斗组ID | L1: monster | M1: 刷新时间（秒） | N1: 自定义形象
A2: id | B2: name | C2: map | D2: lv | E2: icon | F2: species | G2: number | H2: gameMode | I2: pos | J2: talkId | K2: monsterTeamId | L2: monsterId | M2: time | N2: Style
A3: 1010101 | B3: 黑风流贼头目 | C3: 12000 | D3: 1 | F3: 0 | G3: 1 | H3: 0 | I3: 34,33;33,34 | J3: 1 | K3: 3001 | L3: 1010101 | M3: 450
A4: 1010102 | B4: 流落匪首 | C4: 12000 | D4: 1 | F4: 0 | G4: 2 | H4: 0 | I4: 17,33;18,32 | J4: 2 | K4: 3002 | L4: 1010102 | M4: 450
A5: 1020101 | B5: 流贼精锐 | C5: 12000 | D5: 2 | F5: 1 | G5: 1 | H5: 0 | I5: 36,14 | J5: 3 | K5: 3003 | L5: 1020101 | M5: 180
A6: 1020201 | B6: 噬人野狼 | C6: 12000 | D6: 2 | E6: 1110002012 | F6: 3 | G6: 1 | H6: 0 | I6: 9,27;12,27;8,26 | J6: 4 | K6: 3004 | L6: 1020201 | M6: 180
A7: 1030103 | B7: 避缉强盗 | C7: 12000 | D7: 3 | F7: 1 | G7: 3 | H7: 0 | I7: 32,13;31,12 | J7: 9 | K7: 3007 | L7: 1030103 | M7: 90
A8: 1030107 | B8: 村外流寇 | C8: 12000 | D8: 3 | F8: 1 | G8: 3 | H8: 0 | I8: 6,31;5,33 | J8: 10 | K8: 3008 | L8: 1030107 | M8: 90
A9: 1030108 | B9: 青萍地痞 | C9: 12000 | D9: 3 | F9: 0 | G9: 8 | H9: 0 | I9: 4,20 | J9: 14 | K9: 3011 | L9: 1030108 | M9: 90
A10: 1030109 | B10: 歧途恶棍 | C10: 12000 | D10: 3 | F10: 0 | G10: 9 | H10: 0 | I10: 24,28 | J10: 15 | K10: 3012 | L10: 1030109 | M10: 90
A11: 1030201 | B11: 伏训野狼 | C11: 12000 | D11: 3 | E11: 1110002012 | F11: 3 | G11: 1 | H11: 0 | I11: 25,25;25,26 | J11: 16 | K11: 3013 | L11: 1030201 | M11: 90
A12: 1200140 | B12: 强者挑战 | C12: 12000 | D12: 1 | F12: 1 | G12: 1 | H12: 0 | I12: 40,18 | J12: 17 | K12: 3014 | L12: 1200140 | M12: -1
A13: 1200141 | B13: 强者挑战 | C13: 12000 | D13: 1 | F13: 0 | G13: 1 | H13: 0 | I13: 38,10 | J13: 17 | K13: 3014 | L13: 1200141 | M13: -1
A14: 1200142 | B14: 强者挑战 | C14: 12000 | D14: 1 | F14: 0 | G14: 1 | H14: 0 | I14: 38,10 | J14: 17 | K14: 3014 | L14: 1200142 | M14: -1
A15: 1200143 | B15: 强者挑战 | C15: 12000 | D15: 1 | F15: 1 | G15: 1 | H15: 0 | I15: 38,10 | J15: 17 | K15: 3014 | L15: 1200143 | M15: -1
A16: 1200144 | B16: 强者挑战 | C16: 12000 | D16: 1 | F16: 0 | G16: 1 | H16: 0 | I16: 38,10 | J16: 17 | K16: 3014 | L16: 1200144 | M16: -1
A17: 1200145 | B17: 山贼头目 | C17: 13000 | D17: 1 | F17: 0 | G17: 1 | H17: 0 | I17: 54,54 | J17: 18 | K17: 3015 | L17: 1200145 | M17: 90 | O17: 承安镇
A18: 1200146 | B18: 山贼喽啰 | C18: 13000 | D18: 3 | F18: 1 | G18: 1 | H18: 0 | I18: 54,54 | J18: 18 | K18: 3015 | L18: 1200146 | M18: -1 | O18: 承安镇
A19: 1200147 | B19: 山贼喽啰 | C19: 13000 | D19: 3 | F19: 0 | G19: 1 | H19: 0 | I19: 54,54 | J19: 18 | K19: 3015 | L19: 1200147 | M19: -1 | O19: 承安镇
A20: 1200148 | B20: 山贼喽啰 | C20: 13000 | D20: 3 | F20: 1 | G20: 1 | H20: 0 | I20: 54,54 | J20: 18 | K20: 3015 | L20: 1200148 | M20: -1 | O20: 承安镇
A21: 1200149 | B21: 野地狼群 | C21: 13000 | D21: 1 | E21: 1110002012 | F21: 3 | G21: 1 | H21: 0 | I21: 57,52 | J21: 19 | K21: 3016 | L21: 1200149 | M21: 90 | O21: 承安镇
A22: 1200150 | B22: 郊狼 | C22: 13000 | D22: 2 | E22: 1110002012 | F22: 3 | G22: 1 | H22: 0 | I22: 57,52 | J22: 19 | K22: 3016 | L22: 1200150 | M22: -1 | O22: 承安镇
A23: 1200151 | B23: 郊狼 | C23: 13000 | D23: 2 | E23: 1110002012 | F23: 3 | G23: 1 | H23: 0 | I23: 57,52 | J23: 19 | K23: 3016 | L23: 1200151 | M23: -1 | O23: 承安镇
A24: 1200152 | B24: 流亡恶徒 | C24: 13000 | D24: 2 | F24: 1 | G24: 1 | H24: 0 | I24: 55,47 | J24: 20 | K24: 3017 | L24: 1200152 | M24: 90 | O24: 承安镇
A25: 1200153 | B25: 流亡恶徒 | C25: 13000 | D25: 3 | F25: 0 | G25: 1 | H25: 0 | I25: 55,47 | J25: 20 | K25: 3017 | L25: 1200153 | M25: -1 | O25: 承安镇
A26: 1200154 | B26: 流亡恶徒 | C26: 13000 | D26: 3 | F26: 0 | G26: 1 | H26: 0 | I26: 55,47 | J26: 20 | K26: 3017 | L26: 1200154 | M26: -1 | O26: 承安镇
A27: 1200155 | B27: 毒蛇 | C27: 13000 | D27: 2 | E27: 1170007011 | F27: 5 | G27: 1 | H27: 0 | I27: 56,41 | J27: 21 | K27: 3018 | L27: 1200155 | M27: 90 | O27: 承安镇
A28: 1200156 | B28: 毒蛇 | C28: 13000 | D28: 2 | E28: 1400001013 | F28: 5 | G28: 1 | H28: 0 | I28: 56,41 | J28: 21 | K28: 3018 | L28: 1200156 | M28: -1 | O28: 承安镇
A29: 1200157 | B29: 毒蛇 | C29: 13000 | D29: 2 | E29: 1400001013 | F29: 5 | G29: 1 | H29: 0 | I29: 56,41 | J29: 21 | K29: 3018 | L29: 1200157 | M29: -1 | O29: 承安镇
A30: 1200158 | B30: 毒蛇 | C30: 13000 | D30: 2 | E30: 1400001013 | F30: 5 | G30: 1 | H30: 0 | I30: 56,41 | J30: 21 | K30: 3018 | L30: 1200158 | M30: -1 | O30: 承安镇
A31: 1200159 | B31: 贼寇 | C31: 13000 | D31: 2 | F31: 0 | G31: 1 | H31: 0 | I31: 54,9 | J31: 22 | K31: 3019 | L31: 1200159 | M31: 90 | O31: 承安镇
A32: 1200160 | B32: 贼寇 | C32: 13000 | D32: 2 | F32: 0 | G32: 1 | H32: 0 | I32: 54,9 | J32: 22 | K32: 3019 | L32: 1200160 | M32: -1 | O32: 承安镇
A33: 1200161 | B33: 贼寇 | C33: 13000 | D33: 2 | F33: 1 | G33: 1 | H33: 0 | I33: 54,9 | J33: 22 | K33: 3019 | L33: 1200161 | M33: -1 | O33: 承安镇
A34: 1200162 | B34: 贼寇 | C34: 13000 | D34: 2 | F34: 1 | G34: 1 | H34: 0 | I34: 54,9 | J34: 22 | K34: 3019 | L34: 1200162 | M34: -1 | O34: 承安镇
A35: 1200163 | B35: 贼寇小头目 | C35: 13000 | D35: 1 | F35: 0 | G35: 1 | H35: 0 | I35: 55,6 | J35: 23 | K35: 3020 | L35: 1200163 | M35: 90 | O35: 承安镇
A36: 1200164 | B36: 贼寇 | C36: 13000 | D36: 3 | F36: 1 | G36: 1 | H36: 0 | I36: 55,6 | J36: 23 | K36: 3020 | L36: 1200164 | M36: -1 | O36: 承安镇
A37: 1200165 | B37: 贼寇 | C37: 13000 | D37: 3 | F37: 0 | G37: 1 | H37: 0 | I37: 55,6 | J37: 23 | K37: 3020 | L37: 1200165 | M37: -1 | O37: 承安镇
A38: 1200166 | B38: 贼寇头目 | C38: 13000 | D38: 1 | F38: 0 | G38: 1 | H38: 0 | I38: 46,3 | J38: 24 | K38: 3021 | L38: 1200166 | M38: 90 | O38: 承安镇
A39: 1200167 | B39: 贼寇 | C39: 13000 | D39: 3 | F39: 1 | G39: 1 | H39: 0 | I39: 46,3 | J39: 24 | K39: 3021 | L39: 1200167 | M39: -1 | O39: 承安镇
A40: 1200168 | B40: 贼寇 | C40: 13000 | D40: 3 | F40: 1 | G40: 1 | H40: 0 | I40: 46,3 | J40: 24 | K40: 3021 | L40: 1200168 | M40: -1 | O40: 承安镇
...

Sheet Refresh2
A1: 野怪ID | B1: 野怪称号 | C1: 野怪归属地 | D1: 野怪级别 | E1: 野怪图片 | F1: 野怪物种 | G1: 序号 | H1: 存在游戏模式中 | I1: 刷新坐标 | J1: 对话库Id | K1: 战斗组ID | L1: monster | M1: 刷新时间（秒） | N1: 自定义形象
A2: id | B2: name | C2: map | D2: lv | E2: icon | F2: species | G2: number | H2: gameMode | I2: pos | J2: talkId | K2: monsterTeamId | L2: monsterId | M2: time | N2: Style
A3: 1010101 | B3: Black Wind Bandit Leader | C3: 12000 | D3: 1 | F3: 0 | G3: 1 | H3: 0 | I3: 34,33;33,34 | J3: 1 | K3: 3001 | L3: 1010101 | M3: 450
A4: 1010102 | B4: Fallen Bandit Chief | C4: 12000 | D4: 1 | F4: 0 | G4: 2 | H4: 0 | I4: 17,33;18,32 | J4: 2 | K4: 3002 | L4: 1010102 | M4: 450
A5: 1020101 | B5: Elite Rogue Bandit | C5: 12000 | D5: 2 | F5: 1 | G5: 1 | H5: 0 | I5: 36,14 | J5: 3 | K5: 3003 | L5: 1020101 | M5: 180
A6: 1020201 | B6: Maneating Wild Wolf | C6: 12000 | D6: 2 | E6: 1110002012 | F6: 3 | G6: 1 | H6: 0 | I6: 9,27;12,27;8,26 | J6: 4 | K6: 3004 | L6: 1020201 | M6: 180
A7: 1030103 | B7: Escaped Bandit | C7: 12000 | D7: 3 | F7: 1 | G7: 3 | H7: 0 | I7: 32,13;31,12 | J7: 9 | K7: 3007 | L7: 1030103 | M7: 90
A8: 1030107 | B8: Village Outskirt Marauders | C8: 12000 | D8: 3 | F8: 1 | G8: 3 | H8: 0 | I8: 6,31;5,33 | J8: 10 | K8: 3008 | L8: 1030107 | M8: 90
A9: 1030108 | B9: Qingping Street Thug | C9: 12000 | D9: 3 | F9: 0 | G9: 8 | H9: 0 | I9: 4,20 | J9: 14 | K9: 3011 | L9: 1030108 | M9: 90
A10: 1030109 | B10: Villain of Evil Ways | C10: 12000 | D10: 3 | F10: 0 | G10: 9 | H10: 0 | I10: 24,28 | J10: 15 | K10: 3012 | L10: 1030109 | M10: 90
A11: 1030201 | B11: Trained Ambush Wolf | C11: 12000 | D11: 3 | E11: 1110002012 | F11: 3 | G11: 1 | H11: 0 | I11: 25,25;25,26 | J11: 16 | K11: 3013 | L11: 1030201 | M11: 90
A12: 1200140 | B12: Strongman Challenge | C12: 12000 | D12: 1 | F12: 1 | G12: 1 | H12: 0 | I12: 40,18 | J12: 17 | K12: 3014 | L12: 1200140 | M12: -1
A13: 1200141 | B13: Strongman Challenge | C13: 12000 | D13: 1 | F13: 0 | G13: 1 | H13: 0 | I13: 38,10 | J13: 17 | K13: 3014 | L13: 1200141 | M13: -1
A14: 1200142 | B14: Strongman Challenge | C14: 12000 | D14: 1 | F14: 0 | G14: 1 | H14: 0 | I14: 38,10 | J14: 17 | K14: 3014 | L14: 1200142 | M14: -1
A15: 1200143 | B15: Strongman Challenge | C15: 12000 | D15: 1 | F15: 1 | G15: 1 | H15: 0 | I15: 38,10 | J15: 17 | K15: 3014 | L15: 1200143 | M15: -1
A16: 1200144 | B16: Strongman Challenge | C16: 12000 | D16: 1 | F16: 0 | G16: 1 | H16: 0 | I16: 38,10 | J16: 17 | K16: 3014 | L16: 1200144 | M16: -1
A17: 1200145 | B17: Mountain Bandit Leader | C17: 13000 | D17: 1 | F17: 0 | G17: 1 | H17: 0 | I17: 54,54 | J17: 18 | K17: 3015 | L17: 1200145 | M17: 90 | O17: 承安镇
A18: 1200146 | B18: Mountain Bandit Underling | C18: 13000 | D18: 3 | F18: 1 | G18: 1 | H18: 0 | I18: 54,54 | J18: 18 | K18: 3015 | L18: 1200146 | M18: -1 | O18: 承安镇
A19: 1200147 | B19: Mountain Bandit Underling | C19: 13000 | D19: 3 | F19: 0 | G19: 1 | H19: 0 | I19: 54,54 | J19: 18 | K19: 3015 | L19: 1200147 | M19: -1 | O19: 承安镇
A20: 1200148 | B20: Mountain Bandit Underling | C20: 13000 | D20: 3 | F20: 1 | G20: 1 | H20: 0 | I20: 54,54 | J20: 18 | K20: 3015 | L20: 1200148 | M20: -1 | O20: 承安镇
A21: 1200149 | B21: Wilderness Wolf Pack | C21: 13000 | D21: 1 | E21: 1110002012 | F21: 3 | G21: 1 | H21: 0 | I21: 57,52 | J21: 19 | K21: 3016 | L21: 1200149 | M21: 90 | O21: 承安镇
A22: 1200150 | B22: Coyote | C22: 13000 | D22: 2 | E22: 1110002012 | F22: 3 | G22: 1 | H22: 0 | I22: 57,52 | J22: 19 | K22: 3016 | L22: 1200150 | M22: -1 | O22: 承安镇
A23: 1200151 | B23: Coyote | C23: 13000 | D23: 2 | E23: 1110002012 | F23: 3 | G23: 1 | H23: 0 | I23: 57,52 | J23: 19 | K23: 3016 | L23: 1200151 | M23: -1 | O23: 承安镇
A24: 1200152 | B24: Exiled Villain | C24: 13000 | D24: 2 | F24: 1 | G24: 1 | H24: 0 | I24: 55,47 | J24: 20 | K24: 3017 | L24: 1200152 | M24: 90 | O24: 承安镇
A25: 1200153 | B25: Exiled Villain | C25: 13000 | D25: 3 | F25: 0 | G25: 1 | H25: 0 | I25: 55,47 | J25: 20 | K25: 3017 | L25: 1200153 | M25: -1 | O25: 承安镇
A26: 1200154 | B26: Exiled Villain | C26: 13000 | D26: 3 | F26: 0 | G26: 1 | H26: 0 | I26: 55,47 | J26: 20 | K26: 3017 | L26: 1200154 | M26: -1 | O26: 承安镇
A27: 1200155 | B27: Poisonous Snake | C27: 13000 | D27: 2 | E27: 1170007011 | F27: 5 | G27: 1 | H27: 0 | I27: 56,41 | J27: 21 | K27: 3018 | L27: 1200155 | M27: 90 | O27: 承安镇
A28: 1200156 | B28: Poisonous Snake | C28: 13000 | D28: 2 | E28: 1400001013 | F28: 5 | G28: 1 | H28: 0 | I28: 56,41 | J28: 21 | K28: 3018 | L28: 1200156 | M28: -1 | O28: 承安镇
A29: 1200157 | B29: Poisonous Snake | C29: 13000 | D29: 2 | E29: 1400001013 | F29: 5 | G29: 1 | H29: 0 | I29: 56,41 | J29: 21 | K29: 3018 | L29: 1200157 | M29: -1 | O29: 承安镇
A30: 1200158 | B30: Poisonous Snake | C30: 13000 | D30: 2 | E30: 1400001013 | F30: 5 | G30: 1 | H30: 0 | I30: 56,41 | J30: 21 | K30: 3018 | L30: 1200158 | M30: -1 | O30: 承安镇
A31: 1200159 | B31: Bandit | C31: 13000 | D31: 2 | F31: 0 | G31: 1 | H31: 0 | I31: 54,9 | J31: 22 | K31: 3019 | L31: 1200159 | M31: 90 | O31: 承安镇
A32: 1200160 | B32: Bandit | C32: 13000 | D32: 2 | F32: 0 | G32: 1 | H32: 0 | I32: 54,9 | J32: 22 | K32: 3019 | L32: 1200160 | M32: -1 | O32: 承安镇
A33: 1200161 | B33: Bandit | C33: 13000 | D33: 2 | F33: 1 | G33: 1 | H33: 0 | I33: 54,9 | J33: 22 | K33: 3019 | L33: 1200161 | M33: -1 | O33: 承安镇
A34: 1200162 | B34: Bandit Minor Leader | C34: 13000 | D34: 2 | F34: 1 | G34: 1 | H34: 0 | I34: 54,9 | J34: 22 | K34: 3019 | L34: 1200162 | M34: -1 | O34: 承安镇
A35: 1200163 | B35: Bandit | C35: 13000 | D35: 1 | F35: 0 | G35: 1 | H35: 0 | I35: 55,6 | J35: 23 | K35: 3020 | L35: 1200163 | M35: 90 | O35: 承安镇
A36: 1200164 | B36: Bandit | C36: 13000 | D36: 3 | F36: 1 | G36: 1 | H36: 0 | I36: 55,6 | J36: 23 | K36: 3020 | L36: 1200164 | M36: -1 | O36: 承安镇
A37: 1200165 | B37: Bandit Leader | C37: 13000 | D37: 3 | F37: 0 | G37: 1 | H37: 0 | I37: 55,6 | J37: 23 | K37: 3020 | L37: 1200165 | M37: -1 | O37: 承安镇
A38: 1200166 | B38: Bandit | C38: 13000 | D38: 1 | F38: 0 | G38: 1 | H38: 0 | I38: 46,3 | J38: 24 | K38: 3021 | L38: 1200166 | M38: 90 | O38: 承安镇
A39: 1200167 | B39: Bandit | C39: 13000 | D39: 3 | F39: 1 | G39: 1 | H39: 0 | I39: 46,3 | J39: 24 | K39: 3021 | L39: 1200167 | M39: -1 | O39: 承安镇
A40: 1200168 | B40: Reclusive Expert | C40: 13000 | D40: 3 | F40: 1 | G40: 1 | H40: 0 | I40: 46,3 | J40: 24 | K40: 3021 | L40: 1200168 | M40: -1 | O40: 承安镇
...

Sheet RefreshTalk
A1: 对话库ID | B1: 对话内容
A2: id | B2: des
A3: 1 | B3: 流落至此，这般初出茅庐的江湖人都敢轻视我等……今日便让你有命难回！
A4: 2 | B4: ……莫怪我心狠，当真是生计艰难，此处僻静，待料理了你后，倒是个好埋骨处！
A5: 3 | B5: 头目有吩咐，过往之人，财命两夺！
A6: 4 | B6: 野狼嘴边涎水直溢，一双竖目狠狠的盯着你……
A7: 5 | B7: 人财皆掠，为我等重出江湖之资！死于此处，便怪你命数不好，时运不济罢！
A8: 6 | B8: 头目有吩咐，过往之人，财命两夺！
A9: 7 | B9: 这位过路人……可否把身上的银钱，借与在下呢？
A10: 8 | B10: 银财布帛，零碎细软，都拿出来！老子奔忙得紧，敢说半个不字，说不得要灭你的口！
A11: 9 | B11: 你……你可是认得我！既然你已见了我的面目，便留你不得！
A12: 10 | B12: 呦呵，还有人敢迈到这个地界……既是主动送上门来，后情如何，你当知晓！
A13: 11 | B13: 船贼船贼，失了船，还做什么贼……嗯？倒是有人主动上门，也好，宰了你，拿你些银钱盘缠，做个买卖去！
A14: 12 | B14: 我等在此处等待头目回来，想不到还能遇到送上门的肥羊，这等好事，岂能错过！
... A110: 108 | B110: 以血喂刀，杀……杀……

Sheet RefreshTalk2
A1: 对话库ID | B1: 对话内容
A2: id | B2: des
A3: 1 | B3: Stranded here, even greenhorns dare to look down on us... Today you won't leave alive!
A4: 2 | B4: ...Don't blame my cruelty, times are truly hard. This quiet spot will make a good burial ground after dealing with you!
A5: 3 | B5: The boss's orders - rob all passersby of both wealth and life!
A6: 4 | B6: The wild wolf drools greedily, its vertical pupils glaring fiercely at you...
A7: 5 | B7: We'll take both your possessions and life as capital for our return to the underworld! If you die here, blame your ill fate and bad luck!
A8: 6 | B8: The boss's orders - rob all passersby of both wealth and life!
A9: 7 | B9: Traveler... might you lend me the silver you carry?
A10: 8 | B10: Hand over all valuables - money, cloth, trinkets! I'm in a hurry. Say no and I'll silence you forever!
A11: 9 | B11: You... you recognize me! Since you've seen my face, I can't let you live!
A12: 10 | B12: Oh ho! Someone dares enter this territory... Since you came willingly, you know what comes next!
A13: 11 | B13: Boat thieves without boats... Hmm? A volunteer! Fine, I'll kill you and take your money to start a business!
A14: 12 | B14: Waiting here for our boss, we get this fat sheep delivered to us! Such luck can't be missed!
... A110: 108 | B110: Blood feeds the blade, kill... kill...

Sheet Sheet2
A1: 地痞头目 | B1: 瞧甚么？快滚！
A2: 城中恶霸 | B2: 这洛阳城中，可没有爷爷我不敢惹的人！
A3: 无赖头目 | B3: 城中商贩，敢有不交“平安钱”的，老子让他生意做不成！
A4: 白马恶僧 | B4: 还要数死人的闭口禅修得最好，纵使见了菩萨，想来也开不得口。
A5: 村中恶汉 | B5: 这村里谁敢不服，老子便让他去找阎王爷说理！
A6: 江洋大盗 | B6: 听闻洛阳城里多的是乐善好施之人，老子既过此地，便要让他们施舍个倾家荡产！
A7: 盗贼头目 | B7: 听闻西域人开高价收石窟佛头，也不知这些个破烂石头，究竟有甚独到之处。
A8: 盗墓贼 | B8: 此间之物，只需运出几件，那便是半生无忧了！
A9: 白马武僧 | B9: 若未向本寺买过诵经券，这诸天万佛，可不认你的香火！
A10: 东瀛密探 | B10: 这中原皇城当真是黄金遍地，哼，迟早有一日……
A11: 落魄杀手 | B11: 如今黑市闭市，我这一群兄弟，又该到何处讨份生计……
A12: 凶恶赌徒 | B12: 你！来借爷爷几两银子花花！
... A22: 精锐武士 | B22: 哼，三韩人都是软骨头，杀起来都嫌无趣。
A23: 狼群口角流涎，眼冒绿光，向你缓缓逼近。
A24: 关外悍匪 | B24: 老子当年在中原，干的可是诛九族的买卖……
A25: 狼群口角流涎，眼冒绿光，向你缓缓逼近。
A26: 失心刀奴 | B26: 杀……杀……
A27: 嗜血刀奴 | B27: 杀……杀人取血，以血喂刀！
A28: 入魔弟子 | B28: 以血喂刀，杀……杀……

Sheet Sheet1
A1: 1502862 | B1: 地痞头目 | C1: 1502862
A2: 1502863 | B2: 地痞 | C2: 1502863
A3: 1502864 | B3: 地痞 | C3: 1502864
A4: 1502865 | B4: 地痞 | C4: 1502865
A5: 1502866 | B5: 地痞 | C5: 1502866
A6: 1502867 | B6: 地痞 | C6: 1502867
A7: 1502868 | B7: 地痞 | C7: 1502868
A8: 1502869 | B8: 城中恶霸 | C8: 1502869
A9: 1502870 | B9: 地痞 | C9: 1502870
A10: 1502871 | B10: 地痞 | C10: 1502871
A11: 1502872 | B11: 地痞 | C11: 1502872
A12: 1502873 | B12: 地痞 | C12: 1502873
... A560: 1503795.4 | B560: 中年男子 | C560: 1503795.4
