Workbook

Sheet 武学配置
A1: 技能ID | B1: 武学名称 | C1: 武学级别 | D1: 武学类型 | E1: 出处 | F1: 对应武器 | G1: 造诣限制 | H1: 招式id | I1: 招式中文 | J1: 等级上限 | K1: 学习方法 | L1: 武学描述 | M1: icon
A2: id | B2: name | C2: level | D2: type | E2: sect | F2: weapon | G2: condition | H2: childIds | I2: #注释行 | J2: lvMax | K2: study | L2: des | M2: icon
A3: 101001 | B3: 太祖长拳 | C3: 入门武学 | D3: 武功 | E3: 行伍武学 | F3: 1 | G3: att,1,0 | H3: 10100101;10100102;10100201;10100202;10200101;10200102;10200201;10200202;10200203;10300101 | I3: 进步冲捶,心意圆融 | J3: 10 | K3: 秘籍学习 | L3: 江湖入门武学，又名三十二式长拳，谓之百拳之母。 | M3: skill/101001
A4: 101002 | B4: 猛獒拳 | C4: 入门武学 | D4: 武功 | E4: 市井武学 | F4: 拳脚 | G4: att,1,5 | H4: 10100201;10100202 | I4: 恶狗扑食,沾地滚 | J4: 10 | K4: 秘籍学习 | L4: 脱胎于犬类身形的拳法，颇为威猛，动作朴实刚健。 | M4: skill/101002
A5: 102001 | B5: 清风剑法 | C5: 入门武学 | D5: 武功 | E5: 江湖武学 | F5: 2 | G5: att,2,0 | H5: 10100101;10100102;10100201;10100202;10200101;10200102;10200201;10200202;10200203;10300101 | I5: 清风骤起,清风时归 | J5: 10 | K5: 秘籍学习 | L5: 江湖入门武学，轻灵潇洒，若清风快剑，迅疾无形。 | M5: skill/102001
A6: 102002 | B6: 钟灵剑法 | C6: 一般武学 | D6: 武功 | E6: 姑苏楚家 | F6: 2 | G6: att,2,20 | H6: 10100101;10100102;10100201;10100202;10200101;10200102;10200201;10200202;10200203;10300101 | I6: 灵犀一点,灵心慧性 | J6: 10 | K6: 秘籍学习 | L6: 钟灵毓秀，自造化始，剑势慧颖，自灵犀起。 | M6: skill/102002
A7: 102003 | B7: 寥落剑法 | C7: 上乘武学 | D7: 武功 | E7: 杜颜白 | F7: 剑 | G7: att,2,80 | H7: 10200301;10200302;10200303;10200304;10200305 | I7: 山河破,风飘絮,雨打萍,叹零丁,照汗青 | J7: 10 | K7: 秘籍学习 | L7: 寥落剑法为杜颜白自创，寥寥数招，若孤鸿低垂，最合心境。 | M7: skill/102003
A8: 103001 | B8: 乾坤刀法 | C8: 入门武学 | D8: 武功 | E8: 江湖武学 | F8: 3 | G8: att,3,0 | H8: 10100101;10100102;10100201;10100202;10200101;10200102;10200201;10200202;10200203;10300101 | I8: 开天辟地,改天换地 | J8: 10 | K8: 秘籍学习 | L8: 江湖入门武学，刀势雄浑，堂堂正正，不负乾坤之名。 | M8: skill/103001
A9: 103002 | B9: 开山刀法 | C9: 入门武学 | D9: 武功 | E9: 市井武学 | F9: 刀 | G9: att,3,5 | H9: 10300201;10300202 | I9: 力劈华山,开山劲 | J9: 10 | K9: 秘籍学习 | L9: 江湖入门武学，刀法大开大合，干净利落。 | M9: skill/103002
A10: 104001 | B10: 先锋棍法 | C10: 入门武学 | D10: 武功 | E10: 行伍武学 | F10: 4 | G10: att,4,0 | H10: 10100101;10100102;10100201;10100202;10200101;10200102;10200201;10200202;10200203;10300101 | I10: 敲山震虎,力拔山河 | J10: 10 | K10: 秘籍学习 | L10: 江湖入门武学，招式古拙，讲求以力破巧。 | M10: skill/104001
A11: 107001 | B11: 披麻锤法 | C11: 入门武学 | D11: 武功 | E11: 市井武学 | F11: 5 | G11: att,5,10 | H11: 10100101;10100102;10100201;10100202;10200101;10200102;10200201;10200202;10200203;10300101 | I11: 乱披风锤,锤风贯耳 | J11: 10 | K11: 秘籍学习 | L11: 山贼土匪们常习练的武学，出手时以蛮力乱击，简单易用。 | M11: skill/107001
A12: 109001 | B12: 勾栏鞭法 | C12: 入门武学 | D12: 武功 | E12: 市井武学 | F12: 奇门-软兵 | G12: att,5,0 | H12: 10900101;10900102 | I12: 横勾鞭,勾栏缠鞭 | J12: 10 | K12: 秘籍学习 | L12: 奴隶贩子习练的软兵武学，攻击方式较为单一，却效果颇佳。 | M12: skill/109001
A13: 111001 | B13: 撕咬 | C13: 入门武学 | D13: 武功 | E13: 无 | F13: 动物攻击 | G13: 0 | H13: 11100101 | I13: 撕咬 | J13: 10 | K13: 0 | L13: 0 | M13: skill/111001
A14: 200001 | B14: 吐纳法 | C14: 入门武学 | D14: 内功 | E14: 江湖武学 | F14: 7 | G14: att,7,0 | H14: 10100101;10100102;10100201;10100202;10200101;10200102;10200201;10200202;10200203;10300101 | I14: 吐故纳新,气随心转 | J14: 10 | K14: 主线剧情学习 | L14: 最适初习内功者，静感气脉之流转，吐纳之波息，实为夯实入门的不二法门。 | M14: skill/200001
A15: 200002 | B15: 浩然诀 | C15: 上乘武学 | D15: 内功 | E15: 振国卫 | F15: 0 | G15: att,7,80 | H15: 20000201;20000202;20000203;20000204;20000205 | I15: 仁慈恻隐,节义廉退,性静情逸,守真志满,川流不息 | J15: 10 | K15: 任务学习 | L15: 杜颜白所习武学，传闻是镇国公所亲授，内息澎湃悠远，以身证儒生意气。——浩然之气，可吞日月，正道沛然，凌御天地。 | M15: skill/200002
A16: 106006 | B16: 飞蝗石 | C16: 一般武学 | D16: 武功 | E16: 江湖武学 | F16: 奇门-暗器 | G16: att,5,15 | H16: 10600601;10600602;10600603 | I16: 弹飞蝗，振翅拈指，点绷簧 | J16: 10 | K16: 秘籍学习 | L16: 弹指惊鸿，难避飞蝗，以特殊手法出手的暗器武学，颇为难缠。 | M16: skill/106006
A17: 300001 | B17: 轻身法 | C17: 入门武学 | D17: 轻功 | E17: 江湖武学 | F17: 8 | G17: att,8,0 | H17: 10100101;10100102;10100201;10100202;10200101;10200102;10200201;10200202;10200203;10300101 | I17: 纵身翻,轻身纵 | J17: 10 | K17: 秘籍学习 | L17: 江湖中人常习练的轻身法，据传练至极致，身轻似羽毛，落影无痕。 | M17: skill/300001
A18: 101003 | B18: 铁砂掌 | C18: 一般武学 | D18: 武功 | E18: 黑市王家 | F18: 拳脚 | G18: att,1,20 | H18: 10100301;10100302;10100303 | I18: 铁掌双分,破砂石掌,药浸柔掌 | J18: 10 | K18: 秘籍学习 | L18: 寒砂冷铁，方可铸造双掌坚若铁石，此功法据说流传自京城黑市。 | M18: skill/101003
A19: 105001 | B19: 九曲枪法 | C19: 一般武学 | D19: 武功 | E19: 市井武学 | F19: 长兵 | G19: att,4,15 | H19: 10500101;10500102;10500103 | I19: 枪回九曲,蜿蜒九变，九曲云龙现 | J19: 10 | K19: 秘籍学习 | L19: 长枪九曲，崩，抱，横，实为战阵凌然之艺。 | M19: skill/105001
A20: 101004 | B20: 罗帐轻烟掌 | C20: 一般武学 | D20: 武功 | E20: 江湖武学 | F20: 拳脚 | G20: att,1,24 | H20: 10100401;10100402;10100403 | I20: 罗帐轻烟,轻罗回风, | J20: 10 | K20: 秘籍学习 | L20: 功法掌风劲力并非向前，而是向后，除非熄烛登榻，恐再无用处。 | M20: skill/101004
A21: 300002 | B21: 如燕功 | C21: 一般武学 | D21: 轻功 | E21: 江湖武学 | F21: 轻功 | G21: att,8,10 | H21: 30000201;30000202;30000203 | I21: 身轻如燕,燕子冲霄,春燕南归 | J21: 10 | K21: 秘籍学习 | L21: 身轻如燕，自轻灵起，自足下生风，如明如燕。 | M21: skill/300002
A22: 201003 | B22: 运纳功 | C22: 一般武学 | D22: 内功 | E22: 江湖武学 | F22: 内功 | G22: att,7,15 | H22: 20100301;20100302;20100303 | I22: 运气纳体,周天流转,不缚外物 | J22: 10 | K22: 秘籍学习 | L22: 气机流转，纳体周天，何运何从，百川纳归。 | M22: skill/201003
A23: 201004 | B23: 铁骨横练功 | C23: 一般武学 | D23: 内功 | E23: 市井武学 | F23: 内功 | G23: att,7,24 | H23: 20100401;20100302;20100303 | I23: 横铁练体,横式文练，横练武架 | J23: 10 | K23: 秘籍学习 | L23: 内蕴真气，铁骨横练，山川风雨岿不动，我自真气足。 | M23: skill/201004
A24: 104002 | B24: 横江棍法 | C24: 一般武学 | D24: 武功 | E24: 江湖武学 | F24: 长兵 | G24: att,4,20 | H24: 10400201;10400202;10400203 | I24: 铁索横江,拦江铁意,如封似闭 | J24: 10 | K24: 秘籍学习 | L24: 施展时，若铁锁横江，守势顽劲，力道雄浑。 | M24: skill/104002
A25: 102004 | B25: 玉洁剑法 | C25: 一般武学 | D25: 武功 | E25: 江湖武学 | F25: 剑 | G25: att,2,15 | H25: 10200401;10200402;10200403 | I25: 长剑冰清,玉洁宁心,璞玉韬光 | J25: 10 | K25: 秘籍学习 | L25: 剑招清雅灵动，以巧取胜，多为江湖女子所习。 | M25: skill/102004
A26: 103003 | B26: 黑市快刀 | C26: 一般武学 | D26: 武功 | E26: 黑市王家 | F26: 刀 | G26: att,3,15 | H26: 10300301;10300302;10300303 | I26: 黑市快刀,短斤两,公秤分 | J26: 10 | K26: 秘籍学习 | L26: 传自京城黑市王家的刀法，其刀出手之速惊人。 | M26: skill/103003
A27: 111002 | B27: 毒牙 | C27: 一般武学 | D27: 武功 | E27: 无 | F27: 动物攻击 | G27: 0 | H27: 11100201 | I27: 毒牙 | J27: 10 | K27: 0 | L27: 0 | M27: skill/111002
A28: 104003 | B28: 落生莲花棍 | C28: 进阶武学 | D28: 武功 | E28: 丐帮武学 | F28: 长兵 | G28: att,4,40 | H28: 10400301;10400302;10400303 | I28: 莲花落,莲不息,无穷碧，叶连天 | J28: 10 | K28: 秘籍学习 | L28: 丐帮所传棍法，取自莲花落水成根，生生不息之意。 | M28: skill/104003
A29: 108001 | B29: 云隙扇法 | C29: 一般武学 | D29: 武功 | E29: 江湖武学 | F29: 6 | G29: att,5,20 | H29: 10100101;10100102;10100201;10100202;10200101;10200102;10200201;10200202;10200203;10300101 | I29: 长袖出云,藏云隐芒,云裂石惊 | J29: 10 | K29: 秘籍学习 | L29: 或穿云间，或纵过隙，若灵蛇探洞，似骄阳裂云，出手诡谲。 | M29: skill/108001
A30: 101005 | B30: 太和绵掌 | C30: 一般武学 | D30: 武功 | E30: 真武 | F30: 拳脚 | G30: att,1,25 | H30: 10100501;10100502;10100503 | I30: 野马分鬃,雀不飞,生太极 | J30: 10 | K30: 秘籍学习 | L30: 太和绵掌擅四两拨千斤，其势不拘于身，不困于形，自谓弱可胜强，柔中寓刚。 | M30: skill/101005
A31: 102005 | B31: 两仪剑法 | C31: 一般武学 | D31: 武功 | E31: 真武 | F31: 剑 | G31: att,2,25 | H31: 10200501;10200502;10200503 | I31: 剑分阴阳,剑割昏晓,生太极 | J31: 10 | K31: 秘籍学习 | L31: 剑分阴阳，是以奇正相应，两仪相生，其寓清于浊，寓拙于巧，千般变化，不过两仪之分也。 | M31: skill/102005
A32: 204001 | B32: 抱元守一 | C32: 一般武学 | D32: 内功 | E32: 真武 | F32: 内功 | G32: att,7,25 | H32: 20400101;20400102;20400103 | I32: 守心归一,自然之辩,太和清气 | J32: 10 | K32: 秘籍学习 | L32: 唯神是守，与神为一，至身心相融，气神不动，方为守一。 | M32: skill/204001
A33: 300003 | B33: 梯云纵 | C33: 一般武学 | D33: 轻功 | E33: 真武 | F33: 轻功 | G33: att,8,25 | H33: 30000301;30000302;30000303 | I33: 纵青云,踏云烟,唤云气 | J33: 10 | K33: 秘籍学习 | L33: 真武轻身功法，施展时，直上不坠，如梯云而览胜，履气而升空，凌然仙姿也。 | M33: skill/300003
A34: 101902 | B34: 猛獒拳（敌） | C34: 入门武学 | D34: 武功 | E34: 市井武学 | F34: 拳脚 | G34: att,1,5 | H34: 10190201;10190202 | I34: 恶狗扑食,沾地滚 | J34: 10 | K34: 秘籍学习 | L34: 脱胎于犬类身形的拳法，颇为威猛，动作朴实刚健。 | M34: skill/101002
A35: 103902 | B35: 开山刀法（敌） | C35: 入门武学 | D35: 武功 | E35: 市井武学 | F35: 刀 | G35: att,3,5 | H35: 10390201;10390202 | I35: 力劈华山,开山劲 | J35: 10 | K35: 秘籍学习 | L35: 江湖入门武学，刀法大开大合，干净利落。 | M35: skill/103002
A36: 107901 | B36: 披麻锤法（敌） | C36: 入门武学 | D36: 武功 | E36: 市井武学 | F36: 奇门-钝器 | G36: att,5,10 | H36: 10790101;10790102 | I36: 乱披风锤,锤风贯耳 | J36: 10 | K36: 秘籍学习 | L36: 山贼土匪们常习练的武学，出手时以蛮力乱击，简单易用。 | M36: skill/107001
A37: 109901 | B37: 勾栏鞭法（敌） | C37: 入门武学 | D37: 武功 | E37: 市井武学 | F37: 奇门-软兵 | G37: att,5,0 | H37: 10990101;10990102 | I37: 横勾鞭,勾栏缠鞭 | J37: 10 | K37: 秘籍学习 | L37: 奴隶贩子习练的软兵武学，攻击方式较为单一，却效果颇佳。 | M37: skill/109001
A38: 101903 | B38: 铁砂掌（敌） | C38: 一般武学 | D38: 武功 | E38: 黑市王家 | F38: 拳脚 | G38: att,1,20 | H38: 10190301;10190302;10190303 | I38: 铁掌双分,破砂石掌,药浸柔掌 | J38: 10 | K38: 秘籍学习 | L38: 寒砂冷铁，方可铸造双掌坚若铁石，此功法据说流传自京城黑市。 | M38: skill/101003
A39: 105901 | B39: 九曲枪法（敌） | C39: 一般武学 | D39: 武功 | E39: 市井武学 | F39: 长兵 | G39: att,4,15 | H39: 10590101;10590102;10590103 | I39: 枪回九曲,蜿蜒九变，九曲云龙现 | J39: 10 | K39: 秘籍学习 | L39: 长枪九曲，崩，抱，横，实为战阵凌然之艺。 | M39: skill/105001
A40: 101904 | B40: 罗帐轻烟掌（敌） | C40: 一般武学 | D40: 武功 | E40: 江湖武学 | F40: 拳脚 | G40: att,1,24 | H40: 10190401;10190402;10190403 | I40: 罗帐轻烟,轻罗回风, | J40: 10 | K40: 秘籍学习 | L40: 功法掌风劲力并非向前，而是向后，除非熄烛登榻，恐再无用处。 | M40: skill/101004
...

Sheet 武学等级配置
A1: 技能等级ID | B1: 关联技能 | C1: 对应等级 | D1: 对应显示 | E1: 升级所需阅历 | F1: 升级后冷却时间 | G1: 效果 | H1: 开放招式 | I1: 造诣加点 | J1: 备注
A2: id | B2: parentId | C2: level | D2: show | E2: lvUpNeed | F2: cooldown | G2: effect | H2: open | I2: addPoint
A3: 10100101 | B3: 101001 | C3: 1 | D3: 一重/十重 | E3: 0 | F3: *0:00:00 | G3: act,10;block,2 | H3: 10100101 | I3: att,1,1 | J3: 太祖长拳
A4: 10100102 | B4: 101001 | C4: 2 | D4: 二重/十重 | E4: 20 | F4: *0:02:00 | G4: act,15;block,4 | H4: 0 | I4: att,1,1 | J4: 太祖长拳
A5: 10100103 | B5: 101001 | C5: 3 | D5: 三重/十重 | E5: 30 | F5: *0:03:00 | G5: act,20;block,6 | H5: 0 | I5: att,1,1 | J5: 太祖长拳
A6: 10100104 | B6: 101001 | C6: 4 | D6: 四重/十重 | E6: 50 | F6: *0:05:00 | G6: act,25;block,9 | H6: 0 | I6: att,1,2 | J6: 太祖长拳
A7: 10100105 | B7: 101001 | C7: 5 | D7: 五重/十重 | E7: 80 | F7: *0:08:00 | G7: act,30;block,12 | H7: 10100102 | I7: att,1,2 | J7: 太祖长拳
A8: 10100106 | B8: 101001 | C8: 6 | D8: 六重/十重 | E8: 130 | F8: *0:13:00 | G8: act,40;block,15 | H8: 0 | I8: att,1,2 | J8: 太祖长拳
A9: 10100107 | B9: 101001 | C9: 7 | D9: 七重/十重 | E9: 210 | F9: *0:21:00 | G9: act,50;block,18 | H9: 0 | I9: att,1,3 | J9: 太祖长拳
A10: 10100108 | B10: 101001 | C10: 8 | D10: 八重/十重 | E10: 340 | F10: *0:34:00 | G10: act,60;block,22 | H10: 0 | I10: att,1,3 | J10: 太祖长拳
A11: 10100109 | B11: 101001 | C11: 9 | D11: 九重/十重 | E11: 550 | F11: *0:55:00 | G11: act,80;block,26 | H11: 0 | I11: att,1,4 | J11: 太祖长拳
A12: 10100110 | B12: 101001 | C12: 10 | D12: 大圆满 | E12: 890 | F12: *1:29:00 | G12: act,100;block,30 | H12: 0 | I12: att,1,5 | J12: 太祖长拳
A13: 10100201 | B13: 101002 | C13: 1 | D13: 一重/十重 | E13: 0 | F13: *0:00:00 | G13: act,8;block,0 | H13: 10100201 | I13: att,1,2 | J13: 猛獒拳
A14: 10100202 | B14: 101002 | C14: 2 | D14: 二重/十重 | E14: 20 | F14: *0:02:00 | G14: act,13;block,1 | H14: 0 | I14: att,1,2 | J14: 猛獒拳
... A102: 10900110 | B102: 109001 | C102: 10 | D102: 大圆满 | E102: 890 | F102: *1:29:00 | G102: act,84;block,30 | H102: 0 | I102: att,5,5 | J102: 勾栏鞭法
A103: 11100101 | B103: 111001 | C103: 1 | D103: 一重/十重 | E103: 0 | F103: 0 | G103: act,10 | H103: 11100101 | I103: 0 | J103: 撕咬
A104: 11100102 | B104: 111001 | C104: 2 | D104: 二重/十重 | E104: 0 | F104: 0 | G104: act,14 | H104: 0 | I104: 0 | J104: 撕咬
A105: 11100103 | B105: 111001 | C105: 3 | D105: 三重/十重 | E105: 0 | F105: 0 | G105: act,16 | H105: 0 | I105: 0 | J105: 撕咬
A106: 11100104 | B106: 111001 | C106: 4 | D106: 四重/十重 | E106: 0 | F106: 0 | G106: act,21 | H106: 0 | I106: 0 | J106: 撕咬
A107: 11100105 | B107: 111001 | C107: 5 | D107: 五重/十重 | E107: 0 | F107: 0 | G107: act,27 | H107: 0 | I107: 0 | J107: 撕咬
A108: 11100106 | B108: 111001 | C108: 6 | D108: 六重/十重 | E108: 0 | F108: 0 | G108: act,33 | H108: 0 | I108: 0 | J108: 撕咬
A109: 11100107 | B109: 111001 | C109: 7 | D109: 七重/十重 | E109: 0 | F109: 0 | G109: act,45 | H109: 0 | I109: 0 | J109: 撕咬
A110: 11100108 | B110: 111001 | C110: 8 | D110: 八重/十重 | E110: 0 | F110: 0 | G110: act,56 | H110: 0 | I110: 0 | J110: 撕咬
A111: 11100109 | B111: 111001 | C111: 9 | D111: 九重/十重 | E111: 0 | F111: 0 | G111: act,72 | H111: 0 | I111: 0 | J111: 撕咬
A112: 11100110 | B112: 111001 | C112: 10 | D112: 大圆满 | E112: 0 | F112: 0 | G112: act,89 | H112: 0 | I112: 0 | J112: 撕咬
A113: 20000101 | B113: 200001 | C113: 1 | D113: 一重/十重 | E113: 0 | F113: *0:00:00 | G113: hp_max,12;mp_max,8 | H113: 20000101 | I113: att,7,2 | J113: 吐纳法
A114: 20000102 | B114: 200001 | C114: 2 | D114: 二重/十重 | E114: 20 | F114: *0:02:00 | G114: hp_max,20;mp_max,12 | H114: 0 | I114: att,7,2 | J114: 吐纳法
A115: 20000103 | B115: 200001 | C115: 3 | D115: 三重/十重 | E115: 30 | F115: *0:03:00 | G115: hp_max,28;mp_max,16 | H115: 0 | I115: att,7,2 | J115: 吐纳法
A116: 20000104 | B116: 200001 | C116: 4 | D116: 四重/十重 | E116: 50 | F116: *0:05:00 | G116: hp_max,38;mp_max,20 | H116: 0 | I116: att,7,2 | J116: 吐纳法
A117: 20000105 | B117: 200001 | C117: 5 | D117: 五重/十重 | E117: 80 | F117: *0:08:00 | G117: hp_max,50;mp_max,26 | H117: 0 | I117: att,7,3 | J117: 吐纳法
A118: 20000106 | B118: 200001 | C118: 6 | D118: 六重/十重 | E118: 130 | F118: *0:13:00 | G118: hp_max,64;mp_max,32 | H118: 20000102 | I118: att,7,3 | J118: 吐纳法
A119: 20000107 | B119: 200001 | C119: 7 | D119: 七重/十重 | E119: 210 | F119: *0:21:00 | G119: hp_max,78;mp_max,42 | H119: 0 | I119: att,7,3 | J119: 吐纳法
A120: 20000108 | B120: 200001 | C120: 8 | D120: 八重/十重 | E120: 340 | F120: *0:34:00 | G120: hp_max,90;mp_max,52 | H120: 0 | I120: att,7,4 | J120: 吐纳法
A121: 20000109 | B121: 200001 | C121: 9 | D121: 九重/十重 | E121: 550 | F121: *0:55:00 | G121: hp_max,110;mp_max,62 | H121: 0 | I121: att,7,4 | J121: 吐纳法
A122: 20000110 | B122: 200001 | C122: 10 | D122: 大圆满 | E122: 890 | F122: *1:29:00 | G122: hp_max,142;mp_max,74 | H122: 0 | I122: att,7,5 | J122: 吐纳法
A123: 20000201 | B123: 200002 | C123: 1 | D123: 一重/十重 | E123: 0 | F123: *0:00:00 | G123: hp_max,980;mp_max,430 | H123: 0 | I123: att,7,15 | J123: 浩然诀
A124: 20000202 | B124: 200002 | C124: 2 | D124: 二重/十重 | E124: 500 | F124: *0:20:00 | G124: hp_max,1200;mp_max,520 | H124: 0 | I124: att,7,15 | J124: 浩然诀
... A242: 10300310 | B242: 103003 | C242: 10 | D242: 大圆满 | E242: 1500 | F242: *4:05:00 | G242: act,168;block,81 | H242: 0 | I242: att,3,8 | J242: 黑市快刀
A243: 11100201 | B243: 111002 | C243: 1 | D243: 一重/十重 | E243: 0 | F243: 0 | G243: act,21 | H243: 11100201 | I243: 0 | J243: 毒牙
A244: 11100202 | B244: 111002 | C244: 2 | D244: 二重/十重 | E244: 0 | F244: 0 | G244: act,32 | H244: 0 | I244: 0 | J244: 毒牙
...

Sheet 招式配置
A1: 招式ID | B1: 招式名 | C1: 招式类型 | D1: 對應武學 | E1: 境界要求 | F1: 效果 | G1: 消耗 | H1: 冷却 | I1: 連擊 | J1: 追擊 | K1: tips | L1: line | M1: text | N1: textParams | O1: icon | P1: image | Q1: jineng
A2: id | B2: name | C2: type | D2: parentId | E2: attribute | F2: effect | G2: cost | H2: cooldown | K2: tips | L2: line | M2: text | N2: textParams | O2: icon | P2: image | Q2: jineng
A3: 10100101 | B3: 进步冲捶 | C3: 主动 | D3: 101001 | E3: 1 | F3: hurt|force*1.5; | G3: mp,12 | H3: F,2；B,4 | I3: 0 | J3: 0 | K3: 0 | L3: 0 | M3: 进步冲捶：垫步前冲，汇全身力量于一点，造成{0}点伤害。【武力加成】 | N3: force*1.5 | O3: tricks/10100101 | Q3: Quan/10100101,32,19
A4: 10100102 | B4: 心意圆融 | C4: 被动 | D4: 101001 | E4: 2 | F4: backCD|-2; | G4: 0 | H4: 0 | I4: 0 | J4: 0 | K4: 太祖长拳五重开启 | L4: 0 | M4: 心意圆融：拳行圆融，其势愈胜，减少1回合进步冲锤的调息时间。 | O4: tricks/10100102
A5: 10100201 | B5: 恶狗扑食 | C5: 主动 | D5: 101002 | E5: 3 | F5: hurt|force+8; | G5: mp,15 | H5: F,2；B,4 | I5: 0 | J5: 0 | K5: 0 | L5: 0 | M5: 恶狗扑食：向前飞扑，双臂合拢宛若猛獒撕咬，造成{0}点伤害。【武力加成】 | N5: force+8 | O5: tricks/10100201 | Q5: Quan/10100201,18,8
A6: 10100202 | B6: 沾地滚 | C6: 被动 | D6: 101002 | E6: 4 | F6: evade|agile*2 | G6: 0 | H6: 0 | I6: 0 | J6: 0 | K6: 猛獒拳六重开启 | L6: 0 | M6: 沾地滚：模仿犬类身形，间不容发之际伏地闪避，提升{0}闪避值。【身法加成】 | N6: agile*2 | O6: tricks/10100202
A7: 10200101 | B7: 清风骤起 | C7: 主动 | D7: 102001 | E7: 5 | F7: hurt|force*1.2; | G7: mp,10 | H7: F,3；B,3 | I7: 0 | J7: 0 | K7: 0 | L7: 0 | M7: 清风骤起：清风乍起，破萍纵月，造成{0}点伤害。【武力加成】 | N7: force*1.2 | O7: tricks/10200101 | Q7: Jian/10200101,22,13
A8: 10200102 | B8: 清风时归 | C8: 被动 | D8: 102001 | E8: 6 | F8: onHurt|clearCD|1|(agile*0.2)/100; | G8: 0 | H8: 0 | I8: 0 | J8: 0 | K8: 清风剑法六重开启 | L8: 0 | M8: 清风时扫：千里人未还，清风有时归，每次对敌方目标造成伤害时，{0}%概率清除清风骤起整备回合。【身法加成】 | N8: agile*0.2 | O8: tricks/10200102
A9: 10200201 | B9: 灵犀一点 | C9: 主动 | D9: 102002 | E9: 7 | F9: hurt|internal*1.7; | G9: mp,12 | H9: F,0；B,5 | I9: 0 | J9: 0 | K9: 0 | L9: 0 | M9: 灵犀一点：剑似灵犀，稍纵即逝，造成{0}点伤害。【内息加成】 | N9: internal*1.7 | O9: tricks/10200201 | Q9: Jian/10200201,30,19
A10: 10200202 | B10: 灵心慧性 | C10: 被动 | D10: 102002 | E10: 8 | F10: act|internal*2; | G10: 0 | H10: 0 | I10: 0 | J10: 0 | K10: 钟灵剑法六重开启 | L10: 0 | M10: 灵心慧性：如灵如明，如慧如性，若灵犀一点处在调息状态中则增{0}点攻击力。【内息加成】 | N10: internal*2 | O10: tricks/10200202
A11: 10200203 | B11: 器钟灵鸣 | C11: 被动 | D11: 102002 | E11: 9 | F11: OnAfterBeGeDang,AddBuff,201,1 | G11: 0 | H11: 0 | I11: 0 | J11: 0 | K11: 钟灵剑法九重开启 | M11: 器钟灵鸣：器在匣中，不平而鸣，攻击被格挡下次攻击时提升30%攻击力。 | O11: tricks/10200203
A12: 10300101 | B12: 开天辟地 | C12: 主动 | D12: 103001 | E12: 10 | F12: hurt|force*1.4; | G12: mp,18 | H12: F,1；B,4 | I12: 0 | J12: 0 | K12: 0 | L12: 0 | M12: 开天辟地：自上而下的纵斩，似有开天辟地之力，造成{0}点伤害。【武力加成】 | N12: force*1.4 | O12: tricks/10300101 | Q12: Dao/10300101,20,10
A13: 10300102 | B13: 改天换地 | C13: 被动 | D13: 103001 | E13: 1 | F13: onHurt|atkAgainRate|(agile*0.25)/100; | G13: 0 | H13: 0 | I13: 0 | J13: 0 | K13: 乾坤刀法五重开启 | L13: 0 | M13: 改天换地：一刀一刹那，片刻一天地，攻击时{0}%概率触发连击攻击。【身法加成】 | N13: agile*0.25 | O13: tricks/10300102
A14: 10300201 | B14: 力劈华山 | C14: 主动 | D14: 103002 | E14: 1 | F14: hurt|force*1.6 | G14: mp,5 | H14: F,2；B,6 | I14: 0 | J14: 0 | K14: 0 | L14: 0 | M14: 力劈华山：自上而下的纵向斩击，力求至极破山之意，造成{0}点伤害。【武力加成】 | N14: force*1.6 | O14: tricks/10300201 | Q14: Dao/10300201,20,11
A15: 10300202 | B15: 开山劲 | C15: 被动 | D15: 103002 | E15: 1 | F15: def|soma*2 | G15: 0 | H15: 0 | I15: 0 | J15: 0 | K15: 开山刀法七重开启 | L15: 0 | M15: 开山劲：刀行厚重，如破山峦，提升{0}点防御。【筋骨加成】 | N15: soma*2 | O15: tricks/10300202
A16: 10400101 | B16: 敲山震虎 | C16: 主动 | D16: 104001 | E16: 1 | F16: hurt|force*1.3 | G16: mp,16 | H16: F,5；B,4 | I16: 0 | J16: 0 | K16: 0 | L16: 0 | M16: 敲山震虎：长棍贯出，若千军横扫，造成{0}点伤害。【武力加成】 | N16: force*1.3 | O16: tricks/10400101 | Q16: Changbing/10400101,20,11
A17: 10400102 | B17: 力拔山河 | C17: 被动 | D17: 104001 | E17: 1 | F17: onSkill|10400101|hurtNear|force; | G17: 0 | H17: 0 | I17: 0 | J17: 0 | K17: 先锋棍法七重开启 | L17: 0 | M17: 力拔山河：力拔山兮气盖世，施展横扫千军时给攻击目标临近的敌人造成武力伤害。【武力加成】 | O17: tricks/10400102
A18: 10700101 | B18: 乱披风锤 | C18: 主动 | D18: 107001 | E18: 1 | F18: hurt|force*0.7; | G18: mp,18 | H18: F,6；B,8 | I18: 0 | J18: 0 | K18: 0 | L18: 0 | M18: 乱披风锤：面朝对方胡乱地挥舞出四记挥砍，每记挥砍造成{0}点伤害。 【武力加成】 | N18: force*0.7 | O18: tricks/10700101 | Q18: Qimen_dunqi/10700101,58,13,25,45
A19: 10700102 | B19: 锤风贯耳 | C19: 被动 | D19: 107001 | E19: 1 | F19: onSkill|10700101|AddHurt|iif(soma>targetsoma,(soma-targetsoma)*0.5,0); | G19: 0 | H19: 0 | I19: 0 | J19: 0 | K19: 披麻锤法五重开启 | L19: 0 | M19: 锤风贯耳：当你的筋骨高于目标时，锤风之势如黑云压城，提升乱披风锤的伤害（与目标筋骨差*0.5）。【筋骨加成】 | O19: tricks/10700102 | Q19: Qimen_dunqi/10700102,58,13,25,45
A20: 10900101 | B20: 横勾鞭 | C20: 主动 | D20: 109001 | E20: 1 | F20: onSkill|10900101|hurtRow|internal*3; | G20: mp,6 | H20: F,1；B,3 | I20: 0 | J20: 0 | K20: 0 | L20: 0 | M20: 横勾鞭：自左至右横卷向目标，造成{0}点伤害。 【内息加成】 | N20: internal*3 | O20: tricks/10900101 | Q20: Qimen_ruanbing/10900101,22,15
A21: 10900102 | B21: 勾栏缠鞭 | C21: 被动 | D21: 109001 | E21: 1 | F21: onHurt|AddTargetBackCD|1|(agile*2)/100 | G21: 0 | H21: 0 | I21: 0 | J21: 0 | K21: 勾栏鞭法五重开启 | L21: 0 | M21: 勾栏缠鞭：勾栏纠缠，绕指索命，攻击时有{0}%概率增加目标当前武功调息1回合。【身法加成】 | N21: agile*2 | O21: tricks/10900102
A22: 11100101 | B22: 撕咬 | C22: 主动 | D22: 111001 | E22: 1 | F22: hurt|force*3;onHurt|rate|0.15|AddBuff|1001|1 | G22: mp,7 | H22: F,2；B,2 | I22: 0 | J22: 0 | K22: 0 | L22: 0 | M22: 野兽的基本厮杀能力，造成{0}点伤害，有15%概率造成流血。 | N22: force*3 | O22: tricks/11100101 | Q22: 11100101,20,10
A23: 20000101 | B23: 吐故纳新 | C23: 被动 | D23: 200001 | E23: 1 | F23: act|internal;def|internal | G23: 0 | H23: 0 | I23: 0 | J23: 0 | K23: 0 | L23: 0 | M23: 吐故纳新：气机吐纳之间，隐有风雷艮震，提升内息点攻击，内息点防御【内息加成】 | O23: tricks/20000101
A24: 20000102 | B24: 气随心转 | C24: 被动 | D24: 200001 | E24: 1 | F24: onHurt|AddMP|mp*0.02 | G24: 0 | H24: 0 | I24: 0 | J24: 0 | K24: 吐纳法六重开启 | L24: 0 | M24: 气随心转：心意流转，气息反复，攻击后回复2%内力值。 | O24: tricks/20000102
A25: 10400201 | B25: 铁锁横江 | C25: 主动 | D25: 104002 | E25: 1 | F25: hurt|force*1.8; | G25: mp,20 | H25: F,4；B,4 | I25: 0 | J25: 0 | K25: 0 | L25: 0 | M25: 铁锁横江：铁索拦江，拦横遍野，长棍横扫造成{0}点伤害。【武力加成】 | N25: force*1.8 | O25: tricks/10400201 | Q25: Changbing/10400201,35,16,25
A26: 10400202 | B26: 拦江铁意 | C26: 被动 | D26: 104002 | E26: 1 | F26: def|soma*3 | G26: 0 | H26: 0 | I26: 0 | J26: 0 | K26: 横江棍法四重开启 | L26: 0 | M26: 拦江铁意：铁索闭江，万夫莫当，运功时提升{0}点防御。【筋骨加成】 | N26: soma*3 | O26: tricks/10400202
A27: 10400203 | B27: 如封似闭 | C27: 被动 | D27: 104002 | E27: 1 | F27: onSkill|10400201|rate|0.25|AddBuf|1001 | G27: 0 | H27: 0 | I27: 0 | J27: 0 | K27: 横江棍法八重开启 | L27: 0 | M27: 如封似闭：横索连绵，如封似闭，施展铁索横江造成伤害时25%给目标造成流血。 | O27: tricks/10400203
A28: 10100301 | B28: 铁掌双分 | C28: 主动 | D28: 101003 | E28: 1 | F28: hurt|force*1.2 | G28: mp,16 | H28: F,3；B,4 | I28: 0 | J28: 0 | K28: 0 | L28: 0 | M28: 铁掌双分：砂寒铁冷，双掌以推山之势，分别造成2段{0}点伤害。【武力加成】 | N28: force*1.2 | O28: tricks/10100301 | Q28: Quan/10100301,20,11
A29: 10100302 | B29: 破砂石掌 | C29: 被动 | D29: 101003 | E29: 1 | F29: hurt|force*1 | G29: 0 | H29: 0 | I29: 0 | J29: 0 | K29: 铁砂掌四重开启 | L29: 0 | M29: 破砂石掌：舞花坐山，掌若铁石，造成伤害时额外附加{0}点伤害。【武力加成】 | N29: force*1 | O29: tricks/10100302
A30: 10100303 | B30: 药浸柔掌 | C30: 被动 | D30: 101003 | E30: 1 | F30: hp_max|soma*4; | G30: 0 | H30: 0 | I30: 0 | J30: 0 | K30: 铁砂掌八重开启 | L30: 0 | M30: 药浸柔掌：药侵铁掌，锻骨练体，提升{0}点气血上限。【筋骨加成】 | N30: soma*4 | O30: tricks/10100303
A31: 10200401 | B31: 长剑冰清 | C31: 主动 | D31: 102004 | E31: 1 | F31: hurt|force*1.4 | G31: mp,22 | H31: F,2；B,3 | I31: 0 | J31: 0 | K31: 0 | L31: 0 | M31: 长剑冰清：长剑冰清，清意宁心，长剑直点眉心，造成{0}点伤害。【武力加成】 | N31: force*1.4 | O31: tricks/10200401 | Q31: Jian/10200401,38,11,27
A32: 10200402 | B32: 玉洁宁心 | C32: 被动 | D32: 102004 | E32: 1 | F32: OnHurt|rate|0.3|AddMP|attack*0.25 | G32: 0 | H32: 0 | I32: 0 | J32: 0 | K32: 玉洁剑法四重开启 | L32: 0 | M32: 玉洁宁心：玉洁宁心，灵台清明，造成伤害时30%概率回复{0}点内力。 | N32: attack*0.25 | O32: tricks/10200402
A33: 10200403 | B33: 璞玉韬光 | C33: 被动 | D33: 102004 | E33: 1 | F33: OnAddHp|rate|0.4|removeBuff|1001|1002 | G33: 0 | H33: 0 | I33: 0 | J33: 0 | K33: 玉洁剑法八重开启 | L33: 0 | M33: 璞玉韬光：剑若浑金，人比璞玉，恢复时40%概率解除流血和中毒的负面状态。 | O33: tricks/10200403
A34: 10300301 | B34: 黑市快刀 | C34: 主动 | D34: 103003 | E34: 1 | F34: hurt|force*1.8; | G34: mp,18 | H34: F,0；B,4 | I34: 0 | J34: 0 | K34: 0 | L34: 0 | M34: 黑市快刀：快刀直起，骤然劈斩，造成{0}点伤害。【武力加成】 | N34: force*1.8 | O34: tricks/10300301 | Q34: Dao/10300301,40,14，30
A35: 10300302 | B35: 短斤两 | C35: 被动 | D35: 103003 | E35: 1 | F35: OnHurt|IsParterHurt|AttakAgain | G35: 0 | H35: 0 | I35: 0 | J35: 0 | K35: 黑市快刀四重开启 | L35: 0 | M35: 短斤两：同伴对敌方造成伤害时15%概率进行追击。 | O35: tricks/10300302
A36: 10300303 | B36: 公秤分 | C36: 被动 | D36: 103003 | E36: 1 | F36: OnAttackAgain|rate|0.5|useSkill|10300301 | G36: 0 | H36: 0 | I36: 0 | J36: 0 | K36: 黑市快刀八重开启 | L36: 0 | M36: 公秤分：追击时有50%概率施展黑市快刀，且无需消耗内力。 | O36: tricks/10300303
A37: 10500101 | B37: 枪回九曲 | C37: 主动 | D37: 105001 | E37: 1 | F37: hurt|force*1.6; | G37: mp,17 | H37: F,4；B,6 | I37: 0 | J37: 0 | K37: 0 | L37: 0 | M37: 枪回九曲：长枪九曲，三式为始，造成两段伤害，每段伤害为{0}点。【武力加成】 | N37: force*1.6 | O37: tricks/10500101 | Q37: Changbing/10500101,70,16,45
A38: 10500102 | B38: 蜿蜒九变 | C38: 被动 | D38: 105001 | E38: 1 | F38: OnHurt|rate|0.25|AddBuff|1001|1 | G38: 0 | H38: 0 | I38: 0 | J38: 0 | K38: 九曲枪法四重开启 | L38: 0 | M38: 蜿蜒九变：枪出如云龙九变，每次造成伤害时25%概率造成流血效果。 | O38: tricks/10500102
A39: 10500103 | B39: 九曲云龙现 | C39: 被动 | D39: 105001 | E39: 1 | F39: OnHurt|rate|0.3|hurt|force*3; | G39: 0 | H39: 0 | I39: 0 | J39: 0 | K39: 九曲枪法八重开启 | L39: 0 | M39: 九曲云龙现：施展枪回九曲时，每段伤害有30%概率打出{0}点伤害。【武力加成】 | N39: force*3 | O39: tricks/10500103
A40: 10600601 | B40: 弹飞蝗 | C40: 主动 | D40: 106006 | E40: 1 | F40: hurt|force*0.8; | G40: mp,18 | H40: F,0；B,4 | I40: 0 | J40: 0 | K40: 0 | L40: 0 | M40: 弹飞蝗：弹指轻巧，如射飞蝗，造成{0}点伤害。【武力加成】 | N40: force*0.8 | O40: tricks/10600601
...

Sheet 心决
A1: 心诀ID | B1: 心诀名 | C1: 对应招式 | D1: 心诀效果 | E1: 冲突心诀 | F1: 描述 | G1: 对应ICON
A2: id | B2: name | C2: childIds | D2: xg | E2: ct | F2: tip | G2: icon
A3: 1020101 | B3: 长雁 | C3: 1020203 | D3: 0 | E3: 0 | F3: 招式【孤鸿照影】的移动距离提升30%。 | G3: 0
A4: 1020102 | B4: 返鸾 | C4: 1020203 | D4: 0 | E4: 0 | F4: 施展招式【孤鸿照影】后，将获得buff：返鸾（返鸾：不受任何伤害和控制效果的影响）持续1秒。 | G4: 0
A5: 1020103 | B5: 鸳折 | C5: 1020203 | D5: 0 | E5: 1 | F5: 施展招式【孤鸿照影】时，自身获得buff：返鸾。此心决无法与心决【返鸾】同时使用。 | G5: 0
A6: 1020104 | B6: 悲鸣 | C6: 1020110 | D6: 0 | E6: 2 | F6: 无敌2秒 | G6: 0
A7: 1050101 | B7: 放词 | C7: 1050102 | D7: 0 | E7: 3 | F7: 招式【归去来】的伤害范围提升50%，伤害提升100%，但折扇不再返回。 | G7: 0
A8: 1050102 | B8: 凌散 | C8: 1050002 | D8: 0 | E8: 4 | F8: 招式【空余目】释放时不再具有伤害，但对敌方的致盲时长增加至（5）秒。 | G8: 0
A9: 1050103 | B9: 风骨 | C9: 1050002 | D9: 0 | E9: 5 | F9: 【穷途】触发时，立即重置招式【空余目】冷却CD。 | G9: 0
A10: 1050104 | B10: 肆宴 | C10: 1050102 | D10: 0 | E10: 6 | F10: 招式【萧意寒】的伤害提升50%，但每次触发【萧意寒】需消耗（1）点真气。 | G10: 0
A11: 1050105 | B11: 知秋 | C11: 1050101 | D11: 0 | E11: 7 | F11: 每次获得buff【难觅】时，将立即刷新【问秋风】的CD | G11: 0
A12: 1050106 | B12: 摧眉 | C12: 1050100 | D12: 0 | E12: 8 | F12: 扇法的普通攻击造成的伤害提升（30%），获取的真气量降低（20%）。 | G12: 0
A13: 1050107 | B13: 乃绝 | C13: 1050100 | D13: 0 | E13: 9 | F13: 每10秒给自身一个BUFF，最多可叠加3次，当攻击敌方附带负面状态时，额外对敌方造成（X）点伤害。 | G13: 0

Sheet 密卷
A1: 秘术ID | B1: 秘术名称 | C1: 所属道具ID | D1: 秘术效果文本 | E1: 图标 | F1: 所属 | G1: 秘术分类 | H1: 参数1 | I1: 秘术效果文本备用 | J1: 秘术占用cost值（悟性值） | K1: 秘术效果
A2: id | B2: name | C2: ItemID | D2: textEffect | E2: icon | F2: SanCaiBookType | G2: type | H2: c1 | J2: cost | K2: effect
A3: 100101 | B3: 天衍·夕落卷 | C3: 95410101 | D3: =VLOOKUP(B3,三才书属性加成!$B:$D,3,0) -> 装配此卷的角色持单手轻刃、扇法时外功和内功攻击额外提升5%。 | E3: sancaishutian | F3: 1 | G3: 1001 | I3: 无锋残阳，日暮西落，此卷心念黯然散淡，招式似龙蛇气逸，不拘规章。 | J3: 0 | K3: 攻击力,0.10 | L3: =A3 -> 100101
A4: 100102 | B4: 天衍·裂石卷 | C4: 95410102 | D4: =VLOOKUP(B4,三才书属性加成!$B:$D,3,0) -> 装配此卷的角色持拳掌、腿脚时外功和内功攻击额外提升5%。 | E4: sancaishutian | F4: 1 | G4: 1001 | I4: 拳掌百锻，亦得坚猛，真力到处，裂石开碑易如反掌。 | K4: 攻击力,0.10 | L4: =A4 -> 100102
A5: 100103 | B5: 天衍·破军卷 | C5: 95410103 | D5: =VLOOKUP(B5,三才书属性加成!$B:$D,3,0) -> 装配此卷的角色持重刃、长兵时外功和内功攻击额外提升5%。 | E5: sancaishutian | F5: 1 | G5: 1001 | I5: 英雄本学万人敌，何须屑屑悲红妆。力贯千钧，纵使重刃无锋，仍能衣甲平过。 | J5: 0 | K5: 攻击力,0.10 | L5: =A5 -> 100103
A6: 100104 | B6: 天衍·桃花卷 | C6: 95410104 | D6: =VLOOKUP(B6,三才书属性加成!$B:$D,3,0) -> 装配此卷的角色持绳镖、软鞭时外功和内功攻击额外提升5%。 | E6: sancaishutian | F6: 1 | G6: 1001 | I6: 桃花人面，势若春水，柔若初情，千军自破。 | J6: 0 | K6: 攻击力,0.10 | L6: =A6 -> 100104
A7: 100105 | B7: 天衍·摘星卷 | C7: 95410105 | D7: =VLOOKUP(B7,三才书属性加成!$B:$D,3,0) -> 装配此卷的角色持暗器、火器、弓箭时外功和内功攻击额外提升5%。 | E7: sancaishutian | F7: 1 | G7: 1001 | I7: 唐门前代门主唐恨所撰，本是唐门不传之秘，但却不知为何，于近年间流入江湖。 | J7: 0 | K7: 攻击力,0.10 | L7: =A7 -> 100105
A8: 100106 | B8: 天衍·须佐卷 | C8: 95410106 | D8: =VLOOKUP(B8,三才书属性加成!$B:$D,3,0) -> 装配此卷的角色持双手轻刃、短兵时外功和内功攻击额外提升5%。 | E8: sancaishutian | F8: 1 | G8: 1001 | I8: 海客谈瀛洲，烟涛微茫信难求。此乃东瀛流传而来的秘卷，不知何人所撰，其中奥妙晦涩难言。 | J8: 0 | K8: 攻击力,0.10 | L8: =A8 -> 100106
A9: 100107 | B9: 天衍·望山卷 | C9: 95410107 | D9: =VLOOKUP(B9,三才书属性加成!$B:$D,3,0) -> 装配此卷的角色施展拳掌、腿脚的相关武学时，将获得额外5%外功和内功攻击的提升。 | E9: sancaishutian | F9: 1 | G9: 1002 | I9: 此册秘卷所载望山观脉之法晦涩难言，然若能依法而行，许能有获。 | J9: 0 | K9: 攻击力,0.10 | L9: =A9 -> 100107
A10: 100108 | B10: 天衍·凌云卷 | C10: 95410108 | D10: =VLOOKUP(B10,三才书属性加成!$B:$D,3,0) -> 装配此卷的角色施展单手轻刃、扇法的相关武学时，将获得额外5%外功和内功攻击的提升。 | E10: sancaishutian | F10: 1 | G10: 1002 | I10: 愿遂凌云志，直上数千尺，此册秘卷乃旧朝高人写就，奥妙无穷。 | J10: 0 | K10: 攻击力,0.10 | L10: =A10 -> 100108
A11: 100109 | B11: 天衍·西风卷 | C11: 95410109 | D11: =VLOOKUP(B11,三才书属性加成!$B:$D,3,0) -> 装配此卷的角色施展重剑、长兵的相关武学时，将获得额外5%外功和内功攻击的提升。 | E11: sancaishutian | F11: 1 | G11: 1002 | I11: 西风长肃，边城如昨，岿然莫撼，动则有千钧之力。 | J11: 0 | K11: 攻击力,0.10 | L11: =A11 -> 100109
A12: 100110 | B12: 天衍·相思卷 | C12: 95410110 | D12: =VLOOKUP(B12,三才书属性加成!$B:$D,3,0) -> 装配此卷的角色施展暗器、火器、弓箭的相关武学时，将获得额外5%外功和内功攻击的提升。 | E12: sancaishutian | F12: 1 | G12: 1002 | I12: 最伤人者，莫过相思，此乃昔年马踏江湖时自唐门中流出之物。 | J12: 0 | K12: 攻击力,0.10 | L12: =A12 -> 100110
A13: 100111 | B13: 天衍·建御卷 | C13: 95410111 | D13: =VLOOKUP(B13,三才书属性加成!$B:$D,3,0) -> 装配此卷的角色施展双手轻刃、短兵的相关武学时，将获得额外5%外功和内功攻击的提升。 | E13: sancaishutian | F13: 1 | G13: 1002 | I13: 海客谈瀛洲，烟涛微茫信难求。此乃东瀛流传而来的秘卷，不知何人所撰，其中奥妙晦涩难言。 | J13: 0 | K13: 攻击力,0.10 | L13: =A13 -> 100111
A14: 100112 | B14: 天衍·泄玉卷 | C14: 95410112 | D14: =VLOOKUP(B14,三才书属性加成!$B:$D,3,0) -> 装配此卷的角色施展绳镖、软鞭的相关武学时，将获得额外5%外功和内功攻击的提升。 | E14: sancaishutian | F14: 1 | G14: 1002 | I14: 此册秘卷中所载之势如万丈鸿瀑，尽述以柔克刚之精要。 | J14: 0 | K14: 攻击力,0.10 | L14: =A14 -> 100112
A15: 100113 | B15: 天衍·狮搏卷 | C15: 95410113 | D15: =VLOOKUP(B15,三才书属性加成!$B:$D,3,0) -> 装配此卷的角色外功攻击提升5%，外功防御降低5%。 | E15: sancaishutian | F15: 1 | G15: 1003 | I15: 雄狮搏兔亦尽全力，自起势之时，劲力皆出，谓大道之勇。 | J15: 0 | K15: 攻击力,0.10 | L15: =A15 -> 100113
A16: 100114 | B16: 天衍·敛瀑卷 | C16: 95410114 | D16: =VLOOKUP(B16,三才书属性加成!$B:$D,3,0) -> 装配此卷的角色内功攻击提升5%，内功防御降低5%。 | E16: sancaishutian | F16: 1 | G16: 1003 | I16: 千川挂海，飞瀑奔流，此谓形之势，无可避，无可当。 | J16: 0 | K16: 攻击力,0.10 | L16: =A16 -> 100114
... A52: 100150 | B52: 人世·情蛊卷 | C52: 95410150 | D52: =VLOOKUP(B52,三才书属性加成!$B:$D,3,0) -> 装配此卷的角色免暴提升10%，暴击减免提升10% | E52: sancaishuren | F52: 3 | G52: 3005 | I52: 生当同衾，死亦同穴，缠绵入骨，情恨未了，五圣教前任教主金凰儿所创。 | J52: 0 | K52: 攻击力,0.10 | L52: =A52 -> 100150

Sheet 三才书属性加成
A1: 秘术ID | B1: 秘术名称 | C1: 备注 | D1: 备注 | H1: 条件类型 | I1: 条件类型参数 | J1: 气血上限 | K1: 气血回复 | L1: 外功防御 | M1: 内功防御 | N1: 外功攻击 | O1: 内功攻击 | P1: 暴击 | Q1: 免暴 | R1: 暴击伤害 | S1: 暴击减免 | T1: 体力上限 | U1: 体力回复 | V1: 吸血 | W1: 反伤 | X1: 内劲 | Y1: 速度 | Z1: 武力 | AA1: 内息 | AB1: 身法 | AC1: 筋骨 | AD1: 悟性 | AE1: 体力消耗 | AF1: 修为加成
A2: id | B2: name | H2: type | I2: typeNum | J2: qxsx | K2: qxhf | L2: wgfy | M2: ngfy | N2: wg | O2: ng | P2: bj | Q2: mb | R2: bjsh | S2: bjjm | T2: tlsx | U2: tlhf | V2: xx | W2: fs | X2: nj | Y2: sd | Z2: wl | AA2: nx | AB2: sf | AC2: jg | AD2: wx | AE2: tlxh | AF2: xwjc
A3: 100101 | B3: 天衍·夕落卷 | D3: 装配此卷的角色持单手轻刃、扇法时外功和内功攻击额外提升5%。 | E3: 单手轻刃 | F3: 扇子 | H3: 1 | I3: =VLOOKUP(F3,Sheet1!$A$85:$G$101,2,0)&"_"&VLOOKUP(E3,Sheet1!$A$85:$G$101,2,0)&IF(VLOOKUP(G3,Sheet1!$A$85:$G$101,2,0)=0,"","") -> 5_2 | N3: 0.05 | O3: 0.05
A4: 100102 | B4: 天衍·裂石卷 | D4: 装配此卷的角色持拳掌、腿脚时外功和内功攻击额外提升5%。 | E4: 拳掌 | F4: 腿脚 | H4: 1 | I4: =VLOOKUP(F4,Sheet1!$A$85:$G$101,2,0)&"_"&VLOOKUP(E4,Sheet1!$A$85:$G$101,2,0)&IF(VLOOKUP(G4,Sheet1!$A$85:$G$101,2,0)=0,"","") -> 9_1 | N4: 0.05 | O4: 0.05
A5: 100103 | B5: 天衍·破军卷 | D5: 装配此卷的角色持重刃、长兵时外功和内功攻击额外提升5%。 | E5: 重刃 | F5: 长兵 | H5: 1 | I5: =VLOOKUP(F5,Sheet1!$A$85:$G$101,2,0)&"_"&VLOOKUP(E5,Sheet1!$A$85:$G$101,2,0)&IF(VLOOKUP(G5,Sheet1!$A$85:$G$101,2,0)=0,"","") -> 4_3 | N5: 0.05 | O5: 0.05
A6: 100104 | B6: 天衍·桃花卷 | D6: 装配此卷的角色持绳镖、软鞭时外功和内功攻击额外提升5%。 | E6: 绳镖 | F6: 软鞭 | H6: 1 | I6: =VLOOKUP(F6,Sheet1!$A$85:$G$101,2,0)&"_"&VLOOKUP(E6,Sheet1!$A$85:$G$101,2,0)&IF(VLOOKUP(G6,Sheet1!$A$85:$G$101,2,0)=0,"","") -> 13_11 | N6: 0.05 | O6: 0.05
A7: 100105 | B7: 天衍·摘星卷 | D7: 装配此卷的角色持暗器、火器、弓箭时外功和内功攻击额外提升5%。 | E7: 暗器 | F7: 火器 | G7: 弓箭 | H7: 1 | I7: =VLOOKUP(F7,Sheet1!$A$85:$G$101,2,0)&"_"&VLOOKUP(E7,Sheet1!$A$85:$G$101,2,0)&IF(VLOOKUP(G7,Sheet1!$A$85:$G$101,2,0)=0,"","_"&VLOOKUP(G7,Sheet1!$A$85:$G$101,2,0)) -> 14_6_12 | N7: 0.05 | O7: 0.05
A8: 100106 | B8: 天衍·须佐卷 | D8: 装配此卷的角色持双手轻刃、短兵时外功和内功攻击额外提升5%。 | E8: 双手轻刃 | F8: 短兵 | H8: 1 | I8: =VLOOKUP(F8,Sheet1!$A$85:$G$101,2,0)&"_"&VLOOKUP(E8,Sheet1!$A$85:$G$101,2,0)&IF(VLOOKUP(G8,Sheet1!$A$85:$G$101,2,0)=0,"","") -> 15_10 | N8: 0.05 | O8: 0.05
A9: 100107 | B9: 天衍·望山卷 | D9: 装配此卷的角色施展拳掌、腿脚的相关武学时，将获得额外5%外功和内功攻击的提升。 | E9: 拳掌 | F9: 腿脚 | H9: 8 | I9: =VLOOKUP(F9,Sheet1!$A$85:$G$101,2,0)&"_"&VLOOKUP(E9,Sheet1!$A$85:$G$101,2,0)&IF(VLOOKUP(G9,Sheet1!$A$85:$G$101,2,0)=0,"","") -> 9_1 | N9: 0.05 | O9: 0.05
A10: 100108 | B10: 天衍·凌云卷 | D10: 装配此卷的角色施展单手轻刃、扇法的相关武学时，将获得额外5%外功和内功攻击的提升。 | E10: 单手轻刃 | F10: 扇子 | H10: 8 | I10: =VLOOKUP(F10,Sheet1!$A$85:$G$101,2,0)&"_"&VLOOKUP(E10,Sheet1!$A$85:$G$101,2,0)&IF(VLOOKUP(G10,Sheet1!$A$85:$G$101,2,0)=0,"","") -> 5_2 | N10: 0.05 | O10: 0.05
A11: 100109 | B11: 天衍·西风卷 | D11: 装配此卷的角色施展重剑、长兵的相关武学时，将获得额外5%外功和内功攻击的提升。 | E11: 重刃 | F11: 长兵 | H11: 8 | I11: =VLOOKUP(F11,Sheet1!$A$85:$G$101,2,0)&"_"&VLOOKUP(E11,Sheet1!$A$85:$G$101,2,0)&IF(VLOOKUP(G11,Sheet1!$A$85:$G$101,2,0)=0,"","") -> 4_3 | N11: 0.05 | O11: 0.05
A12: 100110 | B12: 天衍·相思卷 | D12: 装配此卷的角色施展暗器、火器、弓箭的相关武学时，将获得额外5%外功和内功攻击的提升。 | E12: 暗器 | F12: 火器 | G12: 弓箭 | H12: 8 | I12: =VLOOKUP(F12,Sheet1!$A$85:$G$101,2,0)&"_"&VLOOKUP(E12,Sheet1!$A$85:$G$101,2,0)&IF(VLOOKUP(G12,Sheet1!$A$85:$G$101,2,0)=0,"","_"&VLOOKUP(G12,Sheet1!$A$85:$G$101,2,0)) -> 14_6_12 | N12: 0.05 | O12: 0.05
A13: 100111 | B13: 天衍·建御卷 | D13: 装配此卷的角色施展双手轻刃、短兵的相关武学时，将获得额外5%外功和内功攻击的提升。 | E13: 双手轻刃 | F13: 短兵 | H13: 8 | I13: =VLOOKUP(F13,Sheet1!$A$85:$G$101,2,0)&"_"&VLOOKUP(E13,Sheet1!$A$85:$G$101,2,0)&IF(VLOOKUP(G13,Sheet1!$A$85:$G$101,2,0)=0,"","") -> 15_10 | N13: 0.05 | O13: 0.05
A14: 100112 | B14: 天衍·泄玉卷 | D14: 装配此卷的角色施展绳镖、软鞭的相关武学时，将获得额外5%外功和内功攻击的提升。 | E14: 绳镖 | F14: 软鞭 | H14: 8 | I14: =VLOOKUP(F14,Sheet1!$A$85:$G$101,2,0)&"_"&VLOOKUP(E14,Sheet1!$A$85:$G$101,2,0)&IF(VLOOKUP(G14,Sheet1!$A$85:$G$101,2,0)=0,"","") -> 13_11 | N14: 0.05 | O14: 0.05
A15: 100113 | B15: 天衍·狮搏卷 | D15: 装配此卷的角色外功攻击提升5%，外功防御降低5%。 | H15: 0 | L15: -0.05 | N15: 0.05
A16: 100114 | B16: 天衍·敛瀑卷 | D16: 装配此卷的角色内功攻击提升5%，内功防御降低5%。 | H16: 0 | M16: -0.05 | O16: 0.05
A17: 100116 | B17: 天衍·震乾卷 | D17: 装配此卷的角色暴击率提升5%。 | H17: 0 | P17: 0.05
A18: 100117 | B18: 天衍·镇厌卷 | D18: 装配此卷的角色暴击伤害提升15%，暴击减免降低5%。 | H18: 0 | R18: 0.15 | S18: -0.05
A19: 100120 | B19: 天衍·喋喰卷 | D19: 装配此卷的角色吸血提升5%。 | H19: 0 | V19: 0.05
A20: 100121 | B20: 地覆·混元卷 | D20: 装配此卷的角色内功防御与外功防御皆提升5%。 | H20: 0 | L20: 0.05 | M20: 0.05
A21: 100125 | B21: 地覆·诸御卷 | D21: 装配此卷的角色暴击减免提升10%。 | H21: 0 | S21: 0.1
A22: 100126 | B22: 地覆·万钟卷 | D22: 装配此卷的角色内功防御提升10%。 | H22: 0 | M22: 0.1
A23: 100127 | B23: 地覆·固源卷 | D23: 装配此卷的角色免暴提升10%。 | H23: 0 | Q23: 0.1
A24: 100128 | B24: 地覆·架擎卷 | D24: 装配此卷的角色暴击减免提升10%。 | H24: 0
A25: 100129 | B25: 地覆·骄子卷 | D25: 装配此卷的角色气血上限提升10%。 | H25: 0 | J25: 0.1
A26: 100131 | B26: 地覆·触石卷 | D26: 装配此卷的角色外功防御提升10%。 | H26: 0 | L26: 0.1
A27: 100132 | B27: 地覆·睚眦卷 | D27: 装配此卷的角色反伤提升5%。 | H27: 0 | W27: 0.05
A28: 100133 | B28: 地覆·坤玖卷 | D28: 装配此卷的角色体力上限提升10%。 | H28: 0 | T28: 0.1
A29: 100134 | B29: 人世·诛邪卷 | D29: 装配此卷的角色单手轻刃、扇法的相关武学时，将获得暴击率提升5%。 | E29: 单手轻刃 | F29: 扇子 | H29: 8 | I29: =VLOOKUP(F29,Sheet1!$A$85:$G$101,2,0)&"_"&VLOOKUP(E29,Sheet1!$A$85:$G$101,2,0)&IF(VLOOKUP(G29,Sheet1!$A$85:$G$101,2,0)=0,"","") -> 5_2 | P29: 0.05
A30: 100135 | B30: 人世·撼岳卷 | D30: 装配此卷的角色拳掌、腿脚的相关武学时，将获得暴击率提升5%。 | E30: 拳掌 | F30: 腿脚 | H30: 8 | I30: =VLOOKUP(F30,Sheet1!$A$85:$G$101,2,0)&"_"&VLOOKUP(E30,Sheet1!$A$85:$G$101,2,0)&IF(VLOOKUP(G30,Sheet1!$A$85:$G$101,2,0)=0,"","") -> 9_1 | P30: 0.05
A31: 100136 | B31: 人世·孤鸾卷 | D31: 装配此卷的角色重刃、长兵的相关武学时，将获得暴击率提升5%。 | E31: 重刃 | F31: 长兵 | H31: 8 | I31: =VLOOKUP(F31,Sheet1!$A$85:$G$101,2,0)&"_"&VLOOKUP(E31,Sheet1!$A$85:$G$101,2,0)&IF(VLOOKUP(G31,Sheet1!$A$85:$G$101,2,0)=0,"","") -> 4_3 | P31: 0.05
A32: 100137 | B32: 人世·天照卷 | D32: 装配此卷的角色双手轻刃、短兵的相关武学时，将获得暴击率提升5%。 | E32: 双手轻刃 | F32: 短兵 | H32: 8 | I32: =VLOOKUP(F32,Sheet1!$A$85:$G$101,2,0)&"_"&VLOOKUP(E32,Sheet1!$A$85:$G$101,2,0)&IF(VLOOKUP(G32,Sheet1!$A$85:$G$101,2,0)=0,"","") -> 15_10 | P32: 0.05
A33: 100138 | B33: 人世·寒鹊卷 | D33: 装配此卷的角色暗器、火器、弓箭的相关武学时，将获得暴击率提升5%。 | E33: 暗器 | F33: 火器 | G33: 弓箭 | H33: 8 | I33: =VLOOKUP(F33,Sheet1!$A$85:$G$101,2,0)&"_"&VLOOKUP(E33,Sheet1!$A$85:$G$101,2,0)&IF(VLOOKUP(G33,Sheet1!$A$85:$G$101,2,0)=0,"","_"&VLOOKUP(G33,Sheet1!$A$85:$G$101,2,0)) -> 14_6_12 | P33: 0.05
A34: 100139 | B34: 人世·断肠卷 | D34: 装配此卷的角色软鞭、绳镖的相关武学时，将获得暴击率提升5%。 | E34: 绳镖 | F34: 软鞭 | H34: 8 | I34: =VLOOKUP(F34,Sheet1!$A$85:$G$101,2,0)&"_"&VLOOKUP(E34,Sheet1!$A$85:$G$101,2,0)&IF(VLOOKUP(G34,Sheet1!$A$85:$G$101,2,0)=0,"","") -> 13_11 | P34: 0.05
A35: 100141 | B35: 人世·致学卷 | D35: 装配此卷的角色获得的修为值额外提升10%，仅主角可生效。 | H35: 4 | AF35: 0.1
A36: 100142 | B36: 人世·无迹卷 | D36: 装配此卷的角色提升30点移动速度。 | H36: 0 | Y36: 30
A37: 100143 | B37: 人世·百草卷 | D37: 装配此卷的角色气血恢复属性提升10%。 | H37: 0 | K37: 0.1
A38: 100144 | B38: 人世·药蛊卷 | D38: 装配此卷的角色体力恢复提升20%。 | H38: 0 | U38: 0.2
A39: 100148 | B39: 人世·丹霞卷 | D39: 装配此卷的角色内劲增长提升10%。 | H39: 0 | X39: 0.1
A40: =VLOOKUP(B40,密卷!$B:$L,11,0) -> 100115 | B40: 天衍·长生卷 | D40: 装配此卷的角色气血恢复额外提升10% | K40: 0.1
...

Sheet Sheet1
A1: 生存向 | B1: 气血上限 | C1: 防御 | D1: 体力
B2: 0.1 | C2: 0.1 | D2: 0.1
A5: 攻击向 | B5: 攻击 | C5: 暴击 | D5: 内劲增长
B6: 0.1 | C6: 0.05 | D6: 0.1
A12: 单独的属性，不能重复有
A13: 悟性在同一等级的河图或洛书下的消耗是相等的
B17: 境界 | C17: 河图 | D17: 洛书
B18: 1
B19: 2 | C19: 1 | D19: 1
B20: 3
B21: 4 | C21: 2 | D21: 2
B22: 5
B23: 6 | C23: 3 | D23: 3
B24: 7
B25: 8 | C25: 4 | D25: 4
B26: 9
B27: 10 | C27: 5 | D27: 5
A29: 秘术ID | B29: 秘术名称 | C29: 所属道具ID | D29: 秘术占用cost值（悟性值） | E29: 秘术效果文本 | F29: 秘术效果 | G29: 图标 | H29: 所属 | I29: 秘术分类 | J29: 参数1 | K29: 秘术效果文本备用
A30: id | B30: name | C30: ItemID | D30: cost | E30: textEffect | F30: effect | G30: icon | H30: SanCaiBookType | I30: type | J30: c1
A31: 100101 | B31: 天衍·夕落卷 | C31: 95410101 | D31: 0 | E31: 装配此卷的角色持单手轻刃、扇法时外功攻击额外提升5%。 | F31: 攻击力,0.10 | G31: sancaishutian | H31: 1 | I31: 1001 | K31: 无锋残阳，日暮西落，此卷心念黯然散淡，招式似龙蛇气逸，不拘规章。
A32: 100102 | B32: 天衍·裂石卷 | C32: 95410102 | E32: 装配此卷的角色持拳掌、腿脚时外功和内功攻击额外提升5%。 | F32: 攻击力,0.10 | G32: sancaishutian | H32: 1 | I32: 1001 | K32: 拳掌百锻，亦得坚猛，真力到处，裂石开碑易如反掌。
A33: 100103 | B33: 天衍·破军卷 | C33: 95410103 | D33: 0 | E33: 装配此卷的角色持重刃、长兵时外功和内功攻击额外提升5%。 | F33: 攻击力,0.10 | G33: sancaishutian | H33: 1 | I33: 1001 | K33: 英雄本学万人敌，何须屑屑悲红妆。力贯千钧，纵使重刃无锋，仍能衣甲平过。
A34: 100104 | B34: 天衍·桃花卷 | C34: 95410104 | D34: 0 | E34: 装配此卷的角色持绳镖、软鞭时外功和内功攻击额外提升5%。 | F34: 攻击力,0.10 | G34: sancaishutian | H34: 1 | I34: 1001 | K34: 桃花人面，势若春水，柔若初情，千军自破。
A35: 100105 | B35: 天衍·摘星卷 | C35: 95410105 | D35: 0 | E35: 装配此卷的角色持暗器、火器、弓箭时外功和内功攻击额外提升5%。 | F35: 攻击力,0.10 | G35: sancaishutian | H35: 1 | I35: 1001 | K35: 唐门前代门主唐恨所撰，本是唐门不传之秘，但却不知为何，于近年间流入江湖。
A36: 100106 | B36: 天衍·须佐卷 | C36: 95410106 | D36: 0 | E36: 装配此卷的角色持双手轻刃、短兵时外功和内功攻击额外提升5%。 | F36: 攻击力,0.10 | G36: sancaishutian | H36: 1 | I36: 1001 | K36: 海客谈瀛洲，烟涛微茫信难求。此乃东瀛流传而来的秘卷，不知何人所撰，其中奥妙晦涩难言。
A37: 100107 | B37: 天衍·望山卷 | C37: 95410107 | D37: 0 | E37: 装配此卷的角色施展拳掌、腿脚武学将获得额外5%外功和内功攻击的提升。 | F37: 攻击力,0.10 | G37: sancaishutian | H37: 1 | I37: 1002 | K37: 此册秘卷所载望山观脉之法晦涩难言，然若能依法而行，许能有获。
A38: 100108 | B38: 天衍·凌云卷 | C38: 95410108 | D38: 0 | E38: 装配此卷的角色施展单手轻刃、扇法武学将获得额外5%外功和内功攻击的提升。 | F38: 攻击力,0.10 | G38: sancaishutian | H38: 1 | I38: 1002 | K38: 愿遂凌云志，直上数千尺，此册秘卷乃旧朝高人写就，奥妙无穷。
A39: 100109 | B39: 天衍·西风卷 | C39: 95410109 | D39: 0 | E39: 装配此卷的角色施展重剑、长兵武学将获得额外5%外功伤害的提升。 | F39: 攻击力,0.10 | G39: sancaishutian | H39: 1 | I39: 1002 | K39: 西风长肃，边城如昨，岿然莫撼，动则有千钧之力。
A40: 100110 | B40: 天衍·相思卷 | C40: 95410110 | D40: 0 | E40: 装配此卷的角色施展暗器、火器、弓箭武学将获得额外5%外功和内功攻击的提升。 | F40: 攻击力,0.10 | G40: sancaishutian | H40: 1 | I40: 1002 | K40: 最伤人者，莫过相思，此乃昔年马踏江湖时自唐门中流出之物。
A41: 100111 | B41: 天衍·建御卷 | C41: 95410111 | D41: 0 | E41: 装配此卷的角色施展双手轻刃、短兵武学将获得额外5%外功和内功攻击的提升。 | F41: 攻击力,0.10 | G41: sancaishutian | H41: 1 | I41: 1002 | K41: 海客谈瀛洲，烟涛微茫信难求。此乃东瀛流传而来的秘卷，不知何人所撰，其中奥妙晦涩难言。
A42: 100112 | B42: 天衍·泄玉卷 | C42: 95410112 | D42: 0 | E42: 装配此卷的角色施展绳镖、软鞭武学将获得额外5%外功和内功攻击的提升。 | F42: 攻击力,0.10 | G42: sancaishutian | H42: 1 | I42: 1002 | K42: 此册秘卷中所载之势如万丈鸿瀑，尽述以柔克刚之精要。
A43: 100113 | B43: 天衍·狮搏卷 | C43: 95410113 | D43: 0 | E43: 装配此卷的角色外功攻击提升10%。 | F43: 攻击力,0.10 | G43: sancaishutian | H43: 1 | I43: 1003 | K43: 雄狮搏兔亦尽全力，自起势之时，劲力皆出，谓大道之勇。
A44: 100114 | B44: 天衍·敛瀑卷 | C44: 95410114 | D44: 0 | E44: 装配此卷的角色内功攻击提升10%。 | F44: 攻击力,0.10 | G44: sancaishutian | H44: 1 | I44: 1003 | K44: 千川挂海，飞瀑奔流，此谓形之势，无可避，无可当。
... A80: 100150 | B80: 人世·情蛊卷 | C80: 95410150 | D80: 0 | E80: 装配此卷的角色受到伤害时，有10%概率将此伤害均摊至角色与伤害来源共担，段姓角色无法修习此卷。 | F80: 攻击力,0.10 | G80: sancaishuren | H80: 3 | I80: 3005 | K80: 生当同衾，死亦同穴，缠绵入骨，情恨未了，五圣教前任教主金凰儿所创，后不知何故立誓仇尽天下段姓之人，故段姓角色无法修习此卷。
B85: 武器类型 | C85: 移动速度 | D85: 攻击类型 | E85: 游走最短距离 | F85: 游走最长距离 | G85: 默认状态
B86: id | C86: speed | D86: type | E86: minDistanceYouZou | F86: maxDistanceYouZou | G86: DefatultState
A87: 拳掌 | B87: 1 | C87: 900 | D87: 0 | E87: 2 | F87: 3.2 | G87: =VLOOKUP(A87,[1]武学境界对应招式表!$C:$F,4,0) -> quan/Idle3
A88: 单手轻刃 | B88: 2 | C88: 800 | D88: 0 | E88: 2.5 | F88: 3.6 | G88: =VLOOKUP(A88,[1]武学境界对应招式表!$C:$F,4,0) -> jian/Idle
A89: 重刃 | B89: 3 | C89: 550 | D89: 0 | E89: 3 | F89: 4 | G89: =VLOOKUP(A89,[1]武学境界对应招式表!$C:$F,4,0) -> zhongren/Idle
A90: 长兵 | B90: 4 | C90: 650 | D90: 0 | E90: 3 | F90: 4 | G90: =VLOOKUP(A90,[1]武学境界对应招式表!$C:$F,4,0) -> qiangfa/Idle
...

Sheet 三才书特效
A1: 秘术ID | B1: 秘术名称 | C1: 备注 | D1: BUFFid
A2: id | B2: name | D2: id
A3: =VLOOKUP(B3,密卷!$B:$L,11,0) -> 100130 | B3: 地覆·无垢卷 | C3: 装配此卷的角色进入战斗后，防御力提升20%，造成的伤害降低10% | D3: 10049
A4: =VLOOKUP(B4,密卷!$B:$L,11,0) -> 100140 | B4: 人世·不工卷 | C4: 装配此卷的角色进入战斗后，移动速度降低80点，造成伤害提升5% | D4: 10050
A5: =VLOOKUP(B5,密卷!$B:$L,11,0) -> 100145 | B5: 人世·悬壶卷 | C5: 装配此卷的角色进入战斗后，治疗成效提升10%，此效果在治疗队友时也会生效 | D5: 10051

Sheet 密卷槽开启
A1: 密卷槽 | B1: 悟性值消耗 | C1: 天赋要求 | D1: 前置开启条件
A2: id | B2: wxz | C2: tfId | D2: condition
A3: 1001 | B3: 0 | C3: 0
A4: 1002 | B4: 1 | C4: 0 | D4: 1001
A5: 1003 | B5: 1 | C5: 0 | D5: 1002
A6: 1004 | B6: 1 | C6: 0 | D6: 1003
A7: 1005 | B7: 1 | C7: 0 | D7: 1004
A8: 2001 | B8: 0 | C8: 0
A9: 2002 | B9: 1 | C9: 0 | D9: 2001
A10: 2003 | B10: 1 | C10: 0 | D10: 2002
A11: 2004 | B11: 1 | C11: 0 | D11: 2003
A12: 2005 | B12: 1 | C12: 0 | D12: 2004
A13: 3001 | B13: 0 | C13: 0
A14: 3002 | B14: 1 | C14: 0 | D14: 3001
A15: 3003 | B15: 1 | C15: 0 | D15: 3002
A16: 3004 | B16: 1 | C16: 0 | D16: 3003
A17: 3005 | B17: 1 | C17: 0 | D17: 3004

Sheet mijuan
A1: id | B1: 篇章名称 | C1: 悟性值消耗 | D1: 篇章分类 | E1: 篇章奖励描述 | F1: 篇章奖励 | G1: 资源名称 | H1: 描述
A2: id | B2: name | C2: wxz | D2: type | E2: rewardTip | F2: reward | G2: icon | H2: des
A3: 1001 | B3: 天书·晨明篇 | C3: 0 | D3: 1 | E3: 无 | F3: 0 | G3: sancaishutian | H3: 天行健，君子自强不息
A4: 1002 | B4: 天书·朏明篇 | C4: 20 | D4: 1 | E4: 气血上限提升5% | F4: 气血,0.05 | G4: sancaishutian | H4: 天行健，君子自强不息
A5: 1003 | B5: 天书·旦明篇 | C5: 40 | D5: 1 | E5: 防御力提升5% | F5: 防御,0.05 | G5: sancaishutian | H5: 天行健，君子自强不息
A6: 1004 | B6: 天书·蚤食篇 | C6: 60 | D6: 1 | E6: 体力上限提升5% | F6: 体力上限,0.05 | G6: sancaishutian | H6: 天行健，君子自强不息
A7: 1005 | B7: 天书·宴食篇 | C7: 90 | D7: 1 | E7: 免伤提升5% 吸血提升5% | F7: 免伤,0.05;吸血,0.05 | G7: sancaishutian | H7: 天行健，君子自强不息
A8: 2001 | B8: 地书·隅中篇 | C8: 0 | D8: 2 | E8: 无 | F8: 0 | G8: sancaishudi | H8: 天行健，君子自强不息
A9: 2002 | B9: 地书·正中篇 | C9: 20 | D9: 2 | E9: 攻击力提升5% | F9: 攻击,0.05 | G9: sancaishudi | H9: 天行健，君子自强不息
A10: 2003 | B10: 地书·小还篇 | C10: 40 | D10: 2 | E10: 内劲增长提升5% | F10: 内劲增长,0.05 | G10: sancaishudi | H10: 天行健，君子自强不息
A11: 2004 | B11: 地书·哺时篇 | C11: 60 | D11: 2 | E11: 暴击提升5% | F11: 暴击,0.05 | G11: sancaishudi | H11: 天行健，君子自强不息
A12: 2005 | B12: 地书·大还篇 | C12: 90 | D12: 2 | E12: 破防提升5% 真气上限提升5% | F12: 破防,0.05;真气上限,0.2 | G12: sancaishudi | H12: 天行健，君子自强不息
A13: 3001 | B13: 人书·高舂篇 | C13: 0 | D13: 3 | E13: 无 | G13: sancaishuren | H13: 天行健，君子自强不息
A14: 3002 | B14: 人书·下舂篇 | C14: 20 | D14: 3 | E14: 攻击力提升5% | F14: 攻击,0.05 | G14: sancaishuren | H14: 天行健，君子自强不息
A15: 3003 | B15: 人书·县车篇 | C15: 40 | D15: 3 | E15: 内劲增长提升5% | F15: 内劲增长,0.05 | G15: sancaishuren | H15: 天行健，君子自强不息
A16: 3004 | B16: 人书·黄昏篇 | C16: 60 | D16: 3 | E16: 暴击提升5% | F16: 暴击,0.05 | G16: sancaishuren | H16: 天行健，君子自强不息
A17: 3005 | B17: 人书·定昏篇 | C17: 90 | D17: 3 | E17: 破防提升5% 真气上限提升5% | F17: 破防,0.05;真气上限,0.2 | G17: sancaishuren | H17: 天行健，君子自强不息
