Workbook

Sheet 掉落基础配置
A1: ID | B1: 掉落ID | C1: 品质 | D1: 概率下限 | E1: 概率上限 | F1: 概率最大上限 | G1: 道具ID | H1: 道具名称 | J1: 类别 | K1: 掉落数量
A2: id | B2: dropid | C2: level | D2: probabilitymin | E2: probabilitymax | F2: upperlimitmax | G2: itemid | H2: name | J2: type | K2: num
A3: 1 | B3: 10001 | C3: 2 | D3: 0 | E3: 52 | G3: 102000 | H3: 枯木枝 | J3: 武器 | K3: 1 | O3: =(E3-D3)/$E$27 -> 0.046931408 | P3: 10001
A4: 2 | B4: 10001 | C4: 2 | D4: =E3 -> 52 | E4: =D4+$E$3 -> 104 | G4: 101001 | H4: 粗布缠手 | J4: 武器 | K4: 1 | O4: =(E4-D4)/$E$27 -> 0.046931408 | P4: 10001
A5: 3 | B5: 10001 | C5: 2 | D5: =E4 -> 104 | E5: =D5+$E$3 -> 156 | G5: 102001 | H5: 硬木剑 | J5: 武器 | K5: 1 | O5: =(E5-D5)/$E$27 -> 0.046931408 | P5: 10001
A6: 4 | B6: 10001 | C6: 2 | D6: =E5 -> 156 | E6: =D6+$E$3 -> 208 | G6: 102101 | H6: 粗钢刀 | J6: 武器 | K6: 1 | O6: =(E6-D6)/$E$27 -> 0.046931408 | P6: 10001
A7: 5 | B7: 10001 | C7: 2 | D7: =E6 -> 208 | E7: =D7+$E$3 -> 260 | G7: 104001 | H7: 白蜡杆 | J7: 武器 | K7: 1 | O7: =(E7-D7)/$E$27 -> 0.046931408 | P7: 10001
A8: 6 | B8: 10001 | C8: 2 | D8: =E7 -> 260 | E8: =D8+$E$3 -> 312 | G8: 104101 | H8: 红缨铁枪 | J8: 武器 | K8: 1 | O8: =(E8-D8)/$E$27 -> 0.046931408 | P8: 10001
A9: 7 | B9: 10001 | C9: 2 | D9: =E8 -> 312 | E9: =D9+$E$3 -> 364 | G9: 105001 | H9: 钿铁扇 | J9: 武器 | K9: 1 | O9: =(E9-D9)/$E$27 -> 0.046931408 | P9: 10001
A10: 8 | B10: 10001 | C10: 2 | D10: =E9 -> 364 | E10: =D10+$E$3 -> 416 | G10: 103001 | H10: 斩马刀 | J10: 武器 | K10: 1 | O10: =(E10-D10)/$E$27 -> 0.046931408 | P10: 10001
A11: 9 | B11: 10001 | C11: 2 | D11: =E10 -> 416 | E11: =D11+$E$3 -> 468 | G11: 106001 | H11: 薄柳袖刀 | J11: 武器 | K11: 1 | O11: =(E11-D11)/$E$27 -> 0.046931408 | P11: 10001
A12: 10 | B12: 10001 | C12: 2 | D12: =E11 -> 468 | E12: =D12+$E$3 -> 520 | G12: 109001 | H12: 千层底 | J12: 武器 | K12: 1 | O12: =(E12-D12)/$E$27 -> 0.046931408 | P12: 10001
A13: 11 | B13: 10001 | C13: 2 | D13: =E12 -> 520 | E13: =D13+$E$3 -> 572 | G13: 110001 | H13: 竹木切 | J13: 武器 | K13: 1 | O13: =(E13-D13)/$E$27 -> 0.046931408 | P13: 10001
A14: 12 | B14: 10001 | C14: 2 | D14: =E13 -> 572 | E14: =D14+$E$3 -> 624 | G14: 111001 | H14: 流星坠 | J14: 武器 | K14: 1 | O14: =(E14-D14)/$E$27 -> 0.046931408 | P14: 10001
A15: 13 | B15: 10001 | C15: 2 | D15: =E14 -> 624 | E15: =D15+$E$3 -> 676 | G15: 200001 | H15: 粗布衣 | J15: 护甲 | K15: 1 | O15: =(E15-D15)/$E$27 -> 0.046931408 | P15: 10001
... A21: 19 | B21: 10001 | C21: 2 | D21: =E20 -> 936 | E21: =D21+$E$3 -> 988 | G21: 800001 | H21: 流苏小坠 | J21: 坠饰 | K21: 1 | O21: =(E21-D21)/$E$27 -> 0.046931408 | P21: 10001
A22: 20 | B22: 10001 | C22: 2 | D22: =E21 -> 988 | E22: =D22+L23 -> 1008 | G22: 908175 | H22: 空麻袋 | J22: 杂物 | K22: 1 | O22: =(E22-D22)/$E$27 -> 0.018050542 | P22: 10001
A23: 21 | B23: 10001 | C23: 4 | D23: =E22 -> 1008 | E23: =D23+L23 -> 1028 | G23: 104402 | H23: 仪戟 | J23: 稀有武器 | K23: 1 | L23: 20 | O23: =(E23-D23)/$E$27 -> 0.018050542
A24: 22 | B24: 10001 | C24: 4 | D24: =E23 -> 1028 | E24: =D24+L24 -> 1048 | G24: 105504 | H24: 醉摇仙 | J24: 稀有武器 | K24: 1 | L24: 20 | O24: =(E24-D24)/$E$27 -> 0.018050542
A25: 23 | B25: 10001 | C25: 4 | D25: =E24 -> 1048 | E25: =D25+L25 -> 1068 | G25: 102905 | H25: 太平令 | J25: 稀有武器 | K25: 1 | L25: 20 | O25: =(E25-D25)/$E$27 -> 0.018050542
A26: 24 | B26: 10001 | C26: 4 | D26: =E25 -> 1068 | E26: =D26+L26 -> 1088 | G26: 105604 | H26: 逍遥游 | J26: 稀有武器 | K26: 1 | L26: 20 | O26: =(E26-D26)/$E$27 -> 0.018050542
A27: 25 | B27: 10001 | C27: 4 | D27: =E26 -> 1088 | E27: =D27+L27 -> 1108 | G27: 1021005 | H27: 乌蛇蜕 | J27: 稀有武器 | K27: 1 | L27: 20 | O27: =(E27-D27)/$E$27 -> 0.018050542
A28: 26 | B28: 10002 | C28: 3 | D28: 0 | E28: 55 | G28: 101003 | H28: 拢掌拳套 | J28: 武器 | K28: 1 | O28: =(E28-D28)/$E$45 -> 0.055555556 | P28: 10002
A29: 27 | B29: 10002 | C29: 3 | D29: =E28 -> 55 | E29: =D29+$E$28 -> 110 | G29: 102003 | H29: 碧鞘长剑 | J29: 武器 | K29: 1 | O29: =(E29-D29)/$E$45 -> 0.055555556 | P29: 10002
A30: 28 | B30: 10002 | C30: 3 | D30: =E29 -> 110 | E30: =D30+$E$28 -> 165 | G30: 102103 | H30: 鬼型吞刀 | J30: 武器 | K30: 1 | O30: =(E30-D30)/$E$45 -> 0.055555556 | P30: 10002
A31: 29 | B31: 10002 | C31: 3 | D31: =E30 -> 165 | E31: =D31+$E$28 -> 220 | G31: 104003 | H31: 磐龙棍 | J31: 武器 | K31: 1 | O31: =(E31-D31)/$E$45 -> 0.055555556 | P31: 10002
A32: 30 | B32: 10002 | C32: 3 | D32: =E31 -> 220 | E32: =D32+$E$28 -> 275 | G32: 104103 | H32: 钿银长枪 | J32: 武器 | K32: 1 | O32: =(E32-D32)/$E$45 -> 0.055555556 | P32: 10002
A33: 31 | B33: 10002 | C33: 3 | D33: =E32 -> 275 | E33: =D33+$E$28 -> 330 | G33: 105003 | H33: 桃花绘扇 | J33: 武器 | K33: 1 | O33: =(E33-D33)/$E$45 -> 0.055555556 | P33: 10002
A34: 32 | B34: 10002 | C34: 3 | D34: =E33 -> 330 | E34: =D34+$E$28 -> 385 | G34: 103003 | H34: 擎斩重刃 | J34: 武器 | K34: 1 | O34: =(E34-D34)/$E$45 -> 0.055555556 | P34: 10002
A35: 33 | B35: 10002 | C35: 3 | D35: =E34 -> 385 | E35: =D35+$E$28 -> 440 | G35: 106003 | H35: 精铁蒺藜 | J35: 武器 | K35: 1 | O35: =(E35-D35)/$E$45 -> 0.055555556 | P35: 10002
A36: 34 | B36: 10002 | C36: 3 | D36: =E35 -> 440 | E36: =D36+$E$28 -> 495 | G36: 109003 | H36: 林南硬靴 | J36: 武器 | K36: 1 | O36: =(E36-D36)/$E$45 -> 0.055555556 | P36: 10002
A37: 35 | B37: 10002 | C37: 3 | D37: =E36 -> 495 | E37: =D37+$E$28 -> 550 | G37: 110003 | H37: 制式和刀 | J37: 武器 | K37: 1 | O37: =(E37-D37)/$E$45 -> 0.055555556 | P37: 10002
A38: 36 | B38: 10002 | C38: 3 | D38: =E37 -> 550 | E38: =D38+$E$28 -> 605 | G38: 111003 | H38: 无间分铜 | J38: 武器 | K38: 1 | O38: =(E38-D38)/$E$45 -> 0.055555556 | P38: 10002
A39: 37 | B39: 10002 | C39: 3 | D39: =E38 -> 605 | E39: =D39+$E$28 -> 660 | G39: 200003 | H39: 挽镜胄 | J39: 护甲 | K39: 1 | O39: =(E39-D39)/$E$45 -> 0.055555556 | P39: 10002
A40: 38 | B40: 10002 | C40: 3 | D40: =E39 -> 660 | E40: =D40+$E$28 -> 715 | G40: 300003 | H40: 蜀锦腕 | J40: 护臂 | K40: 1 | O40: =(E40-D40)/$E$45 -> 0.055555556 | P40: 10002
... A45: 43 | B45: 10002 | C45: 3 | D45: =E44 -> 935 | E45: =D45+$E$28 -> 990 | G45: 800003 | H45: 青庐环佩 | J45: 坠饰 | K45: 1 | O45: =(E45-D45)/$E$45 -> 0.055555556 | P45: 10002
A46: 44 | B46: 10002 | C46: 4 | D46: =E45 -> 990 | E46: =D46+L46 -> 1010 | G46: 104402 | H46: 仪戟 | J46: 稀有武器 | K46: 1 | L46: 20 | O46: =(E46-D46)/$E$27 -> 0.018050542
A47: 45 | B47: 10002 | C47: 4 | D47: =E46 -> 1010 | E47: =D47+L47 -> 1030 | G47: 105504 | H47: 醉摇仙 | J47: 稀有武器 | K47: 1 | L47: 20 | O47: =(E47-D47)/$E$27 -> 0.018050542
A48: 46 | B48: 10002 | C48: 4 | D48: =E47 -> 1030 | E48: =D48+L48 -> 1050 | G48: 102905 | H48: 太平令 | J48: 稀有武器 | K48: 1 | L48: 20 | O48: =(E48-D48)/$E$27 -> 0.018050542
A49: 47 | B49: 10002 | C49: 4 | D49: =E48 -> 1050 | E49: =D49+L49 -> 1070 | G49: 105604 | H49: 逍遥游 | J49: 稀有武器 | K49: 1 | L49: 20 | O49: =(E49-D49)/$E$27 -> 0.018050542
...

Sheet Sheet1
G2: 连环寨简单 | H2: =";"&VLOOKUP(G2,掉落基础配置!$L:$P,5,0)&",1" -> ;10100,1
G3: 连环寨普通 | H3: =";"&VLOOKUP(G3,掉落基础配置!$L:$P,5,0)&",1" -> ;10200,1
G4: 连环寨困难 | H4: =";"&VLOOKUP(G4,掉落基础配置!$L:$P,5,0)&",1" -> ;10300,1
G5: 五圣教简单 | H5: =";"&VLOOKUP(G5,掉落基础配置!$L:$P,5,0)&",1" -> ;10400,1
G6: 五圣教普通 | H6: =";"&VLOOKUP(G6,掉落基础配置!$L:$P,5,0)&",1" -> ;10500,1
G7: 五圣教困难 | H7: =";"&VLOOKUP(G7,掉落基础配置!$L:$P,5,0)&",1" -> ;10600,1
G8: 桃花坞简单 | H8: =";"&VLOOKUP(G8,掉落基础配置!$L:$P,5,0)&",1" -> ;10700,1
G9: 桃花坞普通 | H9: =";"&VLOOKUP(G9,掉落基础配置!$L:$P,5,0)&",1" -> ;10800,1
G10: 桃花坞困难 | H10: =";"&VLOOKUP(G10,掉落基础配置!$L:$P,5,0)&",1" -> ;10900,1
N11: 副本 连环寨 | O11: 143 | Q11: 149 | R11: ;10100,1 | T11: =VLOOKUP(Q11,[3]monster_team!$A:$T,20,0) -> 11000,1 | V11: 10100,1;10110,1;10100,1
N12: 连环寨难度2 | O12: 341 | Q12: 347 | R12: ;10200,1 | T12: =VLOOKUP(Q12,[3]monster_team!$A:$T,20,0) -> 11100,1 | V12: 10200,1;10210,1;10200,1
N13: 连环寨难度3 | O13: 348 | Q13: 354 | R13: ;10300,1 | T13: =VLOOKUP(Q13,[3]monster_team!$A:$T,20,0) -> 11200,1 | V13: 10300,1;10310,1;10300,1
N14: 副本 净蛊天池 | O14: 176 | Q14: 183 | R14: ;10400,1 | T14: =VLOOKUP(Q14,[3]monster_team!$A:$T,20,0) -> 11000,1 | V14: 10400,1;10410,1;10400,1
N15: 净蛊天池难度2 | O15: 355 | Q15: 363 | R15: ;10500,1 | T15: =VLOOKUP(Q15,[3]monster_team!$A:$T,20,0) -> 11100,1 | V15: 10500,1;10510,1;10500,1
N16: 净蛊天池难度3 | O16: 364 | Q16: 372 | R16: ;10600,1 | T16: =VLOOKUP(Q16,[3]monster_team!$A:$T,20,0) -> 11200,1 | V16: 10600,1;10610,1;10600,1
N17: 副本 桃花坞 | O17: 213 | Q17: 219 | R17: ;10700,1 | T17: =VLOOKUP(Q17,[3]monster_team!$A:$T,20,0) -> 11000,1 | V17: 10700,1;10710,1;10700,1
G18: 149 | H18: 10100,1;10110,1;10100,1 | N18: 桃花坞难度2 | O18: 373 | Q18: 380 | R18: ;10800,1 | T18: =VLOOKUP(Q18,[3]monster_team!$A:$T,20,0) -> 11100,1 | V18: 10800,1;10810,1;10800,1
G19: 347 | H19: 10200,1;10210,1;10200,1 | N19: 桃花坞难度3 | O19: 381 | Q19: 388 | R19: ;10900,1 | T19: =VLOOKUP(Q19,[3]monster_team!$A:$T,20,0) -> 11200,1 | V19: 10900,1;10910,1;10900,1
G20: 354 | H20: 10300,1;10310,1;10300,1
G21: 183 | H21: 10400,1;10410,1;10400,1 | K21: =M21/60 -> 0.25 | L21: =K21*10 -> 2.5 | M21: 15
G22: 363 | H22: 10500,1;10510,1;10500,1
G23: 372 | H23: 10600,1;10610,1;10600,1
G24: 219 | H24: 10700,1;10710,1;10700,1 | L24: 野外BOSS填充 | M24: 60 | N24: 秘籍上下册 | Q24: 15 | R24: =SUM(Q24:Q31) -> 100
G25: 380 | H25: 10800,1;10810,1;10800,1
G26: 388 | H26: 10900,1;10910,1;10900,1
N27: 通式、轻重击 | Q27: 15
M29: 8 | N29: 药品，杂项 | Q29: 35
N30: 制造配方 | Q30: 25
C31: 95410101 | D31: 天衍·夕落卷 | E31: 太和 | N31: 心决 | Q31: 10 | T31: 100101 | U31: 天衍·夕落卷 | V31: =VLOOKUP(U31,$D$31:$E$60,2,0) -> 太和
C32: 95410102 | D32: 天衍·裂石卷 | E32: 太和 | L32: 副本 | M32: 8 | N32: 药品 | O32: =Q32/M32 -> 4.375 | P32: =O32*10 -> 43.75 | Q32: 35 | R32: =SUM(Q32:Q37) -> 100 | T32: 100102 | U32: 天衍·裂石卷 | V32: =VLOOKUP(U32,$D$31:$E$60,2,0) -> 太和
C33: 95410107 | D33: 天衍·望山卷 | E33: 太和 | M33: 21 | N33: 三才书 | O33: =Q33/M33 -> 0.47619048 | P33: =O33*10 -> 4.7619048 | Q33: 10 | T33: 100103 | U33: 天衍·破军卷 | V33: =VLOOKUP(U33,$D$31:$E$60,2,0) -> #N/A
C34: 95410108 | D34: 天衍·凌云卷 | E34: 太和 | M34: 60 | N34: 秘籍 | O34: =Q34/M34 -> 0.25 | P34: =O34*10 -> 2.5 | Q34: 15 | T34: 100104 | U34: 天衍·桃花卷 | V34: =VLOOKUP(U34,$D$31:$E$60,2,0) -> 五圣
C35: 95410124 | D35: 地覆·开疆卷 | E35: 太和 | T35: 100105 | U35: 天衍·摘星卷 | V35: =VLOOKUP(U35,$D$31:$E$60,2,0) -> #N/A
M36: 11 | N36: 杂项 | O36: =Q36/M36 -> 3.1818182 | P36: =O36*10 -> 31.818182 | Q36: 35 | T36: 100106 | U36: 天衍·须佐卷 | V36: =VLOOKUP(U36,$D$31:$E$60,2,0) -> 海阁
M37: 83 | N37: 心决 | O37: =Q37/M37 -> 0.060240964 | P37: =O37*10 -> 0.60240964 | Q37: 5 | T37: 100107 | U37: 天衍·望山卷 | V37: =VLOOKUP(U37,$D$31:$E$60,2,0) -> 太和
L38: 副本装备掉落 | T38: 100108 | U38: 天衍·凌云卷 | V38: =VLOOKUP(U38,$D$31:$E$60,2,0) -> 太和
N39: 10把类型的武器 | Q39: 50 | T39: 100109 | U39: 天衍·西风卷 | V39: =VLOOKUP(U39,$D$31:$E$60,2,0) -> #N/A
N40: 装备 | Q40: 50 | T40: 100110 | U40: 天衍·相思卷 | V40: =VLOOKUP(U40,$D$31:$E$60,2,0) -> #N/A
C41: 95410101 | D41: 天衍·夕落卷 | E41: 海阁 | T41: 100111 | U41: 天衍·建御卷 | V41: =VLOOKUP(U41,$D$31:$E$60,2,0) -> 海阁
C42: 95410106 | D42: 天衍·须佐卷 | E42: 海阁 | L42: 剧情战斗填充 | M42: 60 | N42: 秘籍 | Q42: 15 | R42: =SUM(Q42:Q51) -> 100 | T42: 100112 | U42: 天衍·泄玉卷 | V42: =VLOOKUP(U42,$D$31:$E$60,2,0) -> 五圣
...

Sheet Sheet2
J1: 道具名 | K1: id
A2: 100101 | B2: 天衍·夕落卷 | C2: 太和 | J2: 千锻拳势 | K2: 95101011 | N2: 悲鸣 | O2: 1 | Q2: 长雁 | R2: =VLOOKUP(Q2,$N:$O,2,0) -> 1
A3: 100102 | B3: 天衍·裂石卷 | C3: 太和 | J3: 千锻拳势 | K3: 95101012 | N3: 随风 | O3: 1 | Q3: 返鸾 | R3: =VLOOKUP(Q3,$N:$O,2,0) -> 1
A4: 100101 | B4: 天衍·夕落卷 | C4: #N/A | J4: 千锻拳势 | K4: 95101013 | N4: 飘零 | O4: 1 | Q4: 鸳折 | R4: =VLOOKUP(Q4,$N:$O,2,0) -> 1
A5: 100102 | B5: 天衍·裂石卷 | C5: 五圣 | J5: 千锻拳势 | K5: 95101014 | N5: 罡破 | O5: 1 | Q5: 悲鸣 | R5: =VLOOKUP(Q5,$N:$O,2,0) -> 1
A6: 100103 | B6: 天衍·破军卷 | C6: #N/A | J6: 千锻拳势 | K6: 95101015 | N6: 栖隙 | O6: 1 | Q6: 随风 | R6: =VLOOKUP(Q6,$N:$O,2,0) -> 1
A7: 100104 | B7: 天衍·桃花卷 | C7: 海阁 | J7: =J6 -> 千锻拳势 | K7: =K6+1 -> 95101016 | N7: 无涯 | O7: 1 | Q7: 飘零 | R7: =VLOOKUP(Q7,$N:$O,2,0) -> 1
A8: 100105 | B8: 天衍·摘星卷 | C8: 太和 | J8: =J7 -> 千锻拳势 | K8: =K7+1 -> 95101017 | N8: 壁岩 | O8: 1 | Q8: 罡破 | R8: =VLOOKUP(Q8,$N:$O,2,0) -> 1
A9: 100106 | B9: 天衍·须佐卷 | C9: 太和 | J9: =J6&"（上册）" -> 千锻拳势（上册） | K9: =K8+1 -> 95101018 | N9: 赤心 | O9: 1 | Q9: 栖隙 | R9: =VLOOKUP(Q9,$N:$O,2,0) -> 1
A10: 100107 | B10: 天衍·望山卷 | C10: #N/A | J10: =J6&"（下册）" -> 千锻拳势（下册） | K10: =K9+1 -> 95101019 | N10: 万凿 | O10: 1 | Q10: 无涯 | R10: =VLOOKUP(Q10,$N:$O,2,0) -> 1
A11: 100108 | B11: 天衍·凌云卷 | C11: #N/A | J11: =J6&"（全本）" -> 千锻拳势（全本） | K11: =K10+1 -> 95101020 | N11: 转寰 | O11: 1 | Q11: 壁岩 | R11: =VLOOKUP(Q11,$N:$O,2,0) -> 1
A12: 100109 | B12: 天衍·西风卷 | C12: 海阁 | J12: 伏阳开碑拳 | K12: 95101021 | N12: 朝闻 | O12: 1 | Q12: 赤心 | R12: =VLOOKUP(Q12,$N:$O,2,0) -> 1
A13: 100110 | B13: 天衍·相思卷 | C13: 五圣 | J13: 伏阳开碑拳 | K13: 95101022 | N13: 无我 | O13: 1 | Q13: 万凿 | R13: =VLOOKUP(Q13,$N:$O,2,0) -> 1
A14: 100111 | B14: 天衍·建御卷 | C14: 太和 | J14: 伏阳开碑拳 | K14: 95101023 | N14: 昭赤 | O14: 1 | Q14: 敛英 | R14: =VLOOKUP(Q14,$N:$O,2,0) -> #N/A
A15: 100112 | B15: 天衍·泄玉卷 | C15: 太和 | J15: 伏阳开碑拳 | K15: 95101024 | N15: 镇晷 | O15: 1 | Q15: 銮客 | R15: =VLOOKUP(Q15,$N:$O,2,0) -> #N/A
A16: 100113 | B16: 天衍·狮搏卷 | C16: #N/A | J16: 伏阳开碑拳 | K16: 95101025 | N16: 旱临 | O16: 1 | Q16: 放词 | R16: =VLOOKUP(Q16,$N:$O,2,0) -> #N/A
A17: 100114 | B17: 天衍·敛瀑卷 | C17: #N/A | J17: =J16 -> 伏阳开碑拳 | K17: =K16+1 -> 95101026 | N17: 烈轮 | O17: 1 | Q17: 凌散 | R17: =VLOOKUP(Q17,$N:$O,2,0) -> #N/A
A18: 100116 | B18: 天衍·震乾卷 | C18: #N/A | J18: =J17 -> 伏阳开碑拳 | K18: =K17+1 -> 95101027 | N18: 长虹 | O18: 1 | Q18: 风骨 | R18: =VLOOKUP(Q18,$N:$O,2,0) -> #N/A
A19: 100117 | B19: 天衍·镇厌卷 | C19: 太和 | J19: =J16&"（上册）" -> 伏阳开碑拳（上册） | K19: =K18+1 -> 95101028 | N19: 盈亏 | O19: 1 | Q19: 肆宴 | R19: =VLOOKUP(Q19,$N:$O,2,0) -> #N/A
A20: 100120 | B20: 天衍·喋喰卷 | C20: #N/A | J20: =J16&"（下册）" -> 伏阳开碑拳（下册） | K20: =K19+1 -> 95101029 | N20: 气清 | O20: 1 | Q20: 知秋 | R20: =VLOOKUP(Q20,$N:$O,2,0) -> #N/A
A21: 100121 | B21: 地覆·混元卷 | C21: 海阁 | J21: =J16&"（全本）" -> 伏阳开碑拳（全本） | K21: =K20+1 -> 95101030 | N21: 万化 | O21: 1 | Q21: 摧岳 | R21: =VLOOKUP(Q21,$N:$O,2,0) -> 1
A22: 100125 | B22: 地覆·诸御卷 | C22: #N/A | J22: 太极拳 | K22: 95101031 | N22: 凌虚 | O22: 1 | Q22: 百炼 | R22: =VLOOKUP(Q22,$N:$O,2,0) -> 1
A23: 100126 | B23: 地覆·万钟卷 | C23: #N/A | J23: 太极拳 | K23: 95101032 | N23: 太玄 | O23: 1 | Q23: 昭烈 | R23: =VLOOKUP(Q23,$N:$O,2,0) -> 1
A24: 100127 | B24: 地覆·固源卷 | C24: #N/A | J24: 太极拳 | K24: 95101033 | N24: 矢志 | O24: 1 | Q24: 飞将 | R24: =VLOOKUP(Q24,$N:$O,2,0) -> 1
A25: 100129 | B25: 地覆·骄子卷 | C25: 五圣 | J25: 太极拳 | K25: 95101034 | N25: 复烬 | O25: 1 | Q25: 痴缠 | R25: =VLOOKUP(Q25,$N:$O,2,0) -> 1
A26: 100131 | B26: 地覆·触石卷 | C26: 太和 | J26: 太极拳 | K26: 95101035 | N26: 浑旋 | O26: 1 | Q26: 雨绻 | R26: =VLOOKUP(Q26,$N:$O,2,0) -> 1
A27: 100132 | B27: 地覆·睚眦卷 | C27: #N/A | J27: =J26 -> 太极拳 | K27: =K26+1 -> 95101036 | N27: 里剑术 | O27: 1 | Q27: 绸缪 | R27: =VLOOKUP(Q27,$N:$O,2,0) -> 1
A28: 100133 | B28: 地覆·坤玖卷 | C28: #N/A | J28: =J27 -> 太极拳 | K28: =K27+1 -> 95101037 | N28: 断空流 | O28: 1 | Q28: 梅雨 | R28: =VLOOKUP(Q28,$N:$O,2,0) -> 1
A29: 100134 | B29: 人世·诛邪卷 | C29: #N/A | J29: =J26&"（上册）" -> 太极拳（上册） | K29: =K28+1 -> 95101038 | N29: 逆袈裟 | O29: 1 | Q29: 漫堤 | R29: =VLOOKUP(Q29,$N:$O,2,0) -> 1
A30: 100135 | B30: 人世·撼岳卷 | C30: #N/A | J30: =J26&"（下册）" -> 太极拳（下册） | K30: =K29+1 -> 95101039 | N30: 落樱花 | O30: 1 | Q30: 炼血 | R30: =VLOOKUP(Q30,$N:$O,2,0) -> #N/A
A31: 100136 | B31: 人世·孤鸾卷 | C31: #N/A | J31: =J26&"（全本）" -> 太极拳（全本） | K31: =K30+1 -> 95101040 | N31: 风后 | O31: 1 | Q31: 残筋 | R31: =VLOOKUP(Q31,$N:$O,2,0) -> #N/A
A32: 100137 | B32: 人世·天照卷 | C32: #N/A | J32: 凌鸿剑势 | K32: 95102011 | N32: 分野 | O32: 1 | Q32: 化始 | R32: =VLOOKUP(Q32,$N:$O,2,0) -> #N/A
A33: 100138 | B33: 人世·寒鹊卷 | C33: #N/A | J33: 凌鸿剑势 | K33: 95102012 | N33: 独觉 | O33: 1 | Q33: 转寰 | R33: =VLOOKUP(Q33,$N:$O,2,0) -> 1
A34: 100139 | B34: 人世·断肠卷 | C34: 太和 | J34: 凌鸿剑势 | K34: 95102013 | N34: 三生 | O34: 1 | Q34: 朝闻 | R34: =VLOOKUP(Q34,$N:$O,2,0) -> 1
A35: 100141 | B35: 人世·致学卷 | C35: 海阁 | J35: 凌鸿剑势 | K35: 95102014 | N35: 破障 | O35: 1 | Q35: 无我 | R35: =VLOOKUP(Q35,$N:$O,2,0) -> 1
A36: 100142 | B36: 人世·无迹卷 | C36: 五圣 | J36: 凌鸿剑势 | K36: 95102015 | N36: 腾龙 | O36: 1 | Q36: 斗转 | R36: =VLOOKUP(Q36,$N:$O,2,0) -> #N/A
A37: 100143 | B37: 人世·百草卷 | C37: 太和 | J37: =J36 -> 凌鸿剑势 | K37: =K36+1 -> 95102016 | N37: 降世 | O37: 1 | Q37: 昭赤 | R37: =VLOOKUP(Q37,$N:$O,2,0) -> 1
A38: 100144 | B38: 人世·药蛊卷 | C38: #N/A | J38: =J37 -> 凌鸿剑势 | K38: =K37+1 -> 95102017 | N38: 鸿渐 | O38: 1 | Q38: 镇晷 | R38: =VLOOKUP(Q38,$N:$O,2,0) -> 1
A39: 100148 | B39: 人世·丹霞卷 | C39: #N/A | J39: =J36&"（上册）" -> 凌鸿剑势（上册） | K39: =K38+1 -> 95102018 | N39: 时乘 | O39: 1 | Q39: 旱临 | R39: =VLOOKUP(Q39,$N:$O,2,0) -> 1
A40: 100134 | B40: 人世·诛邪卷 | C40: #N/A | J40: =J36&"（下册）" -> 凌鸿剑势（下册） | K40: =K39+1 -> 95102019 | N40: 不息 | O40: 1 | Q40: 烈轮 | R40: =VLOOKUP(Q40,$N:$O,2,0) -> 1
...
